Workbook
Name S1_สร้าง_กฟภ._ให้เติบโตอย่างยั่งยืน: S!$C$3:$C$12
Name SO1_ยกระดับการบริหาร_จัดการระดับสากล_เพื่อสร้าง_ความยั่งยืน: S!$B$3:$B$12
Name ยุทธศาสตร์: S!$C$2:$C$12
Name วัตถุประสงค์เชิงยุทธศาสตร์: S!$B$2:$B$12

Sheet ปก
A10: แบบฟอร์มเสนอขอตั้งงบประมาณลงทุน
A11: เพื่อการดำเนินงานปกติ ประจำปี 2568

Sheet รายชื่อฟอร์ม
A1: แบบฟอร์มเสนอขอตั้งงบประมาณลงทุน
A2: เพื่อการดำเนินงานปกติ ประจำปี 2568
A4: 1. | B4: แบบ งป.003 | C4: สรุปวงเงินงบประมาณลงทุนเพื่อการดำเนินงานปกติ ที่ขอตั้งประจำปี 2568
A5: 2. | B5: แบบ งป.004/1 - งป.004/5 | C5: แบบข้อมูลพื้นฐานของงาน
A6: 3. | B6: แบบ งป.005 | C6: รายละเอียดงานในหมวดที่ดิน
A7: 4. | B7: แบบ งป.006 | C7: รายละเอียดงานในหมวดสิ่งก่อสร้าง งานโยธา
A8: 5. | B8: แบบ งป.007 | C8: รายละเอียดงานในหมวดสิ่งก่อสร้าง ค่าวัสดุอุปกรณ์ของงานระบบไฟฟ้า
A9: 6. | B9: แบบ งป.008 | C9: รายละเอียดงานในหมวดเครื่องจักรอุปกรณ์/หมวดยานพาหนะ/
C10: หมวดเครื่องมือเครื่องใช้ขนาดเล็ก/หมวดวิจัยและพัฒนา/หมวดอื่นๆ
A11: 7. | B11: แบบ งป.009 | C11: รายงานความก้าวหน้าของแผนจัดซื้อ/จัดจ้างตามงบลงทุนเพื่อการดำเนินงานปกติ
A12: 8. | B12: แบบ งป.010/1 | C12: แผนการลงทุนรายปี
A13: 9. | B13: แบบ งป.010/2 | C13: แผนการจ่ายเงินตามงบผูกพันปี 2568 (กรณีแผนระยะยาว/งานต่อเนื่อง)
A14: 10. | B14: แบบ งป.010/3 | C14: เป้าหมายการเบิกจ่ายรายเดือน ปี 2568 แยกรายภาคและสำนักงานใหญ่
A15: 11. | B15: แบบ งป.011 | C15: ประมาณการวัสดุอุปกรณ์นำเข้าจากต่างประเทศ (Import Content) ปี 2568
A16: 12. | B16: แบบ งป.012/1 | C16: การจัดทำงบประมาณสัญญาเช่าที่ไม่ก่อให้เกิดรายได้จากกิจกรรมหลัก ปี 2567
A17: 13. | B17: แบบ งป.012/2 | C17: การจัดทำงบประมาณสัญญาเช่าที่ไม่ก่อให้เกิดรายได้จากกิจกรรมหลัก ปี 2568
A18: 14. | B18: แบบ งป.012/3 | C18: การจัดทำงบประมาณสัญญาเช่าที่ไม่ก่อให้เกิดรายได้จากกิจกรรมหลัก ปี 2569
A19: 15. | B19: แบบ งป.012/4 | C19: การจัดทำงบประมาณสัญญาเช่าที่ไม่ก่อให้เกิดรายได้จากกิจกรรมหลัก ปี 2570
A20: 16. | B20: แบบ งป.012/5 | C20: การจัดทำงบประมาณสัญญาเช่าที่ไม่ก่อให้เกิดรายได้จากกิจกรรมหลัก ปี 2571

Sheet 003
D1: แบบ งป.003
A2: สรุปวงเงินงบประมาณลงทุนเพื่อการดำเนินงานปกติ
A3: ที่ขอตั้งประจำปี 2568
A4: หน่วยงาน สายงานวางแผนและวิศวกรรม
A5: กลุ่มโครงสร้าง………………………………………
D6: หน่วย : บาท
A7: ที่ | B7: ชื่องาน | D7: วงเงินเสนอ
D8: ขอตั้งปี 2568 *
A9: 1 | B9: แผนงานสนับสนุนการดำเนินงาน ระยะที่ 6 | D9: ='004-4'!M23 -> 2868110000
A32: รวม | D32: =D9 -> 2868110000
A33: *หมายเหตุ | B33: แผนงานระยะยาว กรอกจำนวนเงินที่ขอตั้งดำเนินการในปีงบประมาณ 2568

Sheet 004-1
L1: แบบ งป.004/1
A2: แบบข้อมูลพื้นฐานของงาน
A3: (งบลงทุนเพื่อการดำเนินงานปกติ)
A5: 1. | B5: ชื่องาน/แผนงาน | D5: แผนงานสนับสนุนการดำเนินงาน ระยะที่ 6
A6: 2. รายละเอียดของงาน/แผนงาน
B7: 2.1 ผู้รับผิดชอบ | D7: แผนก : …..…...................……………………………………………............……………………............................
D8: กอง : ….......……......…………………………… | G8: ฝ่าย : .....…..................…………………………………………
D9: สายงาน : วางแผนและวิศวกรรม
B10: 2.2 ความจำเป็นในการดำเนินงาน (ทำเครื่องหมาย ü)
C11: ( ) | D11: มีสัญญา ข้อผูกพัน หรือมีเงื่อนไขที่ต้องดำเนินการ | I11: ( ) | J11: นโยบายสำคัญของรัฐบาล
C12: ( ü ) | D12: นโยบายสำคัญของ กฟภ. | I12: ( ) | J12: อื่นๆ ..........................…………………
B13: 2.3 ประเภทการลงทุน (ทำเครื่องหมาย ü)
C14: ( ) งานก่อสร้าง ขยายเขตและปรับปรุงระบบจำหน่าย | I14: ( ) | J14: งานบำรุงรักษาด้านระบบไฟฟ้า
C15: ( ) งานติดตั้งระบบศูนย์สั่งการจ่ายไฟ | I15: ( ) | J15: งาน IT
C16: (ü) งานจัดหาที่ดิน อาคาร ยานพาหนะ และ | I16: ( ) | J16: งานพัฒนาระบบสื่อสาร
D17: เครื่องมือเครื่องใช้ต่างๆ
A18: 2.4 สถานะของงาน | E18: ( ) | F18: งาน/แผนงาน ต่อเนื่อง | I18: ( ü ) | J18: งาน/แผนงาน ใหม่
A19: 2.5 ได้รับอนุมัติจาก | E19: ( ü ) | F19: ผวก. ลงนาม ให้นำเสนอ คณะกรรมการ กฝภ. วันที่ 4 ตุลาคม 2566
E20: ( ) | F20: คณะกรรมการ กฟภ. วันที่ .......................................................................
E21: ( ) | F21: คณะรัฐมนตรี วันที่ ....................................................................................
A22: 2.6 พื้นที่ดำเนินการ ..........ทั่วประเทศ.............
A23: 2.7 ระยะเวลาดำเนินการ .................5............... ปี (ปี 2568 - 2572)
A24: 2.8 วงเงินลงทุนทั้งสิ้น ของงาน/แผนงาน | G24: .....................6,150,000,000.................................................... | K24: บาท
A25: 2.9 วงเงินลงทุนปี 2568 ของงาน/แผนงาน | G25: .....................2,868,110,000.................................................... | K25: บาท
A26: 2.10 เป้าหมายการเบิกจ่ายงบลงทุนปี 2568 | G26: ........................348,545,000.................................................... | K26: บาท
A27: 2.11 วงเงิน งบทำการ ที่ขอตั้งในปี 2568 (ถ้ามี) | G27: ......................................................................... | K27: บาท
A28: 3. วัตถุประสงค์ของงาน/แผนงาน
C29: จัดหาสิ่งสนับสนุนในการดำเนินงานให้เพียงพอกับความต้องการ เพื่อให้ปฏิบัติงานได้อย่างมีประสิทธิภาพสูงสุด
B30: สามารถให้บริการลูกค้าได้ทันต่อความต้องการมากขึ้น ได้รับความสะดวกรวดเร็วในการติดต่องาน สร้างความพึงพอใจ และ
B31: เกิดภาพลักษณ์ที่ดีต่อการไฟฟ้าส่วนภูมิภาค

Sheet 004-2
H1: แบบ งป.004/2
C3: 4. ผลประโยชน์ที่คาดว่าจะได้รับ
D4: 4.1 ผลประโยชน์ที่คาดว่าจะได้รับหลังเสร็จสิ้นงาน/แผนงาน
D5: - ผลผลิต(Output)
E6: ที่ดิน | G6: จำนวน | H6: 56 | I6: รายการ
E7: อาคารสำนักงาน และสิ่งประกอบ | G7: จำนวน | H7: 31 | I7: รายการ
E8: เครื่องมือเครื่องใช้ | G8: จำนวน | H8: 970 | I8: รายการ
E9: ยานพาหนะ | G9: จำนวน | H9: 264 | I9: รายการ
D10: - ผลลัพธ์(Outcome) กฟภ. ได้รับสิ่งสนับสนุนในการดำเนินงานเพียงพอกับความต้องการ สามารถ
D11: ปฏิบัติงานได้มีประสิทธิภาพสูงสุด สามารถให้บริการลูกค้าได้ทันต่อความต้องการ ได้รับความสะดวก
D12: รวดเร็วในการติดต่องาน
D13: 4.2 ผลประโยชน์ที่คาดว่าจะได้รับในปี 2568 (กรณีเป็นแผนงานระยะยาว)
D14: - ผลผลิต(Output) ................................................................................................................................
D15: .......................................................................................................................................................................
D16: - ผลลัพธ์(Outcome) ...........................................................................................................................
D17: .......................................................................................................................................................................
C18: 5. การวิเคราะห์ผลกระทบทางธุรกิจ
D19: 5.1 ผลกระทบต่อองค์กร
E20: .............................................................................................................................................................
D21: .......................................................................................................................................................................
D22: 5.2 ผลกระทบต่อชุมชน สังคม และสิ่งแวดล้อม
E23: ............................................................................................................................................................
D24: .......................................................................................................................................................................
C25: 6. ผลกระทบจากการไม่ได้รับพิจารณาให้ตั้งงบประมาณ
D26: ทำให้ กฟภ. ไม่ได้รับสิ่งสนับสนุนการดำเนินงานที่เพียงพอทำให้ไม่สามารถปฏิบัติงานได้อย่างเต็ม
C27: ประสิทธิภาพ ล่าช้า และไม่สามารถให้บริการลูกค้าได้ทันต่อความต้องการ ไม่ก่อให้เกิดภาพลักษณ์ที่ดีต่อ กฟภ.
C28: 7. ปัญหา อุปสรรค และแนวทางในการแก้ไขปัญหา อุปสรรค
D29: ......................................................................................................................................................................
C30: ...............................................................................................................................................................................
C31: 8. รายงานความก้าวหน้าของแผนจัดซื้อ/จัดจ้างตามแผนงานปกติ แบบ งป.009
C32: 9. แผนการลงทุนรายปี ในกรณีที่ทำมากกว่า 1 ปี ตาม งป.010/1
D33: และแผนการจ่ายเงินตามงบผูกพัน(กรณีแผนระยะยาว/งานต่อเนื่อง) ตาม งป.010/2
C34: 10. เป้าหมายการเบิกจ่ายรายเดือน แยกรายภาคและสำนักงานใหญ่ ตาม งป.010/3
C35: 11. ประมาณการวัสดุอุปกรณ์นำเข้าจากต่างประเทศ ตามแบบ งป.011
A36: 12. | B36: การวิเคราะห์ประโยชน์และความคุ้มค่างาน/แผนงาน
C37: - | D37: ประมาณการผลตอบแทนงาน/แผนงาน
F38: ระยะเวลาคืนทุน (Payback Period) | G38: ................................... | H38: ปี
F39: อัตราผลตอบแทนเฉลี่ยรายปี (IRR) | G39: ................................... | H39: %
F40: มูลค่าปัจจุบันสุทธิ (NPV) | G40: ................................... | H40: ล้านบาท
F41: อัตราผลตอบแทนเฉลี่ยด้านการเงิน (FIRR) | G41: ................................... | H41: %
...

Sheet S
B1: วัตถุประสงค์เชิงยุทธศาสตร์ | C1: ยุทธศาสตร์ | D1: กลยุทธ์ | H1: BSC
A2: SO1 ยกระดับการบริหารจัดการระดับสากลเพื่อสร้างความยั่งยืน | B2: SO1 ยกระดับการบริหารจัดการระดับสากลเพื่อสร้างความยั่งยืน | C2: S1 สร้าง กฟภ. ให้เติบโตอย่างยั่งยืน | H2: เป้าหมายองค์กร (Financial Goal)
A3: SO2 ระบบจําหน่ายที่มีประสิทธิภาพและสร้างความน่าเชื่อถือ ต่อลูกค้า และทุกกลุ่มผู้มีส่วนได้ส่วนเสีย | B3: SO1 ยกระดับการบริหารจัดการระดับสากลเพื่อสร้างความยั่งยืน | C3: S2 ยกระดับการบริหารทุนมนุษย์ | H3: ลูกค้า (Customer Goal)
A4: SO3 เสริมสร้างศักยภาพด้าน Digital Utility และ มุ่งสู่การเป็นผู้นํา ระบบไฟฟ้าในอนาคตระดับภูมิภาค | B4: SO1 ยกระดับการบริหารจัดการระดับสากลเพื่อสร้างความยั่งยืน | C4: S3 ส่งเสริมและพัฒนาขีดความสามารถด้วยเทคโนโลยีดิจิทัล (Digital Technology) ที่มีความมั่นคงปลอดภัย เพื่อการขับเคลื่อนองค์กร อย่างมีประสิทธิภาพ (Digital Transformation) | H4: กระบวนการภายใน (Internal Process Goal)
A5: SO4 ยกระดับผลประกอบการและทิศทางของ PEA Portfolio | B5: SO1 ยกระดับการบริหารจัดการระดับสากลเพื่อสร้างความยั่งยืน | C5: S4 การพัฒนาระบบจัดการนวัตกรรมองค์กร (Corporate Innovation System :CIS) | H5: การเรียนรู้และพัฒนา (Learning & Growth)
B6: SO2 ระบบจําหน่ายที่มีประสิทธิภาพและสร้างความน่าเชื่อถือ ต่อลูกค้า และทุกกลุ่มผู้มีส่วนได้ส่วนเสีย | C6: S5 พัฒนาระบบจําหน่ายที่ได้คุณภาพในระดับชั้นนําของภูมิภาค
B7: SO2 ระบบจําหน่ายที่มีประสิทธิภาพและสร้างความน่าเชื่อถือ ต่อลูกค้า และทุกกลุ่มผู้มีส่วนได้ส่วนเสีย | C7: S6 ยกระดับความพึงพอใจและความผูกพันของลูกค้าและกลุ่มผู้มี ส่วนได้ส่วนเสีย
B8: SO3 เสริมสร้างศักยภาพด้าน Digital Utility และ มุ่งสู่การเป็นผู้นํา ระบบไฟฟ้าในอนาคตระดับภูมิภาค | C8: S7 ยกระดับ Grid Modernization Roadmap & Implementation
B9: SO3 เสริมสร้างศักยภาพด้าน Digital Utility และ มุ่งสู่การเป็นผู้นํา ระบบไฟฟ้าในอนาคตระดับภูมิภาค | C9: S8 ส่งเสริมบทบาท กฟภ. ในการผลักดันบทบาทเพื่อรองรับนโยบาย การเปิดไฟฟ้าเสรี
B10: SO4 ยกระดับผลประกอบการและทิศทางของ PEA Portfolio | C10: S9 การกําหนดทิศทางเชิงยุทธศาสตร์ระหว่าง กฟภ. และบริษัทในเครือ
B11: SO4 ยกระดับผลประกอบการและทิศทางของ PEA Portfolio | C11: S10 การดําเนินงานตามแผนสําหรับธุรกิจเกี่ยวเนื่อง และการบริหาร Product Portfolio
B12: SO4 ยกระดับผลประกอบการและทิศทางของ PEA Portfolio | C12: S11 การปรับปรุงกฎระเบียบที่เกี่ยวข้องให้มีความคล่องตัว และ สามารถแข่งขันได้
B13: S1 สร้าง กฟภ. ให้เติบโตอย่างยั่งยืน | C13: OC1 วิเคราะห GAP และแนวทางการผลักดันองคกรสูความยั่งยืน
B14: S1 สร้าง กฟภ. ให้เติบโตอย่างยั่งยืน | C14: OC2 สนับสนุนการใชพลังงานอยางมีประสิทธิภาพ
B15: S2 ยกระดับการบริหารทุนมนุษย์ | C15: HCM1 สงเสริมการบริหารทุนมนุษยโดยใชเทคโนโลยีดิจิทัลในการพัฒนาระบบงานดาน HCM
B16: S2 ยกระดับการบริหารทุนมนุษย์ | C16: HCM2 พัฒนาระบบการเรียนรูและพัฒนาในการเสริมสรางและยกระดับสมรรถนะของบุคลากร
B17: S3 ส่งเสริมและพัฒนาขีดความสามารถด้วยเทคโนโลยีดิจิทัล (Digital Technology) ที่มีความมั่นคงปลอดภัย เพื่อการขับเคลื่อนองค์กร อย่างมีประสิทธิภาพ (Digital Transformation) | C17: DT1 พัฒนาขีดความสามารถดานเทคโนโลยีดิจิทัล เพื่อสะทอนถึงประสิทธิภาพของการบริหารคาใชจายและประสิทธิภาพของกระบวนการดําเนินงาน
... B31: S11 การปรับปรุงกฎระเบียบที่เกี่ยวข้องให้มีความคล่องตัว และ สามารถแข่งขันได้ | C31: RS1 ทบทวนกฎหมายระเบียบ ขอบังคับ เพื่อรองรับการดําเนินงานในธุรกิจเกี่ยวเนื่อง รวมถึงกํากับการดําเนินงานของบริษัทในเครือ เพื่อใหเกิด Synergy
B35: S1 ยกระดับการบริหารองค์กรและทุนมนุษย์
B36: S2 ส่งเสริมและพัฒนาขีดความสามารถด้วย เทคโนโลยีดิจิทัล (Digital Technology) ที่มีความมั่นคงปลอดภัย เพื่อการขับเคลื่อน องค์กรอย่างมีประสิทธิภาพ (Digital Transformation)
B37: S3 พัฒนาระบบจัดการนวัตกรรมองค์กร (Corporate Innovation System :CIS)
B38: S4 พัฒนาระบบจำหน่ายที่ได้คุณภาพใน ระดับชั้นนำของภูมิภาค ตาม Grid Modernization Roadmap
B39: S5 ยกระดับความพึงพอใจและความผูกพัน ของลูกค้าและกลุ่มผู้มีส่วนได้ส่วนเสีย
B40: S6 กำหนดทิศทางเชิงยุทธศาสตร์ ระหว่าง กฟภ. และบริษัทในเครือ
B41: S7 ดำเนินงานตามแผนสำหรับธุรกิจเกี่ยวเนื่อง และ การบริหารกลุ่มผลิตภัณฑ์(Product Portfolio)
B42: S8 ปรับปรุงกฎระเบียบที่เกี่ยวข้องให้มี ความคล่องตัว และสามารถแข่งขันได้
B43: S9 ส่งเสริมบทบาท กฟภ. ในการขับเคลื่อนนโยบาย การเปิดเสรีกิจการไฟฟ้า
B44: S10 เติบโตอย่างยั่งยืน เพิ่ม Eco-efficiency
B45: S11 เพิ่มสัดส่วนไฟฟ้าจาก Renewable Energy

Sheet 004-3
W1: แบบ งป.004/3
A2: 13. เหตุผลและความจำเป็นของงาน/แผนงาน
B3: 13.1 การสนับสนุนต่อยุทธศาสตร์ และวัตถุประสงค์เชิงยุทธศาสตร์ (เลือกได้มากกว่า 1 ยุทธศาสตร์) (ทำเครื่องหมาย ü)
A4: SO1 | D4: SO2 | I4: SO3 | Q4: SO4
A5: ยกระดับการบริหารจัดการระดับสากลด้วย ดิจิทัลและนวัตกรรมโดยมีทุนมนุษย์เป็น แกนขับเคลื่อนสำคัญ | D5: พัฒนาระบบจำหน่ายที่มีประสิทธิภาพเชื่อถือได้และยกระดับสู่โครงข่ายอัจฉริยะ (Smart Grid) เพื่อเป็นผู้นำระบบไฟฟ้า ตอบสนองความพึงพอใจแก่ลูกค้าและผู้มีส่วนได้ส่วนเสีย | I5: ยกระดับผลประกอบการต่อยอดสู่ธุรกิจใหม่ มุ่งสู่การเปิดเสรีกิจการไฟฟ้า | Q5: เป็นองค์กรไฟฟ้าชั้นนำตอบโจทย์ ความท้าทายของประเทศเพื่อความยั่งยืน ของสังคมและสิ่งแวดล้อม
A6: ( ) | B6: S1 ยกระดับการบริหารองค์กรและทุนมนุษย์ | C6: .......% | D6: ( ) | E6: S4 พัฒนาระบบจำหน่ายที่ได้คุณภาพในระดับชั้นนำของภูมิภาค ตาม Grid Modernization Roadmap | G6: .......% | I6: ( ) | J6: S6 กำหนดทิศทางเชิงยุทธศาสตร์ ระหว่าง กฟภ.และบริษัทในเครือ | O6: .......% | Q6: ( ) | R6: S10 เติบโตอย่างยั่งยืน เพิ่ม Eco-efficiency | X6: .......%
A7: ( ) | B7: S2 ส่งเสริมและพัฒนาขีดความสามารถด้วยเทคโนโลยีดิจิทัล (Digital Technology) ที่มีความมั่นคงปลอดภัย เพื่อการขับเคลื่อนองค์กรอย่างมีประสิทธิภาพ (Digital Transformation) | C7: .......% | D7: (ü ) | E7: S5 ยกระดับความพึงพอใจและความผูกพันของลูกค้าและกลุ่มผู้มีส่วนได้ส่วนเสีย | G7: 1 | I7: ( ) | J7: S7 ดำเนินงานตามแผนสำหรับธุรกิจเกี่ยวเนื่อง และการบริหารกลุ่มผลิตภัณฑ์ (Product Portfolio) | O7: .......% | Q7: ( ) | R7: S11 เพิ่มสัดส่วนไฟฟ้าจาก Renewable Energy | X7: .......%
A8: ( ) | B8: S3 พัฒนาระบบจัดการนวัตกรรมองค์กร (Corporate Innovation System :CIS) | C8: .......% | I8: ( ) | J8: S8 ปรับปรุงกฎระเบียบที่เกี่ยวข้องให้มีความคล่องตัว และสามารถแข่งขันได้ | O8: .......%
I9: ( ) | J9: S9 ส่งเสริมบทบาท กฟภ. ในการขับเคลื่อนนโยบาย การเปิดเสรีกิจการไฟฟ้า | O9: .......%
B10: หมายเหตุ : ทุกยุทธศาสตร์รวมกัน = 100%
B11: 13.2 การสนับสนุนต่อมุมมองตาม Balanced Scorecard
B12: มุมมอง : | C12: เป้าหมายองค์กร (Financial Goal)
B13: ตัวชี้วัดและเป้าหมาย : | C13: ความสำเร็จในการเบิกจ่ายเงิน
A15: 14. แนวทางในการดำเนินงานของงาน/แผนงาน
B16: 14.1 แผนการดำเนินงาน
A17: กิจกรรมหลัก | E17: หน่วยนับ | F17: ระยะเวลาดำเนินการ | X17: รวม
F18: ปีงบประมาณ | I18: ปี 68 | L18: ปี 69 | O18: ปี 70 | R18: ปี 71 | U18: ปี 72
F19: เริ่มต้น - ปี 65
A20: 1. | B20: หมวดที่ดิน | E20: ร้อยละ | I20: 0.19 | L20: 0.39 | O20: 0.42 | R20: =AE20 -> 0 | U20: =AF20 -> 0 | X20: =SUM(F20:W20) -> 1 | AB20: ='004-4'!O7 -> 0.188276 | AC20: ='004-4'!P7 -> 0.39466721 | AD20: ='004-4'!Q7 -> 0.41705679 | AE20: ='004-4'!R7 -> 0 | AF20: ='004-4'!S7 -> 0
A21: 2. | B21: หมวดสิ่งก่อสร้าง | E21: ร้อยละ | I21: 0.07 | L21: 0.49 | O21: 0.37 | R21: 0.03 | U21: 0.04 | X21: =SUM(F21:W21) -> 1 | AB21: ='004-4'!O9 -> 0.071624858 | AC21: ='004-4'!P9 -> 0.49386109 | AD21: ='004-4'!Q9 -> 0.36576327 | AE21: ='004-4'!R9 -> 0.030555906 | AF21: ='004-4'!S9 -> 0.038194882
A22: 3. | B22: หมวดเครื่องมือเครื่องใช้ | E22: ร้อยละ | I22: 0.25 | L22: 0.35 | O22: 0.4 | R22: =AE22 -> 0 | U22: =AF22 -> 0 | X22: =SUM(F22:W22) -> 1 | AB22: ='004-4'!O20 -> 0.24859924 | AC22: ='004-4'!P20 -> 0.35377584 | AD22: ='004-4'!Q20 -> 0.39762492 | AE22: ='004-4'!R20 -> 0 | AF22: ='004-4'!S20 -> 0
A23: 4. | B23: หมวดยานพาหนะ | E23: ร้อยละ | I23: 0.06 | L23: 0.27 | O23: 0.67 | R23: =AE23 -> 0 | U23: =AF23 -> 0 | X23: =SUM(F23:W23) -> 1 | AB23: ='004-4'!O19 -> 0.065124713 | AC23: ='004-4'!P19 -> 0.26962326 | AD23: ='004-4'!Q19 -> 0.66525203 | AE23: ='004-4'!R19 -> 0 | AF23: ='004-4'!S19 -> 0
A24: ร้อยละของงาน | I24: 0.12 | L24: 0.37 | O24: 0.49 | R24: 0.01 | U24: 0.01 | X24: 100
B25: ( ü ) ดำเนินการเอง ……100……… %
B26: ( ) จ้างเหมา ….……….……… %
B27: ( ) จ้างเหมาแบบ Turnkey

Sheet 004-4
M1: แบบ งป.004/4
B2: 14.2 งบประมาณลงทุนเพื่อการดำเนินงานปกติ ที่ขอตั้งประจำปี 2568
M3: หน่วย : บาท
A4: รายการ | F4: วงเงินดำเนินการ | H4: เป้าหมายการเบิกจ่าย(รายปี)
F5: ปี 2568 | H5: 2568 | I5: 2569 | J5: 2570 | K5: 2571 | L5: 2572 | M5: รวม
A6: เป้าหมายการเบิกจ่าย
A7: 1. หมวดที่ดิน (งป.005) | F7: ='005 (3)'!D26 -> 491300000 | H7: =วงเงิน!G5*1000000 -> 92500000 | I7: =วงเงิน!H5*1000000 -> 193900000 | J7: =วงเงิน!I5*1000000 -> 204900000 | M7: =SUM(H7:L7) -> 491300000 | O7: =H7/$F7 -> 0.188276 | P7: =I7/$F7 -> 0.39466721 | Q7: =J7/$F7 -> 0.41705679 | R7: =K7/$F7 -> 0 | S7: =L7/$F7 -> 0
A8: 2. หมวดสิ่งก่อสร้าง
A9: งานโยธา (งป.006) | F9: ='006 (2)'!E22 -> 793300000 | H9: 56820000 | I9: 391780000 | J9: 290160000 | K9: 24240000 | L9: 30300000 | M9: =SUM(H9:L9) -> 793300000 | O9: =H9/$F9 -> 0.071624858 | P9: =I9/$F9 -> 0.49386109 | Q9: =J9/$F9 -> 0.36576327 | R9: =K9/$F9 -> 0.030555906 | S9: =L9/$F9 -> 0.038194882
A10: งานระบบไฟฟ้า
B11: - ค่าวัสดุอุปกรณ์ (งป.007)
B12: - ค่าแรงงาน
B13: - ค่าขนส่ง
B14: - ค่าสำรวจออกแบบและควบคุมงาน | F14: 23800000 | H14: 1705000 | I14: 11754000 | J14: 8705000 | K14: 727000 | L14: =L9*0.03 -> 909000 | M14: =SUM(H14:L14) -> 23800000 | O14: =H14/$F14 -> 0.071638655 | P14: =I14/$F14 -> 0.49386555 | Q14: =J14/$F14 -> 0.3657563 | R14: =K14/$F14 -> 0.030546218 | S14: =L14/$F14 -> 0.038193277
B15: - ค่าเบ็ดเตล็ด
B16: - อื่น ๆ
B17: รวมงานระบบไฟฟ้า
A18: 3. หมวดเครื่องจักรอุปกรณ์ (งป.008)
A19: 4. หมวดยานพาหนะ (งป.008) | F19: ='008'!H22 -> 1036780000 | H19: ='008'!I22 -> 67520000 | I19: ='008'!J22 -> 279540000 | J19: ='008'!K22 -> 689720000 | K19: 0 | L19: 0 | M19: =SUM(H19:L19) -> 1036780000 | O19: =H19/$F19 -> 0.065124713 | P19: =I19/$F19 -> 0.26962326 | Q19: =J19/$F19 -> 0.66525203 | R19: =K19/$F19 -> 0 | S19: =L19/$F19 -> 0
A20: 5. หมวดเครื่องมือ เครื่องใช้ขนาดเล็ก (งป.008) | F20: ='008 (2)'!H12 -> 522930000 | H20: ='008 (2)'!I12 -> 130000000 | I20: ='008 (2)'!J12 -> 185000000 | J20: ='008 (2)'!K12 -> 207930000 | K20: 0 | L20: 0 | M20: =SUM(H20:L20) -> 522930000 | O20: =H20/$F20 -> 0.24859924 | P20: =I20/$F20 -> 0.35377584 | Q20: =J20/$F20 -> 0.39762492 | R20: =K20/$F20 -> 0 | S20: =L20/$F20 -> 0
A21: 6. หมวดวิจัยและพัฒนา (งป.008)
A22: 7. หมวดอื่น ๆ (งป.008)
A23: รวมทั้งสิ้น | F23: =F7+F9+F14+F19+F20 -> 2868110000 | H23: =H7+H9+H14+H19+H20 -> 348545000 | I23: =I7+I9+I14+I19+I20 -> 1061974000 | J23: =J7+J9+J14+J19+J20 -> 1401415000 | K23: =K7+K9+K14+K19+K20 -> 24967000 | L23: =L7+L9+L14+L19+L20 -> 31209000 | M23: =M7+M9+M14+M19+M20 -> 2868110000
H33: =H23/$F$23 -> 0.12152428 | I33: =I23/$F$23 -> 0.37026962 | J33: =J23/$F$23 -> 0.48861968 | K33: =K23/$F$23 -> 0.0087050357 | L33: =L23/$F$23 -> 0.010881382

Sheet 004-5
A1: 15. การประเมินระดับความเสี่ยงโดยระบุประเด็นความเสี่ยงและมิติความเสี่ยง(ที่มีความสอดคล้อง) และประเมินระดับความเสี่ยงของงาน/แผนงาน
A3: 15.1 การประเมินประสิทธิผลการควบคุมที่มีอยู่ของงาน/แผนงาน
A4: งาน/แผนงาน (ปัจจัยเสี่ยง) | C4: ประเภทของปัจจัยเสี่ยง S / O / F / C | E4: ประสิทธิผลการควบคุมที่มีอยู่ | K4: ผลสรุป (เพียงพอ/ไม่เพียงพอ)
E5: ผลการดำเนินงานเมื่อเทียบกับเป้าหมาย | H5: กระบวนการควบคุม | J5: การติดตาม
A6: 1. ไม่สามารถเบิกจ่ายได้ตามเป้าหมาย | E6: 2 | H6: 2 | J6: 3 | K6: เพียงพอ
A7: หมายเหตุ : 1) หากปัจจัยเสี่ยงที่ระบุได้เป็นเรื่องใหม่และยังไม่เคยดำเนินการมาก่อน ให้ประเมินคะแนนประสิทธิผลการควบคุมที่มีอยู่ เท่ากับ 1 คะแนน
A8: 2) ผลการประเมินประสิทธิผลการควบคุมที่มีอยู่ ด้านใดด้านหนึ่ง มีคะแนน 1 คะแนน ให้ถือว่าประสิทธิผลการควบคุมที่มีอยู่ไม่เพียงพอ ให้นำปัจจัยเสี่ยงดังกล่าวไปประเมินระดับความรุนแรงต่อไป
A9: 3) ผลการประเมินประสิทธิผลการควบคุมที่มีอยู่ ในทุกด้านมีคะแนนตั้งแต่ 2 คะแนนขึ้นไป แต่ผู้บริหารให้ความสำคัญ ให้นำปัจจัยเสี่ยงดังกล่าวไปประเมินระดับความรุนแรงต่อไป
A11: คะแนน | B11: ประสิทธิผลการควบคุมที่มีอยู่
B12: ผลการดำเนินงานเมื่อเทียบกับเป้าหมาย | F12: กระบวนการควบคุม | J12: การติดตาม
A13: 1 | B13: ผลการดำเนินงานไม่เป็นไปตามเป้าหมาย | F13: ไม่มีกระบวนการหรือกิจกรรมควบคุม | J13: ไม่มีการติดตาม/รายงานผลการดำเนินงาน
A14: 2 | B14: ผลการดำเนินงานเป็นไปตามเป้าหมาย | F14: มีกระบวนการหรือกิจกรรมควบคุม | J14: มีการติดตาม/รายงานผลการดำเนินงานอย่างน้อยไตรมาสละ 1 ครั้ง
A15: 3 | B15: ผลการดำเนินงานดีกว่าเป้าหมาย | F15: มีกระบวนการหรือกิจกรรมควบคุมและได้จัดทำเป็นคู่มือการปฏิบัติงานที่ชัดเจน | J15: มีการติดตาม/รายงานผลการดำเนินงานเป็นประจำทุกเดือน
A17: 15.2 การประเมินระดับความรุนแรงของโครงการ (ปัจจัยเสี่ยง)
A18: ประเด็นความเสี่ยงของงาน/แผนงาน (สาเหตุ) | B18: ระดับความรุนแรง | E18: แนวทางในการจัดการความเสี่ยง | F18: คาดการณ์ระดับความรุนแรง | I18: เป้าหมาย | L18: คาดการณ์ ผลการดำเนินงาน ค่า KRI (ณ สิ้นปี 2566)
B19: ก่อนการบริหารความเสี่ยง (ต้นปี 2566) | F19: หลังการบริหารความเสี่ยง (ณ สิ้นปี 2566) | I19: (งาน/แผนงาน)
B20: โอกาส | C20: ผลกระทบ | D20: ระดับความเสี่ยง | F20: โอกาส | G20: ผลกระทบ | H20: ระดับความเสี่ยง | I20: ดัชนีชี้วัดความเสี่ยง | J20: ค่าเป้าหมาย | K20: ค่าเบี่ยงเบนที่ยอมรับได้
B21: Likelihood (L) | C21: Impact (I) | D21: (LxI) | F21: Likelihood (L) | G21: Impact (I) | H21: (LxI) | I21: (KRI) | J21: (RA) | K21: (RT)
A22: 1) ผู้รับจ้างทิ้งงานระหว่างานก่อสร้าง | B22: 0.1 | C22: 1 | D22: 1 | E22: จัดทำประชาสัมพันธ์และแผนงานให้ผู้ประกอบการทราบล่วงหน้า | F22: 0.05 | G22: 1 | H22: 1
A23: หมายเหตุ : *1) ให้อธิบายผลการดำเนินงาน
A24: 2) หากผลการดำเนินงานไม่เป็นไปตามเป้าหมาย ให้ระบุปัญหา/อุปสรรค และแนวทางแก้ไขด้วย
L25: แบบ งป.004/5
B26: ตารางโอกาสเกิด/ผลกระทบ
B27: โอกาสเกิด (Likelihood : L) | H27: ผลกระทบ (Impact : I)
B28: ระดับ | D28: ความหมาย | F28: โอกาส/ความน่าจะเกิดทางสถิติ | H28: ความหมาย
B29: 1 | D29: มีโอกาสเกิดขึ้นต่ำมาก | F29: 1 - 20% | H29: มีผลกระทบต่ำมาก
B30: 2 | D30: มีโอกาสเกิดขึ้นต่ำ | F30: 21 - 40% | H30: มีผลกระทบต่ำ
B31: 3 | D31: มีโอกาสเกิดขึ้นปานกลาง | F31: 41 - 60% | H31: มีผลกระทบปานกลาง
B32: 4 | D32: มีโอกาสเกิดขึ้นสูง | F32: 61 - 80% | H32: มีผลกระทบสูง
B33: 5 | D33: มีโอกาสเกิดขึ้นสูงมาก | F33: 81 - 100% | H33: มีผลกระทบสูงมาก
B35: ตารางระดับความเสี่ยง
B36: ลำดับ | D36: ระดับความเสี่ยง
D37: (Risk Severity) (ผลคูณ LxI) | H37: ความหมาย
B38: 1 | D38: ระดับคะแนน 1-4 | H38: ผลกระทบต่ำ
B39: 2 | D39: ระดับคะแนน >4 และ ≤12 | H39: ผลกระทบปานกลาง
B40: 3 | D40: ระดับคะแนนมากกว่า 12 | H40: ผลกระทบสูง
H44: จัดทำโดย | J44: ตรวจสอบโดย
H45: ....................................................................... | J45: ........................................................................
H46: (นาวสาวพรทิพย์ อรุณสกุล) | J46: (นายสมพร แซ่ลิ่ม)
H47: ตำแหน่ง รก.จก. | J47: ตำแหน่ง อก.จก.
...

Sheet คำอธิบายแบบ งป.004-1-5
A1: คำอธิบายแบบ งป.004/1 - งป.004/5
A2: (แบบข้อมูลพื้นฐานของงาน)
A4: 1. | B4: ชื่องาน/แผนงาน หมายถึง ชื่อของงานที่หน่วยงานจะดำเนินการ เพื่อให้บรรลุตามวัตถุประสงค์ที่ตั้งไว้
A5: 2. | B5: รายละเอียดของงาน/แผนงาน
B6: 2.1 | C6: ผู้รับผิดชอบ | F6: ให้ระบุหน่วยงานเป็นระดับแผนก, กอง, ฝ่าย, สายงาน
B7: 2.2 | C7: ความจำเป็นในการดำเนินงาน | F7: ให้ทำเครื่องหมาย ü ในหัวข้อที่เลือกว่าเป็นงาน/แผนงาน
F8: ที่มีความจำเป็นจะต้องดำเนินการ เช่น มีสัญญา ข้อผูกพัน
F9: หรือมีเงื่อนไขที่ต้องดำเนินการ หรือเป็นนโยบายที่สำคัญของ กฟภ.
F10: ถ้าไม่ดำเนินการจะก่อให้เกิดความเสียหาย หรือสอดคล้องกับ
F11: นโยบายของรัฐบาล เช่น งานขยายเขตต่างๆ ให้บ้านเรือนราษฎร
F12: ที่ไม่มีไฟฟ้าใช้ เป็นต้น
B13: 2.3 | C13: ประเภทการลงทุน | F13: ให้ทำเครื่องหมาย ü ในหัวข้อที่เลือกว่างาน/แผนงาน เป็นประเภทการลงทุนใด
B14: 2.4 | C14: สถานะของงาน | F14: หมายถึง สถานภาพของงานในปีที่ขอตั้งงบประมาณว่าเป็น
F15: งาน/แผนงานต่อเนื่องหรืองาน/แผนงานใหม่
B16: 2.5 | C16: ได้รับอนุมัติจาก | F16: ให้ทำเครื่องหมาย ü ในหัวข้อที่ได้รับการอนุมัติ และระบุวันที่ที่ได้รับอนุมัติ
B17: 2.6 | C17: พื้นที่ดำเนินการ | F17: ให้ระบุสถานที่และจังหวัดที่ดำเนินการของงาน/แผนงาน
B18: 2.7 | C18: ระยะเวลาดำเนินการ | F18: ให้ระบุระยะเวลาเริ่มต้นที่ได้รับอนุมัติงาน/แผนงาน และระยะ
F19: เวลาสิ้นสุด คือระยะเวลาที่คาดว่าจะได้รับมอบงานงวดสุดท้าย
B20: 2.8 | C20: วงเงินลงทุนทั้งสิ้นของงาน/แผนงาน | F20: หมายถึง วงเงินงบประมาณรวมทั้งสิ้นที่จะใช้ในการดำเนินการ
B21: 2.9 | C21: วงเงินลงทุนปี 2568 ของงาน/แผนงาน | F21: หมายถึง วงเงินที่ขอตั้งงบประมาณปี 2568
B22: 2.10 | C22: เป้าหมายการเบิกจ่ายงบลงทุนปี 2568 | F22: ให้ประมาณการค่าใช้จ่ายที่จะใช้ในปีที่ขอตั้งงบประมาณ
F23: โดยวงเงินรวมเป้าหมายการเบิกจ่ายต้องเท่ากับวงเงินดำเนินการปี 2568
B24: 2.11 | C24: วงเงินงบทำการที่ขอตั้งในปี 2568 | F24: ให้ใส่วงเงินที่ขอใช้จากงบทำการ (ถ้ามี)
A25: 3. | B25: วัตถุประสงค์ของงาน/แผนงาน | F25: หมายถึง จุดมุ่งหมายในการดำเนินการเพื่อให้บรรลุผลเมื่อสิ้นสุดงาน/แผนงาน
A26: 4. | B26: ผลประโยชน์ที่คาดว่าจะได้รับ
B27: 4.1 | C27: ผลประโยชน์ที่คาดว่าจะได้รับหลังเสร็จสิ้น | F27: ผลผลิต (Output) หมายถึง ผลผลิตต่อหน่วยนับ สำหรับหน่วยของผลผลิต
C28: งาน/แผนงาน | F28: ระบุตามหน่วยที่สามารถวัดเป็นเชิงปริมาณได้ หากไม่สามารถวัดเป็นหน่วยนับได้
F29: กำหนดเป็นเปอร์เซนต์
F30: ผลลัพธ์ (Outcome) หมายถึง ผลที่คาดว่าจะได้รับ ที่เกิดขึ้นตามมาจากการเกิด
F31: ผลผลิต
B32: 4.2 | C32: ผลประโยชน์ที่คาดว่าจะได้รับในปี 2568 | F32: หมายถึง ผลผลิต(Output) และ ผลลัพธ์ (Outcome) ในปี 2568
C33: (กรณีเป็นแผนงานระยะยาว) | F33: ของแผนงานระยะยาว
A34: 5. | B34: การวิเคราะห์ผลกระทบทางธุรกิจ
B35: 5.1 | C35: ผลกระทบต่อองค์กร | E35: ให้ระบุถึง | F35: - สนับสนุนวิสัยทัศน์ พันธกิจขององค์กร
F36: - สนับสนุนยุทธศาสตร์หลักขององค์กร
F37: - หน่วยงานกำกับกำหนด (องค์กรจำเป็นต้องดำเนินการ)
B38: 5.2 | C38: ผลกระทบต่อชุมชน สังคม | F38: ให้ระบุถึงบทวิเคราะห์ผลกระทบทางลบต่อสังคม /
C39: และสิ่งแวดล้อม | F39: ความกังวลของสาธารณะชน / สิ่งแวดล้อมที่เกิดจากการดำเนินงาน
F40: ของงาน/แผนงาน
A41: 6. | B41: ผลกระทบจากการไม่ได้รับพิจารณา | F41: ระบุผลกระทบที่ได้รับหากไม่ได้รับการพิจารณาตั้งงบประมาณ
...

Sheet 005 (1)
H1: แบบ งป.005
A2: แบบฟอร์ม
A3: หมวดที่ดิน
A4: ปีงบประมาณ ........2568.....................
A5: กลุ่มโครงสร้าง
A6: ชื่องาน แผนงานสนับสนุนการดำเนินงาน ระยะที่ 6
A7: หน่วยงาน สายงานวางแผนและวิศวกรรม
H8: หน่วย : บาท
C9: ซื้อที่ดิน | F9: ปรับปรุงที่ดิน
A10: ที่ | B10: ชื่อการไฟฟ้า | C10: จำนวน | D10: จำนวนเงิน | E10: วัตถุประสงค์ | F10: จำนวน | G10: จำนวนเงิน | H10: วัตถุประสงค์
C11: (ไร่) | D11: (บาท) | E11: เหตุผล | F11: ม.3 | G11: (บาท) | H11: เหตุผล
A12: 1 | B12: กฟส.อ.แม่สรวย จ.เชียงราย | C12: 3 - 5 | D12: 10000000 | E12: ซื้อใหม่
A13: 2 | B13: กฟส.ต.นางแล จ.เชียงราย | C13: 3 - 5 | D13: 30000000 | E13: ซื้อใหม่
A14: 3 | B14: กฟย.อ.ลับแล จ.อุตรดิตถ์ | C14: 3 - 5 | D14: 14500000 | E14: ซื้อใหม่
A15: 4 | B15: กฟย.อ.บึงสามัคคี จ.กำแพงเพชร | C15: 3 - 5 | D15: 5000000 | E15: ซื้อใหม่
A16: 5 | B16: กฟย.อ.วังทรายพูน จ.พิจิตร | C16: 3 - 5 | D16: 9500000 | E16: ซื้อใหม่
A17: 6 | B17: กฟย.อ.ดงเจริญ จ.พิจิตร | C17: 3 - 5 | D17: 9500000 | E17: ซื้อใหม่
A18: 7 | B18: กฟจ.กำแพงเพชร | C18: 0-0-88 | D18: 1500000 | E18: ซื้อขยายสำนักงานเดิม
A19: 8 | B19: กฟย.ต.หัวหวาย จ.นครสวรรค์ | C19: 3 - 5 | D19: 4000000 | E19: ซื้อใหม่
A20: 9 | B20: กฟย.อ.ห้วยคต จ.อุทัยธานี | C20: 3 - 5 | D20: 6000000 | E20: ซื้อใหม่
A21: 10 | B21: กฟย.อ.หนองมะโมง จ.ชัยนาท | C21: 3 - 5 | D21: 5000000 | E21: ซื้อใหม่
A22: 11 | B22: กฟย.อ.หนองขาหย่าง จ.อุทัยธานี | C22: 3 - 5 | D22: 4000000 | E22: ซื้อใหม่
A23: 12 | B23: กฟย.ต.พุเตย จ.เพชรบูรณ์ | C23: 3 - 5 | D23: 5500000 | E23: ซื้อใหม่
... A32: 21 | B32: กฟย.อ.สุวรรณคูหา จ.หนองบัวลำภู | C32: 3 - 5 | D32: 3600000 | E32: ซื้อใหม่

Sheet 005 (2)
H1: แบบ งป.005
A2: แบบฟอร์ม
A3: หมวดที่ดิน
A4: ปีงบประมาณ ........2568.....................
A5: กลุ่มโครงสร้าง
A6: ชื่องาน แผนงานสนับสนุนการดำเนินงาน ระยะที่ 6
A7: หน่วยงาน สายงานวางแผนและวิศวกรรม
H8: หน่วย : บาท
C9: ซื้อที่ดิน | F9: ปรับปรุงที่ดิน
A10: ที่ | B10: ชื่อการไฟฟ้า | C10: จำนวน | D10: จำนวนเงิน | E10: วัตถุประสงค์ | F10: จำนวน | G10: จำนวนเงิน | H10: วัตถุประสงค์
C11: (ไร่) | D11: (บาท) | E11: เหตุผล | F11: ม.3 | G11: (บาท) | H11: เหตุผล
A12: 22 | B12: กฟย.อ.พระยืน จ.ขอนแก่น | C12: 3 - 5 | D12: 6000000 | E12: ซื้อใหม่
A13: 23 | B13: กฟย.อ.บ้านแฮด จ.ขอนแก่น | C13: 3 - 5 | D13: 6900000 | E13: ซื้อใหม่
A14: 24 | B14: กฟย.อ.ศรีเมืองใหม่ จ.อุบลราชธานี | C14: 3 - 5 | D14: 7500000 | E14: ซื้อใหม่
A15: 25 | B15: กฟย.อ.ตาลสุม จ.อุบลราชธานี | C15: 3 - 5 | D15: 7500000 | E15: ซื้อใหม่
A16: 26 | B16: กฟย.อ.น้ำเกลี้ยง จ.ศรีสะเกษ | C16: 3 - 5 | D16: 7500000 | E16: ซื้อใหม่
A17: 27 | B17: กฟย.อ.เชียงขวัญ จ.ร้อยเอ็ด | C17: 3 - 5 | D17: 7500000 | E17: ซื้อใหม่
A18: 28 | B18: กฟย.อ.โพนทราย จ.ร้อยเอ็ด | C18: 3 - 5 | D18: 7500000 | E18: ซื้อใหม่
A19: 29 | B19: กฟย.อ.กุดรัง จ.มหาสารคาม | C19: 3 - 5 | D19: 7500000 | E19: ซื้อใหม่
A20: 30 | B20: กฟส.อ.สูงเนิน จ.นครราชสีมา | C20: 3 - 5 | D20: 6000000 | E20: ซื้อใหม่
A21: 31 | B21: กฟย.ต.กลางดง จ.นครราชสีมา | C21: 3 - 5 | D21: 6000000 | E21: ซื้อใหม่
A22: 32 | B22: กฟย.อ.ขามทะเลสอ จ.นครราชสีมา 3 | C22: 3 - 5 | D22: 5400000 | E22: ซื้อใหม่
A23: 33 | B23: กฟย.ต.ห้วยบง จ.นครราชสีมา | C23: 3 - 5 | D23: 3600000 | E23: ซื้อใหม่
... A32: 42 | B32: กฟย.อ.เขาฉกรรจ์ จ.สระแก้ว | C32: 3 - 5 | D32: 18000000 | E32: ซื้อใหม่

Sheet 005 (3)
H1: แบบ งป.005
A2: แบบฟอร์ม
A3: หมวดที่ดิน
A4: ปีงบประมาณ ........2568.....................
A5: กลุ่มโครงสร้าง
A6: ชื่องาน แผนงานสนับสนุนการดำเนินงาน ระยะที่ 6
A7: หน่วยงาน สายงานวางแผนและวิศวกรรม
H8: หน่วย : บาท
C9: ซื้อที่ดิน | F9: ปรับปรุงที่ดิน
A10: ที่ | B10: ชื่อการไฟฟ้า | C10: จำนวน | D10: จำนวนเงิน | E10: วัตถุประสงค์ | F10: จำนวน | G10: จำนวนเงิน | H10: วัตถุประสงค์
C11: (ไร่) | D11: (บาท) | E11: เหตุผล | F11: ม.3 | G11: (บาท) | H11: เหตุผล
A12: 43 | B12: กฟอ.ปลวกแดง จ.ระยอง | C12: 5 - 10 | D12: 40000000 | E12: ซื้อใหม่
A13: 44 | B13: กฟอ.เดิมบางนางบวช จ.สุพรรณบุรี | C13: 5 - 10 | D13: 20000000 | E13: ซื้อใหม่
A14: 45 | B14: กฟย.ต.บางหลวง จ.นครปฐม | C14: 3 - 5 | D14: 7500000 | E14: ซื้อใหม่
A15: 46 | B15: กฟย.ต.มะขามล้ม จ.สุพรรณบุรี | C15: 3 - 5 | D15: 6000000 | E15: ซื้อใหม่
A16: 47 | B16: กฟจ.ประจวบคีรีขันธ์ | C16: 5 - 10 | D16: 50000000 | E16: ซื้อใหม่
A17: 48 | B17: กฟส.อ.คีรีรัฐนิคม จ.สุราษฎร์ธานี | C17: 3 - 5 | D17: 9000000 | E17: ซื้อใหม่
A18: 49 | B18: กฟย.อ.พนม จ.สุราษฎร์ธานี | C18: 3 - 5 | D18: 9000000 | E18: ซื้อใหม่
A19: 50 | B19: กฟย.อ.ท่าฉาง จ.สุราษฎร์ธานี | C19: 3 - 5 | D19: 14000000 | E19: ซื้อใหม่
A20: 51 | B20: กฟย.อ.รัษฎา จ.ตรัง | C20: 3 - 5 | D20: 8000000 | E20: ซื้อใหม่
A21: 52 | B21: กฟย.อ.ป่าพะยอม จ.พัทลุง | C21: 3 - 5 | D21: 9500000 | E21: ซื้อใหม่
A22: 53 | B22: กฟย.อ.คลองหอยโข่ง จ.สงขลา | C22: 3 - 5 | D22: 9500000 | E22: ซื้อใหม่
A23: 54 | B23: กฟย.อ.กระแสสินธุ์ จ.สงขลา | C23: 3 - 5 | D23: 8000000 | E23: ซื้อใหม่
... A25: 56 | B25: กฟย.อ.มะนัง จ.สตูล | C25: 3 - 5 | D25: 7000000 | E25: ซื้อใหม่
A26: รวมจำนวนเงินทั้งสิ้น | D26: =SUM(D12:D25)+SUM('005 (2)'!D12:D32)+SUM('005 (1)'!D12:D32) -> 491300000

Sheet 006
F1: แบบ งป.006
A2: แบบฟอร์ม
A3: หมวดสิ่งก่อสร้าง
A4: งานโยธา
A5: ปีงบประมาณ ........2568........................
A6: กลุ่มโครงสร้าง
A7: ชื่องาน แผนงานสนับสนุนการดำเนินงาน ระยะที่ 6
A8: หน่วยงาน สายงานวางแผนและวิศวกรรม
F9: หน่วย : บาท
A10: ที่ | B10: ชื่อการไฟฟ้า | C10: รายการ | D10: ขนาด | E10: จำนวนเงิน | F10: วัตถุประสงค์
E11: (บาท) | F11: เหตุผล
A12: 1 | B12: กฟอ.หางดง จ.เชียงใหม่ | C12: ก่อสร้างอาคารสำนักงาน และสิ่งก่อสร้างประกอบอื่น ๆ | E12: 32200000
A13: =A12+1 -> 2 | B13: กฟอ.เทิง จ.เชียงราย | C13: ก่อสร้างอาคารสำนักงาน และสิ่งก่อสร้างประกอบอื่น ๆ | E13: 28700000
A14: =A13+1 -> 3 | B14: กฟอ.สวรรคโลก จ.สุโขทัย | C14: ก่อสร้างอาคารสำนักงาน และสิ่งก่อสร้างประกอบอื่น ๆ | E14: 35900000
B15: (ก่อสร้างที่คลังพัสดุ กฟอ.สวรรคโลก)
A16: =A14+1 -> 4 | B16: กฟอ.สวรรคโลก จ.สุโขทัย | C16: ก่อสร้างอาคารพักอาศัยรวม และสิ่งก่อสร้างประกอบอื่น ๆ | E16: 9000000
B17: (ก่อสร้างที่สำนักงานเดิม)
A18: =A16+1 -> 5 | B18: กฟส.อ.หนองม่วง จ.ลพบุรี | C18: ก่อสร้างอาคารสำนักงาน และสิ่งก่อสร้างประกอบอื่น ๆ | E18: 31700000
A19: =A18+1 -> 6 | B19: กฟส.อ.บ้านหมี่ จ.ลพบุรี | C19: ก่อสร้างอาคารสำนักงาน และสิ่งก่อสร้างประกอบอื่น ๆ | E19: 26100000
A20: =A19+1 -> 7 | B20: กฟส.อ.พล จ.ขอนแก่น | C20: ก่อสร้างอาคารสํานักงาน และสิ่งก่อสร้างประกอบอื่น ๆ | E20: 28200000
A21: =A20+1 -> 8 | B21: กฟส.อ.กระนวน จ.ขอนแก่น | C21: ก่อสร้างอาคารสํานักงาน และสิ่งก่อสร้างประกอบอื่น ๆ | E21: 22900000
A22: =A21+1 -> 9 | B22: กฟส.อ.อุทุมพรพิสัย จ.ศรีสะเกษ | C22: ก่อสร้างอาคารสํานักงาน และสิ่งก่อสร้างประกอบอื่น ๆ | E22: 39700000
A23: =A22+1 -> 10 | B23: กฟย.อ.ดงหลวง จ.มุกดาหาร | C23: ก่อสร้างอาคารสํานักงาน และสิ่งก่อสร้างประกอบอื่น ๆ | E23: 15500000
A24: =A23+1 -> 11 | B24: กฟย.อ.หนองบัวระเหว จ.ชัยภูมิ | C24: ก่อสร้างอาคารสํานักงาน และสิ่งก่อสร้างประกอบอื่น ๆ | E24: 11800000
A25: =A24+1 -> 12 | B25: กฟส.อ.หนองบุญมาก จ.นครราชสีมา | C25: ก่อสร้างอาคารสํานักงาน และสิ่งก่อสร้างประกอบอื่น ๆ | E25: 37300000
A26: =A25+1 -> 13 | B26: กฟก.1 | C26: ก่อสร้างรั้ว และสิ่งก่อสร้างประกอบอื่น ๆ | E26: 16000000
A27: =A26+1 -> 14 | B27: กฟอ.บางปะอิน จ.พระนครศรีอยุธยา | C27: ก่อสร้างอาคารสำนักงาน และสิ่งก่อสร้างประกอบอื่น ๆ | E27: 58700000
A28: =A27+1 -> 15 | B28: กฟส.อ.บ้านนา จ.นครนายก | C28: ก่อสร้างอาคารสำนักงาน และสิ่งก่อสร้างประกอบอื่น ๆ | E28: 23100000
A29: =A28+1 -> 16 | B29: กฟส.อ.องครักษ์ จ.นครนายก | C29: ก่อสร้างอาคารสำนักงาน และสิ่งก่อสร้างประกอบอื่น ๆ | E29: 23100000
A30: =A29+1 -> 17 | B30: กฟฟ.เมืองพัทยา จ.ชลบุรี | C30: ก่อสร้างอาคารสำนักงาน และสิ่งก่อสร้างประกอบอื่น ๆ | E30: 61300000
... A34: =A33+1 -> 21 | B34: กฟอ.หลังสวน จ.ชุมพร | C34: ก่อสร้างโรงเก็บมิเตอร์ และสิ่งก่อสร้างประกอบอื่น ๆ | E34: 8400000

Sheet 006 (2)
F1: แบบ งป.006
A2: แบบฟอร์ม
A3: หมวดสิ่งก่อสร้าง
A4: งานโยธา
A5: ปีงบประมาณ ........2568........................
A6: กลุ่มโครงสร้าง
A7: ชื่องาน แผนงานสนับสนุนการดำเนินงาน ระยะที่ 6
A8: หน่วยงาน สายงานวางแผนและวิศวกรรม
F9: หน่วย : บาท
A10: ที่ | B10: ชื่อการไฟฟ้า | C10: รายการ | D10: ขนาด | E10: จำนวนเงิน | F10: วัตถุประสงค์
E11: (บาท) | F11: เหตุผล
A12: ='006'!A34+1 -> 22 | B12: กฟส.อ.บางแพ จ.ราชบุรี | C12: ก่อสร้างโรงเก็บมิเตอร์ และสิ่งก่อสร้างประกอบอื่น ๆ | E12: 12000000
A13: =A12+1 -> 23 | B13: กฟส.อ.ไชยา จ.สุราษฎร์ธานี | C13: ก่อสร้างโรงเก็บมิเตอร์ และสิ่งก่อสร้างประกอบอื่น ๆ | E13: 9600000
A14: =A13+1 -> 24 | B14: กฟอ.เกาะสมุย จ.สุราษฎร์ธานี | C14: ก่อสร้างอาคารสำนักงาน และสิ่งก่อสร้างประกอบอื่น ๆ | E14: 60600000
A15: =A14+1 -> 25 | B15: กฟส.อ.หนองจิก จ.ปัตตานี | C15: ก่อสร้างอาคารสำนักงาน และสิ่งก่อสร้างประกอบอื่น ๆ | E15: 48800000
A16: =A15+1 -> 26 | B16: กฟอ.หาดใหญ่ จ.สงขลา | C16: ก่อสร้างรั้ว และสิ่งก่อสร้างประกอบอื่น ๆ | E16: 12000000
A17: =A16+1 -> 27 | B17: ผรค.เชียงใหม่ | C17: ปรับปรุงโรงผลิตคอน และสิ่งก่อสร้างประกอบอื่น ๆ | E17: 3000000
A18: =A17+1 -> 28 | B18: ผรค.มหาสารคาม | C18: ก่อสร้างโรงผลิตคอน และสิ่งก่อสร้างประกอบอื่น ๆ | E18: 10000000
A19: =A18+1 -> 29 | B19: ผรค.กาญจนบุรี | C19: ก่อสร้างหลังคาคลุมแท่นผลิตภัณฑ์คอนกรีต และสิ่งก่อสร้างประกอบอื่น ๆ | E19: 30500000
A20: =A19+1 -> 30 | B20: ผรค.นครศรีธรรมราช | C20: ก่อสร้างอาคารโรงผลิตคอน และสิ่งก่อสร้างประกอบอื่น ๆ | E20: 10000000
A21: =A20+1 -> 31 | B21: ผรค.พระนครศรีอยุธยา | C21: ก่อสร้างอาคารทดสอบวัสดุ และสิ่งก่อสร้างประกอบอื่น ๆ | E21: 19000000
A22: รวมจำนวนเงินทั้งสิ้น | E22: =SUM('006'!E12:E34)+SUM('006 (2)'!E12:E21) -> 793300000
A23: ค่าสำรวจออกแบบและควบคุมงาน | E23: ='004-4'!M14 -> 23800000

Sheet 007
K1: แบบ งป.007
A2: แบบฟอร์ม
A3: หมวดสิ่งก่อสร้าง
A4: รายละเอียดค่าวัสดุอุปกรณ์ของงานระบบไฟฟ้า
A5: ปีงบประมาณ..........2568...................
A6: กลุ่มโครงสร้าง
A7: ชื่องาน
A8: หน่วยงาน
K9: หน่วย : บาท
A10: ที่ | B10: รายการ | C10: จำนวน | D10: ราคา ต่อหน่วย | E10: แหล่งที่มาของราคาที่ขอตั้งงบประมาณ | H10: วงเงินรวม (บาท) | I10: ประมาณจ่าย | K10: คำชี้แจง
E11: ครั้งสุดท้ายเมื่อ ................. | F11: ท้องตลาด เฉลี่ย 3 บริษัท | G11: อื่นๆ | I11: ปี 2568 | J11: ปี 2569

Sheet 008
L1: แบบ งป.008
A2: แบบฟอร์ม
A3: หมวด ยานพาหนะ
A4: รายละเอียดครุภัณฑ์ แผนจัดหายานพาหนะ
A5: ปีงบประมาณ..........2568.......................
A6: กลุ่มโครงสร้าง
A7: ชื่องาน แผนงานสนับสนุนการดำเนินงาน ระยะที่ 6
A8: หน่วยงาน สายงานวางแผนและวิศวกรรม
L9: หน่วย : บาท
A10: ที่ | B10: รายการ | C10: จำนวน | D10: ราคา ต่อหน่วย | E10: แหล่งที่มาของราคาที่ขอตั้งงบประมาณ | H10: วงเงินรวม | I10: ประมาณจ่าย | L10: คำชี้แจง
E11: ครั้งสุดท้ายเมื่อ ................. | F11: ท้องตลาด เฉลี่ย 3 บริษัท | G11: อื่นๆ | I11: ปี 2568 | J11: ปี 2569 | K11: ปี 2570
A12: 1 | B12: =หมวดยานพาหนะ!B6 -> รถบรรทุก 3 ตัน พร้อมตู้เก็บเครื่องมือ | C12: =หมวดยานพาหนะ!AE6 -> 72 | D12: =หมวดยานพาหนะ!AF6 -> 1920000 | H12: =หมวดยานพาหนะ!AG6 -> 138240000 | I12: 0 | J12: ='ประมาณเบิกจ่าย หมวดยานพาหนะ'!BP5 -> 138240000 | K12: 0
A13: 2 | B13: =หมวดยานพาหนะ!B7 -> รถบรรทุก 4 ตัน ติดกระเช้า (Category C) | C13: =หมวดยานพาหนะ!AE7 -> 64 | D13: =หมวดยานพาหนะ!AF7 -> 4130000 | H13: =หมวดยานพาหนะ!AG7 -> 264320000 | I13: 0 | J13: 0 | K13: ='ประมาณเบิกจ่าย หมวดยานพาหนะ'!BQ7 -> 264320000
A14: 3 | B14: =หมวดยานพาหนะ!B8 -> รถบรรทุก 6 ตัน (ใช้งานคลังพัสดุ) | C14: =หมวดยานพาหนะ!AE8 -> 90 | D14: =หมวดยานพาหนะ!AF8 -> 2110000 | H14: =หมวดยานพาหนะ!AG8 -> 189900000 | I14: ='ประมาณเบิกจ่าย หมวดยานพาหนะ'!BO9 -> 63300000 | J14: ='ประมาณเบิกจ่าย หมวดยานพาหนะ'!BP9 -> 126600000 | K14: 0
A15: 4 | B15: =หมวดยานพาหนะ!B9 -> รถกระเช้าฮอทไลน์ 22 เควี | C15: =หมวดยานพาหนะ!AE9 -> 15 | D15: =หมวดยานพาหนะ!AF9 -> 11220000 | H15: =หมวดยานพาหนะ!AG9 -> 168300000 | I15: 0 | J15: 0 | K15: ='ประมาณเบิกจ่าย หมวดยานพาหนะ'!BQ10 -> 168300000
A16: 5 | B16: =หมวดยานพาหนะ!B10 -> รถบริการด้านฮอทไลน์ | C16: =หมวดยานพาหนะ!AE10 -> 6 | D16: =หมวดยานพาหนะ!AF10 -> 2450000 | H16: =หมวดยานพาหนะ!AG10 -> 14700000 | I16: 0 | J16: ='ประมาณเบิกจ่าย หมวดยานพาหนะ'!BP11 -> 14700000
A17: 6 | B17: =หมวดยานพาหนะ!B11 -> รถเครน ขนาด 35 ตัน | C17: =หมวดยานพาหนะ!AE11 -> 3 | D17: =หมวดยานพาหนะ!AF11 -> 34100000 | H17: =หมวดยานพาหนะ!AG11 -> 102300000 | I17: 0 | J17: 0 | K17: ='ประมาณเบิกจ่าย หมวดยานพาหนะ'!BQ12 -> 102300000
A18: 7 | B18: =หมวดยานพาหนะ!B12 -> รถหัวลากติดเครน พร้อมรถกึ่งพ่วงแบบพื้นราบ (Flat Bed) แบบขยายความยาวได้ | C18: =หมวดยานพาหนะ!AE12 -> 9 | D18: =หมวดยานพาหนะ!AF12 -> 13480000 | H18: =หมวดยานพาหนะ!AG12 -> 121320000 | I18: 0 | J18: 0 | K18: ='ประมาณเบิกจ่าย หมวดยานพาหนะ'!BQ15 -> 121320000
A19: 8 | B19: =หมวดยานพาหนะ!B13 -> รถบรรทุก 6 ตัน กระบะยาว | C19: =หมวดยานพาหนะ!AE13 -> 2 | D19: =หมวดยานพาหนะ!AF13 -> 2110000 | H19: =หมวดยานพาหนะ!AG13 -> 4220000 | I19: ='ประมาณเบิกจ่าย หมวดยานพาหนะ'!BO16 -> 4220000 | J19: 0 | K19: 0
A20: 9 | B20: =หมวดยานพาหนะ!B14 -> รถบรรทุก 6 ล้อติดเครนพับ พร้อมกระบะบรรทุกความยาว ไม่น้อยกว่า 6 เมตร พร้อมหลังคาเลื่อนเปิด - ปิด ได้ตลอด | C20: =หมวดยานพาหนะ!AE14 -> 1 | D20: =หมวดยานพาหนะ!AF14 -> 3680000 | H20: =หมวดยานพาหนะ!AG14 -> 3680000 | I20: 0 | J20: 0 | K20: ='ประมาณเบิกจ่าย หมวดยานพาหนะ'!BQ17 -> 3680000
A21: 10 | B21: =หมวดยานพาหนะ!B15 -> รถขุดเจาะ 4x4 | C21: =หมวดยานพาหนะ!AE15 -> 2 | D21: =หมวดยานพาหนะ!AF15 -> 14900000 | H21: =หมวดยานพาหนะ!AG15 -> 29800000 | I21: 0 | J21: 0 | K21: ='ประมาณเบิกจ่าย หมวดยานพาหนะ'!BQ25 -> 29800000
A22: รวมเป็นวงเงินทั้งสิ้น | H22: =SUM(H12:H21) -> 1036780000 | I22: =SUM(I12:I21) -> 67520000 | J22: =SUM(J12:J21) -> 279540000 | K22: =SUM(K12:K21) -> 689720000
A29: หมายเหตุ | B29: 1. หมวด ให้ระบุหมวดที่ขอตั้งงบประมาณ เช่น หมวดเครื่องจักรอุปกรณ์ ,หมวดยานพาหนะ
B30: 2. กรณีจัดซื้อเครื่องมือเครื่องใช้ขนาดเล็ก ให้ระบุรายละเอียดครุภัณฑ์ เช่น ครุภัณฑ์สื่อสาร, ครุภัณฑ์โรงงานโรงซ่อม

Sheet 008 (2)
L1: แบบ งป.008
A2: แบบฟอร์ม
A3: หมวดเครื่องมือ เครื่องใช้ขนาดเล็ก
A4: รายละเอียดครุภัณฑ์ จัดหาเครื่องมือเครื่องใช้
A5: ปีงบประมาณ..........2568.......................
A6: กลุ่มโครงสร้าง
A7: ชื่องาน แผนงานสนับสนุนการดำเนินงาน ระยะที่ 6
A8: หน่วยงาน สายงานวางแผนและวิศวกรรม
L9: หน่วย : บาท
A10: ที่ | B10: รายการ | C10: จำนวน | D10: ราคา ต่อหน่วย | E10: แหล่งที่มาของราคาที่ขอตั้งงบประมาณ | H10: วงเงินรวม | I10: ประมาณจ่าย | L10: คำชี้แจง
E11: ครั้งสุดท้ายเมื่อ ................. | F11: ท้องตลาด เฉลี่ย 3 บริษัท | G11: อื่นๆ | I11: ปี 2568 | J11: ปี 2569 | K11: ปี 2570
A12: 1 | B12: จัดหาเครื่องมือเครื่องใช้เพิ่มเติมและทดแทน | C12: =SUM('เครื่องมือ(ส่วนกลาง) ปี 2568'!AD254:AE254)+SUM('เครื่องมือ(ส่วนภูมิภาค) ปี 2568'!AB262:AC262) -> 970 | H12: ='เครื่องมือ(ส่วนกลาง) ปี 2568'!BH254+'เครื่องมือ(ส่วนภูมิภาค) ปี 2568'!BD262 -> 522930000 | I12: 130000000 | J12: 185000000 | K12: =H12-I12-J12 -> 207930000
A29: หมายเหตุ | B29: 1. หมวด ให้ระบุหมวดที่ขอตั้งงบประมาณ เช่น หมวดเครื่องจักรอุปกรณ์ ,หมวดยานพาหนะ
B30: 2. กรณีจัดซื้อเครื่องมือเครื่องใช้ขนาดเล็ก ให้ระบุรายละเอียดครุภัณฑ์ เช่น ครุภัณฑ์สื่อสาร, ครุภัณฑ์โรงงานโรงซ่อม

Sheet 009
A2: รายงานความก้าวหน้าของแผนจัดซื้อ/จัดจ้างตามงบลงทุนเพื่อการดำเนินงานปกติ
A3: ที่ขอตั้งงบประมาณประจำปี 2568
A4: กลุ่มโครงสร้าง
A5: ชื่องาน แผนงานสนับสนุนการดำเนินงาน ระยะที่ 6
A6: หน่วยงาน สายงานวางแผนและวิศวกรรม
T7: หน่วย : ล้านบาท(ทศนิยม 3 ตำแหน่ง)
A8: ลำดับ | B8: ขั้นตอนการดำเนินงาน | C8: วงเงิน | D8: กำหนดเวลาดำเนินการใช้เงิน
C9: ดำเนินการ | D9: ปี 2568 - ปีสิ้นสุดการเบิกจ่าย/แผนงาน | Q9: ปี 2569 | R9: ปี 25670 | S9: ปี 25671 | T9: ปี 25672
A10: ที่ | C10: ปี 2568 | D10: ม.ค. | E10: ก.พ. | F10: มี.ค. | G10: เม.ย. | H10: พ.ค. | I10: มิ.ย. | J10: ก.ค. | K10: ส.ค. | L10: ก.ย. | M10: ต.ค. | N10: พ.ย. | O10: ธ.ค. | P10: รวม
A11: 1 | B11: อนุมัติหลักการ / อนุมัติสเปค
A12: 2 | B12: การดำเนินการจัดซื้อจัดจ้าง
B13: - จัดทำเอกสารประกวดราคา/สอบราคา
B14: - ประกวดราคา /สอบราคา
B15: - อนุมัติจัดซื้อ / จัดจ้าง
B16: - ทำสัญญา
A17: 3 | B17: ส่งของ / ดำเนินการก่อสร้าง
A18: 4 | B18: ตรวจรับและทดสอบ
A19: 5 | B19: เบิกจ่ายเงิน(ล้านบาท)
B20: - หมวดที่ดิน | D20: 0 | E20: 0 | F20: 0 | G20: 0 | H20: 0 | I20: 0 | J20: 0 | K20: 0 | L20: 0 | M20: 0 | N20: 0 | O20: ='004-4'!H7/1000000 -> 92.5 | P20: =SUM(D20:O20) -> 92.5 | Q20: ='004-4'!I7/1000000 -> 193.9 | R20: ='004-4'!J7/1000000 -> 204.9 | S20: ='004-4'!K7/1000000 -> 0 | T20: ='004-4'!L7/1000000 -> 0
B21: - หมวดสิ่งก่อสร้าง | D21: 0 | E21: 0 | F21: 0 | G21: 0 | H21: 0 | I21: 0 | J21: 0 | K21: 0 | L21: 0 | M21: =('004-4'!H9*0.2+'004-4'!H14*0.2)/1000000 -> 11.705 | N21: =('004-4'!H9*0.4+'004-4'!H14*0.4)/1000000 -> 23.41 | O21: =('004-4'!H9*0.4+'004-4'!H14*0.4)/1000000 -> 23.41 | P21: =SUM(D21:O21) -> 58.525 | Q21: =('004-4'!I9+'004-4'!I14)/1000000 -> 403.534 | R21: =('004-4'!J9+'004-4'!J14)/1000000 -> 298.865 | S21: =('004-4'!K9+'004-4'!K14)/1000000 -> 24.967 | T21: =('004-4'!L9+'004-4'!L14)/1000000 -> 31.209
B22: - หมวดเครื่องมือเครื่องใช้ | D22: 0 | E22: 0 | F22: 0 | G22: 0 | H22: 0 | I22: 30 | J22: 0 | K22: 0 | L22: 40 | M22: 0 | N22: 0 | O22: 60 | P22: =SUM(D22:O22) -> 130 | Q22: ='008 (2)'!J12/1000000 -> 185 | R22: ='008 (2)'!K12/1000000 -> 207.93 | S22: ='008 (2)'!L12/1000000 -> 0 | T22: ='008 (2)'!M12/1000000 -> 0
B23: - หมวดยานพาหนะ | D23: 0 | E23: 0 | F23: 0 | G23: 0 | H23: 0 | I23: 0 | J23: 0 | K23: 0 | L23: 0 | M23: 0 | N23: 0 | O23: ='008'!I22/1000000 -> 67.52 | P23: =SUM(D23:O23) -> 67.52 | Q23: ='008'!J22/1000000 -> 279.54 | R23: ='008'!K22/1000000 -> 689.72 | S23: ='008'!L22/1000000 -> 0 | T23: ='008'!M22/1000000 -> 0
B24: (ระบุวงเงินแต่ละเดือนให้ชัดเจน)
A25: หมายเหตุ | B25: 1. ให้แสดง Workflow สถานะการดำเนินงานตามขั้นตอนต่าง ๆ เป็นรายเดือนตั้งแต่ปีที่ตั้งงบประมาณจนสิ้นสุดแผนงาน | U25: แบบ งป.009
B26: 2. การประมาณเบิกจ่ายรายเดือน แยกรายละเอียด การจัดซื้ออุปกรณ์, ค่าใช้จ่ายหน้างาน, ค่าจ้างเหมาก่อสร้าง สำหรับสำรองค่าปรับราคา ไม่ต้องประมาณจ่าย
B27: 3. สำหรับแผนงานที่ได้รับอนุมัติแล้ว ให้แสดง work flow ตั้งแต่เริ่มแผนจนสิ้นสุดแผนงงาน

Sheet 010-1
A2: แผนการลงทุนรายปี (การลงทุนเพื่อการดำเนินงานปกติ)
A3: กลุ่มโครงสร้าง..............................................
A4: ชื่องาน แผนงานสนับสนุนการดำเนินงาน ระยะที่ 6
A5: หน่วยงาน สายงานวางแผนและวิศวกรรม
J6: หน่วย : บาท
C7: ระยะเวลาดำเนินการ | J7: รวม
A8: รายการ | C8: วงเงินลงทุน
C9: ปีที่เริ่มต้น-ถึงปี 2566 | D9: ปี 2567 | E9: ปี 2568 | F9: ปี 2569 | G9: ปี 2570 | H9: ปี 2571 | I9: ปี 2572-สิ้นสุดแผนงาน
A10: 1. หมวดที่ดิน | E10: ='004-4'!M7 -> 491300000 | J10: =E10 -> 491300000
A11: 2. หมวดสิ่งก่อสร้าง
A12: งานโยธา | E12: ='004-4'!M9 -> 793300000 | J12: =E12 -> 793300000
A13: งานระบบไฟฟ้า
B14: - ค่าวัสดุอุปกรณ์
B15: - ค่าแรงงาน
B16: - ค่าขนส่ง
B17: - ค่าสำรวจออกแบบและควบคุมงาน | E17: ='004-4'!M14 -> 23800000 | J17: =E17 -> 23800000
B18: - ค่าเบ็ดเตล็ด
B19: - อื่น ๆ
B20: รวมงานระบบไฟฟ้า
A21: 3. หมวดเครื่องจักรอุปกรณ์
A22: 4. หมวดยานพาหนะ | E22: ='004-4'!M19 -> 1036780000 | J22: =E22 -> 1036780000
A23: 5. หมวดเครื่องมือเครื่องใช้ขนาดเล็ก | E23: ='004-4'!M20 -> 522930000 | J23: =E23 -> 522930000
A24: 6. หมวดวิจัยและพัฒนา
A25: 7. หมวดอื่น ๆ
A26: รวม | E26: =SUM(E10:E25) -> 2868110000 | J26: =E26 -> 2868110000
A27: สำรองค่าปรับราคา(กรณีแผนระยะยาว)
B28: รวมทั้งสิ้น | E28: =E26 -> 2868110000 | J28: =E28 -> 2868110000
A29: หมายเหตุ* | B29: 1. วงเงินลงทุนรวมต้องเท่ากับวงเงินเต็มแผนงาน
B30: 2. สำรองค่าปรับราคา เป็นการตั้งวงเงินสำหรับสมทบการจัดซื้อ จัดจ้าง/จ้างเหมา กรณีเป็นแผนงานใหม่ จะเริ่มตั้งสำรองราคาปี 2569 จนสิ้นสุดแผน | J30: แบบ งป.010/1

Sheet 010-2
A2: แผนการจ่ายเงินตามงบผูกพันปี 2568 (กรณีแผนระยะยาว/งานต่อเนื่อง)
V3: หน่วย : บาท
A4: รายการ | B4: วงเงินเต็ม แผนงาน | C4: อนุมัติถึง ปี 2568 | D4: จ่ายจริงถึง ปี 2570 | E4: ปี 2568 | K4: ปี 2569 | Q4: ปี 2570
E5: งบประมาณ | H5: ประมาณจ่าย | K5: งบประมาณ | N5: ประมาณจ่าย | Q5: งบประมาณ | T5: ประมาณจ่าย
E6: ผูกพัน | F6: ลงทุน | G6: รวม | H6: ผูกพัน | I6: ลงทุน | J6: รวม | K6: ผูกพัน | L6: ลงทุน | M6: รวม | N6: ผูกพัน | O6: ลงทุน | P6: รวม | Q6: ผูกพัน | R6: ลงทุน | S6: รวม | T6: ผูกพัน | U6: ลงทุน | V6: รวม
A7: 1. หมวดที่ดิน | B7: =วงเงิน!B5*1000000 -> 491300000 | C7: ='004-4'!M7 -> 491300000 | F7: =C7 -> 491300000 | G7: =E7+F7 -> 491300000 | I7: ='004-4'!H7 -> 92500000 | J7: =I7 -> 92500000 | K7: =G7-J7 -> 398800000 | M7: =K7+L7 -> 398800000 | N7: ='004-4'!I7 -> 193900000 | P7: =N7 -> 193900000 | Q7: =M7-P7 -> 204900000 | S7: =Q7 -> 204900000 | T7: =S7 -> 204900000 | V7: =T7 -> 204900000
A8: 2. หมวดสิ่งก่อสร้าง
A9: งานโยธา | B9: =วงเงิน!B6*1000000 -> 1917600000 | C9: ='004-4'!M9 -> 793300000 | F9: =C9 -> 793300000 | G9: =F9+E9 -> 793300000 | I9: ='004-4'!H9 -> 56820000 | J9: =I9 -> 56820000 | K9: =G9-J9 -> 736480000 | M9: =K9+L9 -> 736480000 | N9: ='004-4'!I9 -> 391780000 | P9: =N9 -> 391780000 | Q9: =M9-P9 -> 344700000 | S9: =Q9 -> 344700000 | T9: ='004-4'!J9 -> 290160000 | V9: =T9 -> 290160000
A10: งานระบบไฟฟ้า
A11: - ค่าวัสดุอุปกรณ์
A12: - ค่าแรงงาน
A13: - ค่าขนส่ง
A14: - ค่าสำรวจออกแบบและควบคุม | B14: =วงเงิน!B7*1000000 -> 57530000 | C14: ='004-4'!M14 -> 23800000 | F14: =C14 -> 23800000 | G14: =F14+E14 -> 23800000 | I14: ='004-4'!H14 -> 1705000 | J14: =I14 -> 1705000 | K14: =G14-J14 -> 22095000 | M14: =K14+L14 -> 22095000 | N14: ='004-4'!I14 -> 11754000 | P14: =N14 -> 11754000 | Q14: =M14-P14 -> 10341000 | S14: =Q14 -> 10341000 | T14: ='004-4'!J14 -> 8705000 | V14: =T14 -> 8705000
A15: - ค่าเบ็ดเตล็ต
A16: - อื่น ๆ
A17: รวมงานระบบไฟฟ้า
A18: 3. หมวดเครื่องอุปกรณ์ไฟฟ้า
A19: 4. หมวดยานพาหนะ | B19: =วงเงิน!B9*1000000 -> 2094745000 | C19: ='004-4'!M19 -> 1036780000 | F19: =C19 -> 1036780000 | G19: =F19+E19 -> 1036780000 | I19: ='004-4'!H19 -> 67520000 | J19: =I19 -> 67520000 | K19: =G19-J19 -> 969260000 | M19: =K19+L19 -> 969260000 | N19: ='004-4'!I19 -> 279540000 | P19: =N19 -> 279540000 | Q19: =M19-P19 -> 689720000 | S19: =Q19 -> 689720000 | T19: ='004-4'!J19 -> 689720000 | V19: =T19 -> 689720000
A20: 5. หมวดเครื่องมือเครื่องใช้ขนาดเล็ก | B20: =วงเงิน!B8*1000000 -> 1363596000 | C20: ='004-4'!M20 -> 522930000 | F20: =C20 -> 522930000 | G20: =F20+E20 -> 522930000 | I20: ='004-4'!H20 -> 130000000 | J20: =I20 -> 130000000 | K20: =G20-J20 -> 392930000 | M20: =K20+L20 -> 392930000 | N20: ='004-4'!I20 -> 185000000 | P20: =N20 -> 185000000 | Q20: =M20-P20 -> 207930000 | S20: =Q20 -> 207930000 | T20: ='004-4'!J20 -> 207930000 | V20: =T20 -> 207930000
A21: 6. หมวดวิจัยและพัฒนา
A22: 7. หมวดอื่น ๆ
A23: รวม | B23: =SUM(B7:B20) -> 5924771000 | C23: =SUM(C7:C20) -> 2868110000 | F23: =SUM(F7:F20) -> 2868110000 | G23: =SUM(G7:G20) -> 2868110000 | I23: =SUM(I7:I20) -> 348545000 | J23: =I23+H23 -> 348545000 | K23: =G23-J23 -> 2519565000 | M23: =K23+L23 -> 2519565000 | N23: =SUM(N7:N20) -> 1061974000 | P23: =N23 -> 1061974000 | Q23: =M23-P23 -> 1457591000 | S23: =Q23 -> 1457591000 | T23: =SUM(T7:T20) -> 1401415000 | V23: =T23 -> 1401415000
A24: สำรองค่าปรับราคา | B24: =วงเงิน!B11*1000000 -> 2.25229e+08
A25: รวมทั้งสิ้น | B25: =B23+B24 -> 6150000000 | C25: =C23+C24 -> 2868110000 | F25: =F23+F24 -> 2868110000 | G25: =G23+G24 -> 2868110000 | I25: =I23+I24 -> 348545000 | J25: =J23+J24 -> 348545000 | K25: =K23+K24 -> 2519565000 | M25: =M23+M24 -> 2519565000 | N25: =N23+N24 -> 1061974000 | P25: =N25 -> 1061974000 | Q25: =Q23+Q24 -> 1457591000 | S25: =Q25 -> 1457591000 | T25: =T23+T24 -> 1401415000 | V25: =T25 -> 1401415000
W28: แบบ งป.010/2

Sheet 010-3
P1: แบบ งป. 010/3
A2: เป้าหมายการเบิกจ่ายรายเดือน ปี 2568 แยกรายภาคและสำนักงานใหญ่
A3: หน่วยงาน...................................................................
A4: งาน/แผนงาน.............................................................
A5: ชุด (ผูกพัน+ลงทุน) | P5: หน่วย: ล้านบาท
A6: ลำดับ ที่ | B6: ศูนย์การไฟฟ้า | D6: ประมาณจ่ายปี 2568
D7: ม.ค. | E7: ก.พ. | F7: มี.ค. | G7: เม.ย. | H7: พ.ค. | I7: มิ.ย. | J7: ก.ค. | K7: ส.ค. | L7: ก.ย. | M7: ต.ค. | N7: พ.ย. | O7: ธ.ค. | P7: รวม
A9: 1 | B9: การไฟฟ้าภาค 1
A10: 2 | B10: การไฟฟ้าภาค 2
A11: 3 | B11: การไฟฟ้าภาค 3
A12: 4 | B12: การไฟฟ้าภาค 4
A13: 5 | B13: สำนักงานใหญ่
A14: รวมทั้งสิ้น
C15: หมายเหตุ - ดำเนินการภายหลังจากได้รับอนุมัติงบประมาณประจำปีจากคณะกรรมการ กฟภ. แล้ว
C16: - ประมาณจ่ายแบ่งตามพื้นที่ดำเนินการ (ภาค 1-4 , สำนักงานใหญ่)

Sheet 011
A2: ประมาณการวัสดุอุปกรณ์นำเข้าจากต่างประเทศ (Import Content)
A3: ประจำปี .......2568...............
A4: (งบลงทุนเพื่อการดำเนินงานปกติ)
A5: กลุ่มโครงสร้าง..............................................
A6: ชื่องาน
A7: หน่วยงาน
T8: หน่วย : บาท
A9: ที่ | B9: รายการ | C9: ปีเริ่มต้น - ปี 2565 | D9: ปี 2566 | E9: ปี 2567 | F9: ปี 2568 | S9: ปี 2569 | T9: ปี 2570 - ปีสิ้นสุด
F10: ประมาณการเบิกจ่ายรายเดือน | R10: รวม
F11: ม.ค. | G11: ก.พ. | H11: มี.ค. | I11: เม.ย. | J11: พ.ค. | K11: มิ.ย. | L11: ก.ค. | M11: ส.ค. | N11: ก.ย. | O11: ต.ค. | P11: พ.ย. | Q11: ธ.ค.
B12: ทางตรง
B18: ทางอ้อม
B19: หมายถึง การจัดซื้อจัดหาผ่านตัวแทนจำหน่าย
B20: หรือผ่านผู้รับเหมา
A27: หมายเหตุ | B27: วัสดุอุปกรณ์นำเข้าจากต่างประเทศ (Import Content) หมายถึง การใช้หรือการนำเข้าพัสดุที่ผลิตสำเร็จรูปแล้วจากต่างประเทศ
B28: ไม่ว่าจะนำเข้าโดยคู่สัญญาหรือบุคคลอื่นใด | U28: แบบ งป.011

Sheet 010-2 (2)
A2: แผนการจ่ายเงินตามงบผูกพันปี 2568 (กรณีแผนระยะยาว/งานต่อเนื่อง)
V3: หน่วย : บาท
A4: รายการ | B4: วงเงินเต็ม แผนงาน | C4: อนุมัติถึง ปี 2568 | D4: จ่ายจริงถึง ปี 2567 | E4: ปี 2571 | K4: ปี 2572 | Q4: ปี 2573
E5: งบประมาณ | H5: ประมาณจ่าย | K5: งบประมาณ | N5: ประมาณจ่าย | Q5: งบประมาณ | T5: ประมาณจ่าย
E6: ผูกพัน | F6: ลงทุน | G6: รวม | H6: ผูกพัน | I6: ลงทุน | J6: รวม | K6: ผูกพัน | L6: ลงทุน | M6: รวม | N6: ผูกพัน | O6: ลงทุน | P6: รวม | Q6: ผูกพัน | R6: ลงทุน | S6: รวม | T6: ผูกพัน | U6: ลงทุน | V6: รวม
A7: 1. หมวดที่ดิน | B7: =วงเงิน!B5*1000000 -> 491300000 | C7: ='004-4'!M7 -> 491300000 | D7: =C7 -> 491300000 | F7: 0 | G7: =E7+F7 -> 0 | I7: 0 | J7: =I7 -> 0 | K7: =G7-J7 -> 0 | M7: =K7+L7 -> 0 | O7: 0 | P7: =O7 -> 0 | Q7: 0 | S7: =Q7 -> 0
A8: 2. หมวดสิ่งก่อสร้าง
A9: งานโยธา | B9: =วงเงิน!B6*1000000 -> 1917600000 | C9: ='004-4'!M9 -> 793300000 | D9: ='010-2'!J9+'010-2'!P9+'010-2'!V9 -> 738760000 | E9: ='010-2'!S9-'010-2'!V9 -> 54540000 | F9: 0 | G9: =F9+E9 -> 54540000 | H9: ='004-4'!K9 -> 24240000 | I9: 0 | J9: =H9 -> 24240000 | K9: =G9-J9 -> 30300000 | M9: =K9+L9 -> 30300000 | N9: ='004-4'!L9 -> 30300000 | O9: 0 | P9: =N9 -> 30300000 | Q9: =M9-P9 -> 0 | S9: =Q9 -> 0 | U9: 0 | V9: =U9 -> 0
A10: งานระบบไฟฟ้า
A11: - ค่าวัสดุอุปกรณ์
A12: - ค่าแรงงาน
A13: - ค่าขนส่ง
A14: - ค่าสำรวจออกแบบและควบคุม | B14: =วงเงิน!B7*1000000 -> 57530000 | C14: ='004-4'!M14 -> 23800000 | D14: ='010-2'!J14+'010-2'!P14+'010-2'!V14 -> 22164000 | E14: ='010-2'!S14-'010-2'!V14 -> 1636000 | F14: 0 | G14: =F14+E14 -> 1636000 | H14: ='004-4'!K14 -> 727000 | I14: 0 | J14: =H14 -> 727000 | K14: =G14-J14 -> 909000 | M14: =K14+L14 -> 909000 | N14: ='004-4'!L14 -> 909000 | O14: 0 | P14: =N14 -> 909000 | Q14: =M14-P14 -> 0 | S14: =Q14 -> 0 | U14: 0 | V14: =U14 -> 0
A15: - ค่าเบ็ดเตล็ต
A16: - อื่น ๆ
A17: รวมงานระบบไฟฟ้า
A18: 3. หมวดเครื่องอุปกรณ์ไฟฟ้า
A19: 4. หมวดยานพาหนะ | B19: =วงเงิน!B9*1000000 -> 2094745000 | C19: ='004-4'!M19 -> 1036780000 | D19: ='010-2 (2)'!C19 -> 1036780000 | F19: 0 | G19: =F19+E19 -> 0 | I19: 0 | J19: =I19 -> 0 | K19: =G19-J19 -> 0 | M19: =K19+L19 -> 0 | O19: 0 | P19: =O19 -> 0 | Q19: 0 | S19: =Q19 -> 0 | U19: 0 | V19: =U19 -> 0
A20: 5. หมวดเครื่องมือเครื่องใช้ขนาดเล็ก | B20: =วงเงิน!B8*1000000 -> 1363596000 | C20: ='004-4'!M20 -> 522930000 | D20: =C20 -> 522930000 | F20: 0 | G20: =F20+E20 -> 0 | I20: 0 | J20: =I20 -> 0 | K20: =G20-J20 -> 0 | M20: =K20+L20 -> 0 | O20: 0 | P20: =O20 -> 0 | Q20: 0 | S20: =Q20 -> 0 | U20: 0 | V20: =U20 -> 0
A21: 6. หมวดวิจัยและพัฒนา
A22: 7. หมวดอื่น ๆ
A23: รวม | B23: =SUM(B7:B20) -> 5924771000 | C23: =SUM(C7:C20) -> 2868110000 | D23: =SUM(D7:D20) -> 2811934000 | E23: =SUM(E7:E20) -> 56176000 | F23: =SUM(F7:F20) -> 0 | G23: =SUM(G7:G20) -> 56176000 | H23: =SUM(H7:H20) -> 24967000 | I23: =SUM(I7:I20) -> 0 | J23: =I23+H23 -> 24967000 | K23: =G23-J23 -> 31209000 | M23: =K23+L23 -> 31209000 | N23: =L23+M23 -> 31209000 | O23: =SUM(O7:O20) -> 0 | P23: =N23+O23 -> 31209000 | Q23: =M23-P23 -> 0 | S23: =Q23 -> 0 | U23: =SUM(U7:U20) -> 0 | V23: =U23 -> 0
A24: สำรองค่าปรับราคา | B24: =วงเงิน!B11*1000000 -> 2.25229e+08
A25: รวมทั้งสิ้น | B25: =B23+B24 -> 6150000000 | C25: =C23+C24 -> 2868110000 | D25: =D23+D24 -> 2811934000 | E25: =E23+E24 -> 56176000 | F25: =F23+F24 -> 0 | G25: =G23+G24 -> 56176000 | H25: =H23+H24 -> 24967000 | I25: =I23+I24 -> 0 | ... K25: =K23+K24 -> 31209000 | M25: =M23+M24 -> 31209000 | N25: =N23+N24 -> 31209000 | O25: =O23+O24 -> 0 | P25: =P23+P24 -> 31209000 | Q25: =Q23+Q24 -> 0 | S25: =Q25 -> 0 | U25: =U23+U24 -> 0 | V25: =U25 -> 0
W28: แบบ งป.010/2

Sheet วงเงิน
A1: แผนสนับสนุนการดำเนินงาน ระยะที่ 6 (ปี 2568 - 2570)
A3: รายการ | B3: วงเงินรวม (ล้านบาท) | C3: จำนวน | D3: วงเงินดำเนินการ (ล้านบาท) | G3: วงเงินคาดจ่าย (ล้านบาท)
C4: (รายการ) | D4: ปี 2568 | E4: ปี 2569 | F4: ปี 2570 | G4: ปี 2568 | H4: ปี 2569 | I4: ปี 2570 | J4: ปี 2571 | K4: ปี 2572
A5: 1. หมวดที่ดิน | B5: =SUM(D5:F5) -> 491.3 | C5: ='[1]สรุปรวม (ที่ดิน+สิ่งก่อสร้าง)'!C8 -> 56 | D5: ='[1]สรุปรวม (ที่ดิน+สิ่งก่อสร้าง)'!D8 -> 491.3 | E5: ='[1]สรุปรวม (ที่ดิน+สิ่งก่อสร้าง)'!E8 -> - | F5: ='[1]สรุปรวม (ที่ดิน+สิ่งก่อสร้าง)'!F8 -> - | G5: ='[2]งานด้านจัดหาที่ดิน 15 พย.66'!N79 -> 92.5 | H5: ='[2]งานด้านจัดหาที่ดิน 15 พย.66'!O79 -> 193.9 | I5: ='[2]งานด้านจัดหาที่ดิน 15 พย.66'!P79 -> 204.9 | J5: 0 | K5: ='[2]งานด้านจัดหาที่ดิน 15 พย.66'!Q79 -> 0 | L5: =G5/$B$5 -> 0.188276 | M5: =H5/$B$5 -> 0.39466721 | N5: =I5/$B$5 -> 0.41705679 | O5: =J5/$B$5 -> 0 | P5: =K5/$B$5 -> 0 | Q5: =SUM(G5:K5)-SUM(D5:F5) -> 0
A6: 2. หมวดสิ่งก่อสร้าง | B6: =SUM(D6:F6) -> 1917.6 | C6: ='[1]สรุปรวม (ที่ดิน+สิ่งก่อสร้าง)'!C10 -> 79 | D6: ='[1]สรุปรวม (ที่ดิน+สิ่งก่อสร้าง)'!D10 -> 793.3 | E6: ='[1]สรุปรวม (ที่ดิน+สิ่งก่อสร้าง)'!E10 -> 632.3 | F6: ='[1]สรุปรวม (ที่ดิน+สิ่งก่อสร้าง)'!F10 -> 492 | G6: =[2]รายละเอียดสิ่งก่อสร้าง!G179 -> 56.82 | H6: =[2]รายละเอียดสิ่งก่อสร้าง!H179 -> 439.8 | I6: =[2]รายละเอียดสิ่งก่อสร้าง!I179 -> 670.43 | J6: =[2]รายละเอียดสิ่งก่อสร้าง!J179 -> 539.8 | K6: =[2]รายละเอียดสิ่งก่อสร้าง!K179 -> 210.75 | L6: =G6/$B$6 -> 0.029630788 | M6: =H6/$B$6 -> 0.22934919 | N6: =I6/$B$6 -> 0.34961932 | O6: =J6/$B$6 -> 0.28149771 | P6: =K6/$B$6 -> 0.109903 | Q6: =SUM(G6:K6)-SUM(D6:F6) -> 0 | R6: 634.7 | S6: 485.6
A7: ค่าสำรววจ-ควบคุมงาน 3% | B7: =SUM(D7:F7) -> 57.53 | D7: ='[1]สรุปรวม (ที่ดิน+สิ่งก่อสร้าง)'!D12 -> 23.8 | E7: ='[1]สรุปรวม (ที่ดิน+สิ่งก่อสร้าง)'!E12 -> 18.97 | F7: ='[1]สรุปรวม (ที่ดิน+สิ่งก่อสร้าง)'!F12 -> 14.76 | G7: =ROUND(G6*0.03,3) -> 1.705 | H7: =ROUND(H6*0.03,3) -> 13.194 | I7: =ROUND(I6*0.03,3) -> 20.113 | J7: =ROUND(J6*0.03,3) -> 16.194 | K7: =ROUND(K6*0.03,3)+0.001 -> 6.324 | L7: =G7/$B$7 -> 0.029636711 | M7: =H7/$B$7 -> 0.22934121 | N7: =I7/$B$7 -> 0.3496089 | O7: =J7/$B$7 -> 0.28148792 | P7: =K7/$B$7 -> 0.10992526 | Q7: =SUM(G7:K7)-SUM(D7:F7) -> 0
A8: 3. หมวดเครื่องมือ-เครื่องใช้ | B8: =SUM(D8:F8) -> 1363.596 | C8: =(SUM('[1]รวมทุกปีเครื่องมือ (ส่วนกลาง)'!AD254:AE254)+SUM('[1]รวมทุกปีเครื่องมือ (ภูมิภาค)'!AB262:AC262)) -> 2622 | D8: =('[1]ปี 2568 (ส่วนกลาง)'!BH254+'[1]ปี 2568 (ภูมิภาค)'!BD262)/1000000 -> 522.93 | E8: =('[1]ปี 2569 (ส่วนกลาง)'!BH254+'[1]ปี 2569 (ภูมิภาค)'!BD262)/1000000 -> 495.626 | F8: =('[1]ปี 2570 (ส่วนกลาง)'!BH254+'[1]ปี 2570 (ภูมิภาค)'!BD262)/1000000 -> 345.04 | G8: 130 | H8: 385 | I8: 460 | J8: 300 | K8: 88.596 | L8: =G8/$B$8 -> 0.095336155 | M8: =H8/$B$8 -> 0.28234169 | N8: =I8/$B$8 -> 0.33734332 | O8: =J8/$B$8 -> 0.22000651 | P8: =K8/$B$8 -> 0.064972323 | Q8: =SUM(G8:K8)-SUM(D8:F8) -> 0 | S8: 68 | T8: 69 | U8: 70 | V8: 71 | W8: 72
A9: 4. หมวดยานพาหนะ | B9: =SUM(D9:F9) -> 2094.745 | C9: ='[1]สรุปแผนงาน (ยานพาหนะ)'!AE16+'[1]สรุปแผนงาน (ยานพาหนะ)'!AE37 -> 519 | D9: ='[1]สรุปแผนงาน (ยานพาหนะ)'!AG16/1000000 -> 1036.78 | E9: ='[1]สรุปแผนงาน (ยานพาหนะ)'!AG37/1000000 -> 1057.965 | F9: 0 | G9: ='[2]ประมาณเบิกจ่าย (ยานพาหนะ)'!BO29/1000000 -> 67.52 | H9: ='[2]ประมาณเบิกจ่าย (ยานพาหนะ)'!BP29/1000000 -> 324.74 | I9: ='[2]ประมาณเบิกจ่าย (ยานพาหนะ)'!BQ29/1000000 -> 893.52 | J9: ='[2]ประมาณเบิกจ่าย (ยานพาหนะ)'!BR29/1000000 -> 808.965 | K9: ='[2]ประมาณเบิกจ่าย (ยานพาหนะ)'!BS29/1000000 -> 0 | L9: =G9/$B$9 -> 0.03223304 | M9: =H9/$B$9 -> 0.15502603 | N9: =I9/$B$9 -> 0.42655311 | O9: =J9/$B$9 -> 0.38618782 | P9: =K9/$B$9 -> 0 | Q9: =SUM(G9:K9)-SUM(D9:F9) -> 0 | S9: =SUM(S10:S17) -> 3 | T9: =SUM(T10:T17) -> 23 | U9: =SUM(U10:U17) -> 35 | V9: =SUM(V10:V17) -> 35 | W9: =SUM(W10:W17) -> 20 | X9: =SUM(X10:X17) -> 0
A10: รวม 4 หมวด | B10: =SUM(B5:B9) -> 5924.771 | D10: =SUM(D5:D9) -> 2868.11 | E10: =SUM(E5:E9) -> 2204.861 | F10: =SUM(F5:F9) -> 851.8 | G10: =SUM(G5:G9) -> 348.545 | H10: =SUM(H5:H9) -> 1356.634 | I10: =SUM(I5:I9) -> 2248.963 | J10: =SUM(J5:J9) -> 1664.959 | K10: =SUM(K5:K9) -> 305.67 | Q10: =SUM(G10:K10)-SUM(D10:F10) -> 0 | S10: 3 | T10: 20 | U10: 12
A11: สำรองราคา | B11: =SUM(D11:F11) -> 225.229 | D11: 0 | E11: 180 | F11: 45.229 | G11: 0 | H11: =ROUND($B$11*H24/100,3) -> 42.794 | I11: =ROUND($B$11*I24/100,3) -> 108.11 | J11: =ROUND($B$11*J24/100,3) -> 60.812 | K11: =ROUND($B$11*K24/100,3)-0.001 -> 13.513 | Q11: =SUM(G11:K11)-SUM(D11:F11) -> 0 | T11: 3 | U11: 20 | V11: 12
A12: รวมทั้งสิ้น | B12: =B11+B10 -> 6150 | C12: =SUM(C5:C9) -> 3276 | D12: =D11+D10 -> 2868.11 | E12: =E11+E10 -> 2384.861 | F12: =F11+F10 -> 897.029 | G12: =G11+G10 -> 348.545 | H12: =H11+H10 -> 1399.428 | I12: =I11+I10 -> 2357.073 | J12: =J11+J10 -> 1725.771 | K12: =K11+K10 -> 319.183 | Q12: =SUM(G12:K12)-SUM(D12:F12) -> 0 | U12: 3 | V12: 20
V13: 3 | W13: 20
M14: =B5+B6+B7 -> 2466.43
M15: 2041.876 | N15: ราคาแก้ไข จาก กอย. 11 พ.ย. 2563
B16: =B5/$B$12 -> 0.079886179 | C16: 9 | M16: =M15-M14 -> -424.554
B17: =B6/$B$12 -> 0.31180488 | C17: 33
B19: =B8/$B$12 -> 0.22172293 | C19: 23
B20: =B9/$B$12 -> 0.34060894 | C20: 35 | V20: เพิ่มอาคารอเนกประสงค์
K21: จัดทำโดย กจก.
J22: วันที่ 16 พฤศจิกายน 2566
G24: =SUM(H10:K10) -> 5576.226 | H24: 19 | I24: 48 | J24: 27 | K24: 6
E26: 128.543 | F26: 97 | H26: 42.853 | I26: 108.261 | J26: 60.897 | K26: 13.532
G27: 485.48945

Sheet รายละเอียดด้านจัดหาที่ดิน
A1: รายละเอียดด้านจัดหาที่ดินที่เสนอจัดตั้ง
A2: แผนงานสนับสนุนการดำเนินงาน ระยะที่ 6 ปีงบประมาณ 2568
A3: บัญชีรายการสิ่งก่อสร้างที่ผ่านหลักเกณฑ์การพิจารณาขั้นต้น
A4: จำนวน 56 รายการ
A7: ที่ | B7: สถานที่ | C7: ขนาดที่ดิน | D7: วงเงิน | E7: ปีงบประมาณ | F7: หมายเหตุ
C8: โดยประมาณ (ไร่) | D8: (ล้านบาท)
A9: กฟน.1
A10: 1 | B10: กฟส.อ.แม่สรวย จ.เชียงราย | C10: 3 - 5 | D10: 10 | E10: 2568 | F10: ซื้อใหม่
A11: 2 | B11: กฟส.ต.นางแล จ.เชียงราย | C11: 3 - 5 | D11: 30 | E11: 2568 | F11: ซื้อใหม่
A12: กฟน.2
A13: 3 | B13: กฟย.อ.ลับแล จ.อุตรดิตถ์ | C13: 3 - 5 | D13: 14.5 | E13: 2568 | F13: ซื้อใหม่
A14: 4 | B14: กฟย.อ.บึงสามัคคี จ.กำแพงเพชร | C14: 3 - 5 | D14: 5 | E14: 2568 | F14: ซื้อใหม่
A15: 5 | B15: กฟย.อ.วังทรายพูน จ.พิจิตร | C15: 3 - 5 | D15: 9.5 | E15: 2568 | F15: ซื้อใหม่
A16: 6 | B16: กฟย.อ.ดงเจริญ จ.พิจิตร | C16: 3 - 5 | D16: 9.5 | E16: 2568 | F16: ซื้อใหม่
A17: 7 | B17: กฟจ.กำแพงเพชร | C17: 0-0-88 | D17: 1.5 | E17: 2568 | F17: ซื้อขยายสำนักงานเดิม
A18: กฟน.3
A19: 8 | B19: กฟย.ต.หัวหวาย จ.นครสวรรค์ | C19: 3 - 5 | D19: 4 | E19: 2568 | F19: ซื้อใหม่
A20: 9 | B20: กฟย.อ.ห้วยคต จ.อุทัยธานี | C20: 3 - 5 | D20: 6 | E20: 2568 | F20: ซื้อใหม่
A21: 10 | B21: กฟย.อ.หนองมะโมง จ.ชัยนาท | C21: 3 - 5 | D21: 5 | E21: 2568 | F21: ซื้อใหม่
A22: 11 | B22: กฟย.อ.หนองขาหย่าง จ.อุทัยธานี | C22: 3 - 5 | D22: 4 | E22: 2568 | F22: ซื้อใหม่
A23: 12 | B23: กฟย.ต.พุเตย จ.เพชรบูรณ์ | C23: 3 - 5 | D23: 5.5 | E23: 2568 | F23: ซื้อใหม่
A24: 13 | B24: กฟย.บ.หนองเบน จ.นครสวรรค์ | C24: 3 - 5 | D24: 8 | E24: 2568 | F24: ซื้อใหม่
A25: 14 | B25: กฟย.อ.โกรกพระ จ.นครสวรรค์ | C25: 3 - 5 | D25: 7.5 | E25: 2568 | F25: ซื้อใหม่
