Workbook
Name S1_สร้าง_กฟภ._ให้เติบโตอย่างยั่งยืน: S!$C$3:$C$12
Name SO1_ยกระดับการบริหาร_จัดการระดับสากล_เพื่อสร้าง_ความยั่งยืน: S!$B$3:$B$12
Name ยุทธศาสตร์: S!$C$2:$C$12
Name วัตถุประสงค์เชิงยุทธศาสตร์: S!$B$2:$B$12

Sheet ปก
A10: แบบฟอร์มเสนอขอตั้งงบประมาณลงทุน
A11: เพื่อการดำเนินงานปกติ ประจำปี 2570

Sheet รายชื่อฟอร์ม
A1: แบบฟอร์มเสนอขอตั้งงบประมาณลงทุน
A2: เพื่อการดำเนินงานปกติ ประจำปี 2570
A4: 1. | B4: แบบ งป.003 | C4: สรุปวงเงินงบประมาณลงทุนเพื่อการดำเนินงานปกติ ที่ขอตั้งประจำปี 2570
A5: 2. | B5: แบบ งป.004/1 - งป.004/5 | C5: แบบข้อมูลพื้นฐานของงาน
A6: 3. | B6: แบบ งป.007 | C6: รายละเอียดงานในหมวดสิ่งก่อสร้าง ค่าวัสดุอุปกรณ์ของงานระบบไฟฟ้า
A7: 4. | B7: แบบ งป.009 | C7: รายงานความก้าวหน้าของแผนจัดซื้อ/จัดจ้างตามงบลงทุนเพื่อการดำเนินงานปกติ
A8: 5. | B8: แบบ งป.010/1 | C8: แผนการลงทุนรายปี
A9: 6. | B9: แบบ งป.010/2 | C9: แผนการจ่ายเงินตามงบผูกพันปี 2570 (กรณีแผนระยะยาว/งานต่อเนื่อง)
A10: 7. | B10: แบบ งป.010/3 | C10: เป้าหมายการเบิกจ่ายรายเดือน ปี 2570 แยกรายภาคและสำนักงานใหญ่
A11: 8. | B11: แบบ งป.011 | C11: ประมาณการวัสดุอุปกรณ์นำเข้าจากต่างประเทศ (Import Content) ปี 2570

Sheet 003
D1: แบบ งป.003
A2: สรุปวงเงินงบประมาณลงทุนเพื่อการดำเนินงานปกติ
A3: ที่ขอตั้งประจำปี 2570
A4: หน่วยงาน กองบริหารจัดการระบบไฟฟ้า (กบร.)
D5: หน่วย : บาท
A6: ที่ | B6: ชื่องาน | D6: วงเงินเสนอ
D7: ขอตั้งปี 2570 [1]
A8: 1 | B8: แผนงานจัดหาอุปกรณ์ป้องกัน/ตัดตอน/อุปกรณ์ประกอบและอุปกรณ์สำรองสำหรับสายเคเบิลใต้ดิน/ใต้น้ำ ในระบบจำหน่ายและสายส่งไฟฟ้า (ปี 2569-2571) | D8: ='010-1 (2)'!H31 -> 256813242
B10: สำรองราคา | D10: 8616398
A31: รวม | D31: =D8+D10 -> 265429640
A32: หมายเหตุ | B32: [1] 1.แผนงานระยะยาว กรอกวงเงินที่ขอตั้งดำเนินการในปีงบประมาณ 2570 และวงเงินไม่รวมภาษีมูลค่าเพิ่ม
B33: 2.ให้กรอกวงเงินโดยปัดเศษสตางค์เป็นหลักหน่วย

Sheet 004-1
L1: แบบ งป.004/1
A2: แบบข้อมูลพื้นฐานของงาน
A3: (งบลงทุนเพื่อการดำเนินงานปกติ)
A5: 1. | B5: ชื่องาน/แผนงาน | D5: แผนงานจัดหาอุปกรณ์ป้องกัน/ตัดตอน/อุปกรณ์ประกอบและอุปกรณ์สำรองสำหรับสายเคเบิลใต้ดิน/ใต้น้ำ ในระบบจำหน่ายและสายส่งไฟฟ้า (ปี 2569-2571)
A7: 2. รายละเอียดของงาน/แผนงาน
B8: 2.1 ผู้รับผิดชอบ | D8: แผนก : | E8: แผนกจัดการงานบำรุงรักษาอุปกรณ์ป้องกันและตัดตอน
D9: กอง : | E9: กองบริหารจัดการระบบไฟฟ้า | G9: ฝ่าย : | H9: ฝ่ายบริหารจัดการสินทรัพย์ระบบไฟฟ้า
D10: สายงาน : | E10: ปฏิบัติการระบบไฟฟ้า | G10: เบอร์โทร : | H10: 5467
B11: 2.2 ความจำเป็นในการดำเนินงาน (ทำเครื่องหมาย ü)
C12: ( ) | D12: มีสัญญา ข้อผูกพัน หรือมีเงื่อนไขที่ต้องดำเนินการ | I12: ( ü ) | J12: นโยบายสำคัญของรัฐบาล
C13: ( ) | D13: นโยบายสำคัญของ กฟภ. | I13: ( ) | J13: อื่นๆ
B14: 2.3 ประเภทการลงทุน (ทำเครื่องหมาย ü)
C15: ( ) งานก่อสร้าง ขยายเขตและปรับปรุงระบบจำหน่าย | I15: ( ü ) | J15: งานบำรุงรักษาด้านระบบไฟฟ้า
C16: ( ) งานติดตั้งระบบศูนย์สั่งการจ่ายไฟ | I16: ( ) | J16: งาน IT
C17: ( ) งานจัดหาที่ดิน อาคาร ยานพาหนะ และ | I17: ( ) | J17: งานพัฒนาระบบสื่อสาร
D18: เครื่องมือเครื่องใช้ต่างๆ
A19: 2.4 สถานะของงาน | E19: ( ü ) | F19: งาน/แผนงาน ต่อเนื่อง | I19: ( ) | J19: งาน/แผนงาน ใหม่
A20: 2.5 ได้รับอนุมัติจาก | E20: ( ) | F20: ผวก. ลงนาม วันที่
E21: ( ) | F21: คณะกรรมการ กฟภ. วันที่
E22: ( ) | F22: ยังไม่ได้รับการอนุมัติ (โปรดระบุสถานะปัจจุบัน)
A23: 2.6 พื้นที่ดำเนินการ | E23: กฟข. 12 เขต
A24: 2.7 ระยะเวลาดำเนินการ | E24: 3 | F24: ปี | G24: (ปี 2569 - 2571 )[1]
A25: 2.8 วงเงินลงทุนทั้งสิ้น ของงาน/แผนงาน[2] | G25: ='010-1 (2)'!L33 -> 742286844 | K25: บาท
A26: 2.9 วงเงินลงทุนปี 2570 ของงาน/แผนงาน[3] | G26: ='010-1 (2)'!H31 -> 256813242 | K26: บาท
A27: 2.10 เป้าหมายการเบิกจ่ายงบลงทุนปี 2570 | G27: ='007 (70)'!J77 -> 0 | K27: บาท
A28: 2.11 วงเงิน งบทำการ ที่ขอตั้งในปี 2570 (ถ้ามี) | G28: - | K28: บาท
A29: 3. วัตถุประสงค์ของงาน/แผนงาน
C30: เพื่อเปลี่ยนอุปกรณ์ในระบบจำหน่าย และระบบสายส่งไฟฟ้าทดแทนการชำรุด
C31: เพื่อเปลี่ยนอุปกรณ์ในระบบจำหน่าย และระบบสายส่งไฟฟ้าทดแทนการเสื่อมสภาพการใช้งาน
C32: เพื่อเป็นอุปกรณ์สำรองไว้ใช้งานกรณีซ่อมแซมฉุกเฉิน สำหรับระบบจำหน่าย และระบบสายส่งไฟฟ้าใต้ดิน/ใต้น้ำ
B35: หมายเหตุ | C35: [1] ปีแรกที่ตั้งวงเงินดำเนินการ - จ่ายจนสิ้นสุดงาน/แผนงาน
C36: [2] วงเงินไม่รวมภาษีมูลค่าเพิ่ม
C37: [3] วงเงินไม่รวมภาษีมูลค่าเพิ่ม , หากมีสำรองราคาให้รวมสำรองราคาด้วย

Sheet 004-2
H1: แบบ งป.004/2
C3: 4. ผลประโยชน์ที่คาดว่าจะได้รับ
D4: 4.1 ผลประโยชน์ที่คาดว่าจะได้รับหลังเสร็จสิ้นงาน/แผนงาน
D5: - ผลผลิต(Output) [1] | F5: ดำเนินงานปรับปรุงเพิ่มความมั่นคงระบบจำหน่าย และสายส่งไฟฟ้า
D6: ได้อย่างมีประสิทธิภาพ ครบ 100 %
D7: - ผลลัพธ์(Outcome) [2] | F7: เพิ่มความมั่นคง และรักษาระดับความเชื่อถือได้ของระบบจำหน่าย
D8: และระบบสายส่งไฟฟ้าของ กฟภ.
D9: 4.2 ผลประโยชน์ที่คาดว่าจะได้รับในปี 2570 (กรณีเป็นแผนงานระยะยาว)
D10: - ผลผลิต(Output) [1] | F10: ดำเนินงานปรับปรุงเพิ่มความมั่นคงระบบจำหน่าย และสายส่งไฟฟ้า
D11: ได้อย่างมีประสิทธิภาพ ครบ 100 %
D12: - ผลลัพธ์(Outcome) [2] | F12: เพิ่มความมั่นคง และรักษาระดับความเชื่อถือได้ของระบบจำหน่าย
D13: และระบบสายส่งไฟฟ้าของ กฟภ.
D14: 4.3 ก่อให้เกิดประโยชน์กับ กฟภ. (ทำเครื่องหมาย ü พร้อมระบุวงเงิน)
D15: ( ü ) | E15: เพิ่มรายได้ | F15: - | G15: บาท
D16: ( ü ) | E16: ลดค่าใช้จ่าย | F16: - | G16: บาท
D17: ( ) | E17: อื่นๆ ระบุ
C18: 5. การวิเคราะห์ผลกระทบทางธุรกิจ
D19: 5.1 ผลกระทบต่อองค์กร
D20: มีการบริหารจัดการอุปกรณ์ไฟฟ้าในระบบจำหน่าย และสายส่งไฟฟ้าเป็นไปอย่างมีประสิทธิภาพ
D21: และมีแผนงานดำเนินการที่ชัดเจน
D22: 5.2 ผลกระทบต่อชุมชน สังคม และสิ่งแวดล้อม
D23: เพื่อสร้างความมั่นคงและเพิ่มเสถียรภาพของระบบจำหน่ายและสายส่งไฟฟ้า
C24: 6. ผลกระทบจากการไม่ได้รับพิจารณาให้ตั้งงบประมาณ
D25: เนื่องจากเป็นแผนระยะยาวที่ได้ประมาณการจากสถิติการชำรุดไว้แล้ว หากไม่ได้รับการจัดสรรอุปกรณ์ตาม
D26: ที่กำหนดไว้ อาจทำให้กระทบต่อการเปลี่ยนทดแทนการชำรุดของอุปกรณ์หลัก ซึ่งจะส่งผลต่อความมั่นคง
D27: และความเชื่อถือได้ของระบบ จำหน่าย 22/33 kV และระบบสายส่ง 115 kV
C28: 7. ปัญหา อุปสรรค และแนวทางในการแก้ไขปัญหา อุปสรรค
D29: กระบวนการจัดหาล่าช้า แก้ไขโดยการวางแผนงานและติดตามผลการดำเนินงาน
C31: 8. รายงานความก้าวหน้าของแผนจัดซื้อ/จัดจ้างตามแผนงานปกติ แบบ งป.009
C32: 9. แผนการลงทุนรายปี ในกรณีที่ทำมากกว่า 1 ปี ตาม งป.010/1
D33: และแผนการจ่ายเงินตามงบผูกพัน(กรณีแผนระยะยาว/งานต่อเนื่อง) ตาม งป.010/2
C34: 10. เป้าหมายการเบิกจ่ายรายเดือน แยกรายภาคและสำนักงานใหญ่ ตาม งป.010/3
C35: 11. ประมาณการวัสดุอุปกรณ์นำเข้าจากต่างประเทศ ตาม แบบ งป.011
C36: 12. การวิเคราะห์ประโยชน์และความคุ้มค่างาน/แผนงาน
C37: - | D37: ประมาณการผลตอบแทนงาน/แผนงาน
F38: ระยะเวลาคืนทุน (Payback Period) | H38: ปี
F39: อัตราผลตอบแทนเฉลี่ยรายปี (IRR) | H39: %
F40: มูลค่าปัจจุบันสุทธิ (NPV) | H40: ล้านบาท
F41: อัตราผลตอบแทนเฉลี่ยด้านการเงิน (FIRR) | H41: %
F42: อัตราผลตอบแทนเฉลี่ยด้านเศรษฐศาสตร์ (EIRR) | H42: %
...

Sheet S
B1: วัตถุประสงค์เชิงยุทธศาสตร์ | C1: ยุทธศาสตร์ | D1: กลยุทธ์ | H1: BSC
A2: SO1 ยกระดับการบริหารจัดการระดับสากลเพื่อสร้างความยั่งยืน | B2: SO1 ยกระดับการบริหารจัดการระดับสากลเพื่อสร้างความยั่งยืน | C2: S1 สร้าง กฟภ. ให้เติบโตอย่างยั่งยืน | H2: เป้าหมายองค์กร (Financial Goal)
A3: SO2 ระบบจําหน่ายที่มีประสิทธิภาพและสร้างความน่าเชื่อถือ ต่อลูกค้า และทุกกลุ่มผู้มีส่วนได้ส่วนเสีย | B3: SO1 ยกระดับการบริหารจัดการระดับสากลเพื่อสร้างความยั่งยืน | C3: S2 ยกระดับการบริหารทุนมนุษย์ | H3: ลูกค้า (Customer Goal)
A4: SO3 เสริมสร้างศักยภาพด้าน Digital Utility และ มุ่งสู่การเป็นผู้นํา ระบบไฟฟ้าในอนาคตระดับภูมิภาค | B4: SO1 ยกระดับการบริหารจัดการระดับสากลเพื่อสร้างความยั่งยืน | C4: S3 ส่งเสริมและพัฒนาขีดความสามารถด้วยเทคโนโลยีดิจิทัล (Digital Technology) ที่มีความมั่นคงปลอดภัย เพื่อการขับเคลื่อนองค์กร อย่างมีประสิทธิภาพ (Digital Transformation) | H4: กระบวนการภายใน (Internal Process Goal)
A5: SO4 ยกระดับผลประกอบการและทิศทางของ PEA Portfolio | B5: SO1 ยกระดับการบริหารจัดการระดับสากลเพื่อสร้างความยั่งยืน | C5: S4 การพัฒนาระบบจัดการนวัตกรรมองค์กร (Corporate Innovation System :CIS) | H5: การเรียนรู้และพัฒนา (Learning & Growth)
B6: SO2 ระบบจําหน่ายที่มีประสิทธิภาพและสร้างความน่าเชื่อถือ ต่อลูกค้า และทุกกลุ่มผู้มีส่วนได้ส่วนเสีย | C6: S5 พัฒนาระบบจําหน่ายที่ได้คุณภาพในระดับชั้นนําของภูมิภาค
B7: SO2 ระบบจําหน่ายที่มีประสิทธิภาพและสร้างความน่าเชื่อถือ ต่อลูกค้า และทุกกลุ่มผู้มีส่วนได้ส่วนเสีย | C7: S6 ยกระดับความพึงพอใจและความผูกพันของลูกค้าและกลุ่มผู้มี ส่วนได้ส่วนเสีย
B8: SO3 เสริมสร้างศักยภาพด้าน Digital Utility และ มุ่งสู่การเป็นผู้นํา ระบบไฟฟ้าในอนาคตระดับภูมิภาค | C8: S7 ยกระดับ Grid Modernization Roadmap & Implementation
B9: SO3 เสริมสร้างศักยภาพด้าน Digital Utility และ มุ่งสู่การเป็นผู้นํา ระบบไฟฟ้าในอนาคตระดับภูมิภาค | C9: S8 ส่งเสริมบทบาท กฟภ. ในการผลักดันบทบาทเพื่อรองรับนโยบาย การเปิดไฟฟ้าเสรี
B10: SO4 ยกระดับผลประกอบการและทิศทางของ PEA Portfolio | C10: S9 การกําหนดทิศทางเชิงยุทธศาสตร์ระหว่าง กฟภ. และบริษัทในเครือ
B11: SO4 ยกระดับผลประกอบการและทิศทางของ PEA Portfolio | C11: S10 การดําเนินงานตามแผนสําหรับธุรกิจเกี่ยวเนื่อง และการบริหาร Product Portfolio
B12: SO4 ยกระดับผลประกอบการและทิศทางของ PEA Portfolio | C12: S11 การปรับปรุงกฎระเบียบที่เกี่ยวข้องให้มีความคล่องตัว และ สามารถแข่งขันได้
B13: S1 สร้าง กฟภ. ให้เติบโตอย่างยั่งยืน | C13: OC1 วิเคราะห GAP และแนวทางการผลักดันองคกรสูความยั่งยืน
B14: S1 สร้าง กฟภ. ให้เติบโตอย่างยั่งยืน | C14: OC2 สนับสนุนการใชพลังงานอยางมีประสิทธิภาพ
B15: S2 ยกระดับการบริหารทุนมนุษย์ | C15: HCM1 สงเสริมการบริหารทุนมนุษยโดยใชเทคโนโลยีดิจิทัลในการพัฒนาระบบงานดาน HCM
B16: S2 ยกระดับการบริหารทุนมนุษย์ | C16: HCM2 พัฒนาระบบการเรียนรูและพัฒนาในการเสริมสรางและยกระดับสมรรถนะของบุคลากร
B17: S3 ส่งเสริมและพัฒนาขีดความสามารถด้วยเทคโนโลยีดิจิทัล (Digital Technology) ที่มีความมั่นคงปลอดภัย เพื่อการขับเคลื่อนองค์กร อย่างมีประสิทธิภาพ (Digital Transformation) | C17: DT1 พัฒนาขีดความสามารถดานเทคโนโลยีดิจิทัล เพื่อสะทอนถึงประสิทธิภาพของการบริหารคาใชจายและประสิทธิภาพของกระบวนการดําเนินงาน
... B31: S11 การปรับปรุงกฎระเบียบที่เกี่ยวข้องให้มีความคล่องตัว และ สามารถแข่งขันได้ | C31: RS1 ทบทวนกฎหมายระเบียบ ขอบังคับ เพื่อรองรับการดําเนินงานในธุรกิจเกี่ยวเนื่อง รวมถึงกํากับการดําเนินงานของบริษัทในเครือ เพื่อใหเกิด Synergy
B35: S1 ยกระดับการบริหารองค์กรและทุนมนุษย์
B36: S2 ส่งเสริมและพัฒนาขีดความสามารถด้วย เทคโนโลยีดิจิทัล (Digital Technology) ที่มีความมั่นคงปลอดภัย เพื่อการขับเคลื่อน องค์กรอย่างมีประสิทธิภาพ (Digital Transformation)
B37: S3 พัฒนาระบบจัดการนวัตกรรมองค์กร (Corporate Innovation System :CIS)
B38: S4 พัฒนาระบบจำหน่ายที่ได้คุณภาพใน ระดับชั้นนำของภูมิภาค ตาม Grid Modernization Roadmap
B39: S5 ยกระดับความพึงพอใจและความผูกพัน ของลูกค้าและกลุ่มผู้มีส่วนได้ส่วนเสีย
B40: S6 กำหนดทิศทางเชิงยุทธศาสตร์ ระหว่าง กฟภ. และบริษัทในเครือ
B41: S7 ดำเนินงานตามแผนสำหรับธุรกิจเกี่ยวเนื่อง และ การบริหารกลุ่มผลิตภัณฑ์(Product Portfolio)
B42: S8 ปรับปรุงกฎระเบียบที่เกี่ยวข้องให้มี ความคล่องตัว และสามารถแข่งขันได้
B43: S9 ส่งเสริมบทบาท กฟภ. ในการขับเคลื่อนนโยบาย การเปิดเสรีกิจการไฟฟ้า
B44: S10 เติบโตอย่างยั่งยืน เพิ่ม Eco-efficiency
B45: S11 เพิ่มสัดส่วนไฟฟ้าจาก Renewable Energy

Sheet 004-3
W1: แบบ งป.004/3
A2: 13. เหตุผลและความจำเป็นของงาน/แผนงาน
B3: 13.1 การสนับสนุนต่อยุทธศาสตร์ และวัตถุประสงค์เชิงยุทธศาสตร์ (เลือกได้มากกว่า 1 ยุทธศาสตร์) (ทำเครื่องหมาย ü)
A4: SO1 | D4: SO2 | I4: SO3
A5: เป็นผู้นำการให้บริการจำหน่ายไฟฟ้าด้วยเทคโนโลยีดิจิทัล นวัตกรรม และทุนมนุษย์ | D5: ยกระดับผลประกอบการของธุรกิจเกี่ยวเนื่องต่อยอดธุรกิจใหม่ | I5: เป็นองค์กรที่มีความพร้อมสำหรับการเปลี่ยนแปลงความท้าทายของประเทศเพื่อความยั่งยืน
A6: ( ) | B6: S1 พัฒนาประสิทธิภาพการทำงานและการให้บริการด้วยเทคโนโลยีเพื่อลดต้นทุน ค่าใช้จ่าย ควบคู่ไปกับการพัฒนาความสามารถด้านดิจิทัลและเทคโนโลยี AI ขององคกรและทุนมนษุยเพื่อรองรับ Industry 5.0, Electricity 5.0 และ Building 5.0 | C6: .......% | D6: ( ) | E6: S3 ขยายรายได้จากธุรกิจเกี่ยวเนื่อง | G6: .......% | I6: ( ü ) | J6: S4 เตรียมความพร้อมของระบบเพื่อรองรับการเปลี่ยนแปลงพลังงานในอนาคต | O6: .......%
A7: ( ) | B7: S2 ยกระดับความพึงพอใจและความผูกพันของบุคลากร ลูกค้าและผู้มีส่วนไดสวนเสีย | C7: .......% | I7: ( ) | J7: S5 การพัฒนาเติบโตอย่างยั่งยืนเพื่อพัฒนาองค์กร มุ่งสู่ Cabon Neutrality | O7: .......%
B8: หมายเหตุ : ทุกยุทธศาสตร์รวมกัน = 100%
B9: 13.2 การสนับสนุนต่อมุมมองตาม Balanced Scorecard
B10: มุมมอง : | C10: เป้าหมายองค์กร (Financial Goal)
B11: ตัวชี้วัดและเป้าหมาย : | C11: เพื่อปรับปรุงระบบไฟฟ้า ให้ความเชื่อถือได้ และสร้างความเชื่อมั่นแก่ผู้ใช้ไฟ
A13: 14. แนวทางในการดำเนินงานของงาน/แผนงาน
B14: 14.1 แผนการดำเนินงาน
A15: กิจกรรมหลัก | E15: หน่วยนับ | F15: ระยะเวลาดำเนินการ | O15: รวม
F16: ปีงบประมาณ | I16: ปี 70 | L16: ปี 71 - สิ้นสุดแผนงาน
F17: เริ่มต้น - ปี 69
B18: แผนงานจัดหาอุปกรณ์ป้องกัน/ตัดตอน/อุปกรณ์ประกอบและอุปกรณ์สำรองสำหรับสายเคเบิลใต้ดิน/ใต้น้ำ ในระบบจำหน่ายและสายส่งไฟฟ้า (ปี 2569-2571) (22 รายการ) (ไม่รวมสำรองราคา) | F18: ='010-1 (2)'!F31 -> 243722692 | I18: ='010-1 (2)'!H31 -> 256813242 | L18: ='010-1 (2)'!J31 -> 219751637 | O18: =F18+I18+L18 -> 720287571
A22: ร้อยละของงาน 100 % | F22: =F18/$O$18*100 -> 33.836859 | I22: =I18/$O$18*100 -> 35.654265 | L22: =L18/$O$18*100 -> 30.508875 | O22: =O18/$O$18*100 -> 100
B23: ( Ö ) | C23: ดำเนินการเอง …………… %
B24: ( ) | C24: จ้างเหมา ….……….……… %
B25: ( ) | C25: จ้างเหมาแบบ Turnkey …........... %

Sheet 004-4
J1: แบบ งป.004/4
B2: 14.2 งบประมาณลงทุนเพื่อการดำเนินงานปกติ ที่ขอตั้งประจำปี 2570
J3: หน่วย : บาท
A4: รายการ | F4: วงเงินดำเนินการ | H4: เป้าหมายการเบิกจ่าย(รายปี)
F5: ปี 2570 | H5: 2570 | I5: 2571 | J5: รวม
A6: เป้าหมายการเบิกจ่าย
A7: 1. หมวดที่ดิน (งป.005)
A8: 2. หมวดสิ่งก่อสร้าง
A9: งานโยธา (งป.006)
A10: งานระบบไฟฟ้า
B11: - ค่าวัสดุอุปกรณ์ (งป.007)
A12: แผนงานจัดหาอุปกรณ์ป้องกัน/ตัดตอน/อุปกรณ์ประกอบและอุปกรณ์สำรองสำหรับสายเคเบิลใต้ดิน/ใต้น้ำ ในระบบจำหน่ายและสายส่งไฟฟ้า (ปี 2569-2571)(รายการที่ 1 -22) ไม่รวมสำรองราคา
F13: ='010-1 (2)'!H31 -> 256813242 | H13: ='007 (70)'!J77 -> 0 | I13: ='007 (70)'!K77 -> 256813242 | J13: =H13+I13 -> 256813242
B17: รวมงานระบบไฟฟ้า | F17: =F13 -> 256813242 | H17: =H13 -> 0 | I17: =I13 -> 256813242 | J17: =J13 -> 256813242
A18: 3. หมวดเครื่องจักรอุปกรณ์ (งป.008)
A19: 4. หมวดยานพาหนะ (งป.008)
A20: 5. หมวดเครื่องมือ เครื่องใช้ขนาดเล็ก (งป.008)
A21: 6. หมวดวิจัยและพัฒนา (งป.008)
A22: 7. หมวดอื่น ๆ (งป.008)
A23: 8. สำรองค่าปรับราคา(กรณีแผนระยะยาว) [1] | F23: 287213242 | H23: 17658942 | I23: 269554300 | J23: 287213242
A24: รวมทั้งสิ้น
A25: หมายเหตุ | B25: [1] สำรองค่าปรับราคา เป็นการตั้งวงเงินสำหรับสมทบการจัดซื้อ จัดจ้าง/จ้างเหมา กรณีเป็นแผนงานใหม่
B26: จะเริ่มตั้งสำรองราคาปี 2571 จนสิ้นสุดแผน

Sheet 004-5
A1: 15. การประเมินประสิทธิผลการควบคุมที่มีอยู่ และประเมินระดับความเสี่ยงของงาน/แผนงาน
A3: 15.1 การประเมินประสิทธิผลการควบคุมที่มีอยู่ของงาน/แผนงาน
A4: งาน/แผนงาน (ปัจจัยเสี่ยง) | C4: ประเภทของปัจจัยเสี่ยง S / O / F / C | E4: ประสิทธิผลการควบคุมที่มีอยู่ | K4: ผลสรุป (เพียงพอ(ü)/ไม่เพียงพอ(û))
E5: ผลการดำเนินงานเมื่อเทียบกับเป้าหมาย | H5: กระบวนการควบคุม | J5: การติดตาม
A6: 1.แผนงานจัดหาอุปกรณ์ป้องกัน/ตัดตอน/อุปกรณ์ประกอบและอุปกรณ์สำรองสำหรับสายเคเบิลใต้ดิน/ใต้น้ำ ในระบบจำหน่ายและสายส่งไฟฟ้า (ปี 2569-2571) | C6: O : Operational Risk ความเสี่ยงด้านการปฏิบัติการ | E6: ผลการดำเนินงานเป็นไปตามเป้าหมาย (เทียบเท่าระดับ 3) | H6: มีการควบคุมเป็นมาตรฐานของ แต่ละหน่วยงาน | J6: มีการติดตาม แต่ไม่มีการรายงานให้ผู้บริหารทราบ | K6: เพียงพอ
A10: ประสิทธิผลการควบคุมที่มีอยู่
A11: ระดับการควบคุม | C11: ผลการดำเนินงานเมื่อเทียบกับเป้าหมาย | F11: กระบวนการควบคุม | J11: การติดตาม
A12: 1 | B12: เบื่องต้น | C12: ผลการดำเนินงานต่ำกว่าเป้าหมายมาก (เทียบเท่าระดับ 1) | F12: ไม่มีมาตรฐานที่ชัดเจน | J12: ไม่มีการติดตาม
A13: 2 | B13: ไม่เป็นทางการ | C13: ผลการดำเนินงานต่ำกว่าเป้าหมาย (เทียบเท่าระดับ 2) | F13: มีการควบคุมเป็นมาตรฐาน แต่ยังไม่นำออกมาใช้ | J13: มีการควบคุม แต่ไม่มีการติดตาม
A14: 3 | B14: เป็นระบบ | C14: ผลการดำเนินงานเป็นไปตามเป้าหมาย (เทียบเท่าระดับ 3) | F14: มีการควบคุมเป็นมาตรฐาน ของแต่ละหน่วยงาน | J14: มีการติดตาม แต่ไม่มีการรายงานให้ผู้บริหารทราบ
A15: 4 | B15: บูรณาการ | C15: ผลการดำเนินงานดีกว่าเป้าหมาย (เทียบเท่าระดับ 4) | F15: มีการกำหนดเป็นมาตรฐาน ขององค์กร | J15: มีการติดตาม และมีการรายงานให้ผู้บริหารทราบเป็นระยะ
A16: 5 | B16: เกิดประโยชน์สูงสุด | C16: ผลการดำเนินงานดีกว่าเป้าหมายมาก (เทียบเท่าระดับ 5) | F16: มีการกำหนดเป็นมาตรฐานขององค์กร และเทียบเคียงกับ Best Practice | J16: มีการระบุระยะเวลาการติดตามและรายงานผลที่ชัดเจน
A18: หมายเหตุ : | B18: การให้คะแนน 1 - 5 คะแนน ตามตารางที่ 15.1 ใน 3 ประเด็น ดังนี้
B19: 1) ผลการดำเนินงานเมื่อเทียบกับเป้าหมาย
B20: 2) กระบวนการควบคุม | L20: แบบ งป.004/5
B21: 3) การติดตามประเมินผล
B22: โดยพิจารณาความเพียงพอจากการประเมินประสิทธิผลการควบคุมที่มีอยู่ หากปัจจัยเสี่ยงใดมีผลการประเมินในมิติใดมติหนึ่ง ต่ำกว่า 3 คะแนน ปัจจัยเสี่ยงนั้นจะถูกนำมาพิจารณาว่ามีประสิทธิผล
B23: ของการควบคุมไม่เพียงพอ ให้นำปัจจัยเสี่ยงดังกล่าวไปประเมินระดับความรุนแรงปัจจัยเสี่ยงของโครงการต่อไป หากปัจจัยเสี่ยงที่ระบุได้ เป็นเรื่องใหม่และยังไม่เคยดำเนินการมาก่อน ให้คาดการณ์ผลการประเมินฯ ทั้ง 3 ประเด็น
A24: 15.2 การประเมินระดับความรุนแรงปัจจัยเสี่ยงของงาน/แผนงาน
A25: ปัจจัยเสี่ยง | B25: ระดับความรุนแรง ก่อนการบริหารความเสี่ยง (ต้นปี 2568) | F25: แนวทางในการจัดการความเสี่ยง | I25: คาดการณ์ระดับความรุนแรง หลังการบริหารความเสี่ยง (ณ สิ้นปี 2568)
B27: โอกาส | D27: ผลกระทบ | I27: โอกาส | J27: ผลกระทบ | K27: ระดับความเสี่ยง
B28: (Likelihood : L) | D28: (Impact : I) | I28: (Likelihood : L) | J28: (Impact : I) | K28: (Risk Severity : LxI)
A29: 1) กระบวนการจัดซื้ออุปกรณ์ได้ล่าช้ากว่าแผนความต้องการใช้งานที่กำหนดไว้ | B29: 3 | D29: 3 | F29: มีการประชุมติดตามและสนับสนุนข้อมูลในการจัดหา | I29: 2 | J29: 2 | K29: 4
A33: ตารางโอกาสเกิด/ผลกระทบ
A34: ระดับ | B34: โอกาสเกิด (Likelihood : L) | D34: ผลกระทบ (Impact : I)
B35: ความหมาย | D35: ความหมาย
A36: 1 | B36: มีโอกาสเกิดขึ้นต่ำมาก | D36: มีผลกระทบต่ำมาก
A37: 2 | B37: มีโอกาสเกิดขึ้นต่ำ | D37: มีผลกระทบต่ำ
A38: 3 | B38: มีโอกาสเกิดขึ้นปานกลาง | D38: มีผลกระทบปานกลาง
A39: 4 | B39: มีโอกาสเกิดขึ้นสูง | D39: มีผลกระทบสูง
A40: 5 | B40: มีโอกาสเกิดขึ้นสูงมาก | D40: มีผลกระทบสูงมาก
A42: แผนภาพความเสี่ยง (Risk Profile)
H44: จัดทำโดย | J44: ตรวจสอบโดย
H45: ....................................................................... | J45: ..........................................................................
H46: ( ) | J46: ( )
H47: ตำแหน่ง (หผ.) | J47: ตำแหน่ง (อก.)
H48: ....................................................................... | J48: ..........................................................................
H49: เบอร์โทรศัพท์ | J49: เบอร์โทรศัพท์
H50: ....................................................................... | J50: ..........................................................................
H51: วันที่ | J51: วันที่
...

Sheet คำอธิบายแบบ งป.004-1-5
A1: คำอธิบายแบบ งป.004/1 - งป.004/5
A2: (แบบข้อมูลพื้นฐานของงาน)
A4: 1. | B4: ชื่องาน/แผนงาน หมายถึง ชื่อของงานที่หน่วยงานจะดำเนินการ เพื่อให้บรรลุตามวัตถุประสงค์ที่ตั้งไว้
A5: 2. | B5: รายละเอียดของงาน/แผนงาน
B6: 2.1 | C6: ผู้รับผิดชอบ | F6: ให้ระบุหน่วยงานเป็นระดับแผนก, กอง, ฝ่าย, สายงาน, เบอร์โทร
B7: 2.2 | C7: ความจำเป็นในการดำเนินงาน | F7: ให้ทำเครื่องหมาย ü ในหัวข้อที่เลือกว่าเป็นงาน/แผนงาน
F8: ที่มีความจำเป็นจะต้องดำเนินการ เช่น มีสัญญา ข้อผูกพัน
F9: หรือมีเงื่อนไขที่ต้องดำเนินการ หรือเป็นนโยบายที่สำคัญของ กฟภ.
F10: ถ้าไม่ดำเนินการจะก่อให้เกิดความเสียหาย หรือสอดคล้องกับ
F11: นโยบายของรัฐบาล เช่น งานขยายเขตต่างๆ ให้บ้านเรือนราษฎร
F12: ที่ไม่มีไฟฟ้าใช้ เป็นต้น
B13: 2.3 | C13: ประเภทการลงทุน | F13: ให้ทำเครื่องหมาย ü ในหัวข้อที่เลือกว่างาน/แผนงาน เป็นประเภทการลงทุนใด
B14: 2.4 | C14: สถานะของงาน | F14: หมายถึง สถานภาพของงานในปีที่ขอตั้งงบประมาณว่าเป็น
F15: งาน/แผนงานต่อเนื่องหรืองาน/แผนงานใหม่
B16: 2.5 | C16: ได้รับอนุมัติจาก | F16: ให้ทำเครื่องหมาย ü ในหัวข้อที่ได้รับการอนุมัติ และระบุวันที่ที่ได้รับอนุมัติ
B17: 2.6 | C17: พื้นที่ดำเนินการ | F17: ให้ระบุสถานที่และจังหวัดที่ดำเนินการของงาน/แผนงาน
B18: 2.7 | C18: ระยะเวลาดำเนินการ | F18: ให้ระบุระยะเวลาเริ่มต้นที่ได้รับอนุมัติงาน/แผนงาน และระยะ
F19: เวลาสิ้นสุด คือระยะเวลาที่คาดว่าจะได้รับมอบงานงวดสุดท้าย
B20: 2.8 | C20: วงเงินลงทุนทั้งสิ้นของงาน/แผนงาน | F20: หมายถึง วงเงินงบประมาณรวมทั้งสิ้นที่จะใช้ในการดำเนินการ
B21: 2.9 | C21: วงเงินลงทุนปี 2570 ของงาน/แผนงาน | F21: หมายถึง วงเงินที่ขอตั้งงบประมาณปี 2570
B22: 2.10 | C22: เป้าหมายการเบิกจ่ายงบลงทุนปี 2570 | F22: ให้ประมาณการค่าใช้จ่ายที่จะใช้ในปีที่ขอตั้งงบประมาณ
F23: โดยวงเงินรวมเป้าหมายการเบิกจ่ายต้องเท่ากับวงเงินดำเนินการปี 2570
B24: 2.11 | C24: วงเงินงบทำการที่ขอตั้งในปี 2570 | F24: ให้ใส่วงเงินที่ขอใช้จากงบทำการ (ถ้ามี)
A25: 3. | B25: วัตถุประสงค์ของงาน/แผนงาน | F25: หมายถึง จุดมุ่งหมายในการดำเนินการเพื่อให้บรรลุผลเมื่อสิ้นสุดงาน/แผนงาน
A26: 4. | B26: ผลประโยชน์ที่คาดว่าจะได้รับ
B27: 4.1 | C27: ผลประโยชน์ที่คาดว่าจะได้รับหลังเสร็จสิ้น | F27: ผลผลิต (Output) หมายถึง ผลผลิตต่อหน่วยนับ สำหรับหน่วยของผลผลิต
C28: งาน/แผนงาน | F28: ระบุตามหน่วยที่สามารถวัดเป็นเชิงปริมาณได้ หากไม่สามารถวัดเป็นหน่วยนับได้
F29: กำหนดเป็นเปอร์เซนต์
F30: ผลลัพธ์ (Outcome) หมายถึง ผลที่คาดว่าจะได้รับ ที่เกิดขึ้นตามมาจากการเกิด
F31: ผลผลิต
B32: 4.2 | C32: ผลประโยชน์ที่คาดว่าจะได้รับในปี 2570 | F32: หมายถึง ผลผลิต(Output) และ ผลลัพธ์ (Outcome) ในปี 2570
C33: (กรณีเป็นแผนงานระยะยาว) | F33: ของแผนงานระยะยาว
B34: 4.3 | C34: ก่อให้เกิดประโยชน์กับ กฟภ. | F34: ระบุการลงทุนของงาน/แผนงาน ก่อให้เกิด ประโยชน์กับ กฟภ.ในด้านใด ให้ทำเครื่องหมาย ü
A35: 5. | B35: การวิเคราะห์ผลกระทบทางธุรกิจ
B36: 5.1 | C36: ผลกระทบต่อองค์กร | E36: ให้ระบุถึง | F36: - สนับสนุนวิสัยทัศน์ พันธกิจขององค์กร
F37: - สนับสนุนยุทธศาสตร์หลักขององค์กร
F38: - หน่วยงานกำกับกำหนด (องค์กรจำเป็นต้องดำเนินการ)
B39: 5.2 | C39: ผลกระทบต่อชุมชน สังคม | F39: ให้ระบุถึงบทวิเคราะห์ผลกระทบทางลบต่อสังคม /
C40: และสิ่งแวดล้อม | F40: ความกังวลของสาธารณะชน / สิ่งแวดล้อมที่เกิดจากการดำเนินงาน
F41: ของงาน/แผนงาน
...

Sheet 007 (69)
K1: แบบ งป.007
A2: แบบฟอร์ม
A3: หมวดสิ่งก่อสร้าง
A4: รายละเอียดค่าวัสดุอุปกรณ์ของงานระบบไฟฟ้า
A5: ปีงบประมาณ..........2569...................
A6: กลุ่มโครงสร้าง กลุ่มเครือข่ายและบริการ
A7: ชื่องาน แผนงานจัดหาอุปกรณ์ป้องกัน/ตัดตอน/อุปกรณ์ประกอบและอุปกรณ์สำรองสำหรับสายเคเบิลใต้ดิน/ใต้น้ำ ในระบบจำหน่ายและสายส่งไฟฟ้า (ปี 2569-2571)
A8: หน่วยงาน กองบริหารจัดการระบบไฟฟ้า
A10: ที่ | B10: ประเภท / รายการ | C10: จำนวน | D10: ราคาต่อ | E10: แหล่งที่มาของราคาที่ขอตั้งงบประมาณ | H10: วงเงินรวม (บาท) | I10: ประมาณจ่าย | K10: คำชี้แจง
D11: หน่วย | E11: ครั้งสุดท้ายเมื่อ..... | F11: ท้องตลาด เฉลี่ย 3 บริษัท | G11: อื่นๆ | I11: ปี 2569 | J11: ปี 2570 | L11: ก.ย.69 | M11: ธ.ค.69 | N11: มิ.ย. 70 | O11: ธ.ค. 70
A12: 1 | B12: สวิตช์เปิดได้เมื่อมีโหลดสามารถใช้การ | C12: ='[1]010-1'!E9 -> 359 | D12: ='[1]010-1'!D9 -> 260000 | G12: สืบราคาจากบริษัท | H12: =C12*D12 -> 93340000 | I12: 0 | J12: =H12 -> 93340000 | K12: คาดจ่าย มิ.ย 70 | L12: =I26+I28+I52+I54 -> 8998722 | M12: =H42+H45+H48+H50 -> 8118640 | N12: =J12+J19+J58+J61+J63+J65+J67+J69+J71+J73+J75 -> 136368130 | O12: =J30+J36+J56 -> 90237200 | P12: =SUM(L12:O12) -> 243722692
B13: ควบคุมระยะไกล 3 เฟส 22 เควี 600 แอมป์
B14: ประกอบด้วย
B15: - ชุดควบคุมสวิตช์ชนิด ภายนอกอาคาร CT, VT,
B16: ชุดจ่ายไฟชุดควบคุม LOCAL และชุดควบคุม
B17: INTERFACE และ CONTROL CABINET
B18: (Mat No. 1040070009, 1040070305, 1040073011, 1000120005)
A19: 2 | B19: สวิตช์เปิดได้เมื่อมีโหลดสามารถใช้การ | C19: ='[1]010-1'!E10 -> 90 | D19: ='[1]010-1'!D10 -> 260000 | G19: สืบราคาจากบริษัท | H19: =C19*D19 -> 23400000 | I19: 0 | J19: =H19 -> 23400000 | K19: คาดจ่าย มิ.ย 70
B20: ควบคุมระยะไกล 3 เฟส 33 เควี 600 แอมป์
B21: ประกอบด้วย
B22: - ชุดควบคุมสวิตช์ชนิด ภายนอกอาคาร CT, VT,
B23: ชุดจ่ายไฟชุดควบคุม LOCAL และชุดควบคุม
B24: INTERFACE และ CONTROL CABINET
B25: (Mat No. 1040070107, 1040070305,1040073012, 1000120007)
A26: 3 | B26: Capacitor แรงสูง ระบบ 12.7 kV.1 เฟส 100 kVAR. | C26: ='[1]010-1'!E11 -> 750 | D26: ='[1]010-1'!D11 -> 9357 | G26: ราคากลางปี 2567 ครั้งที่ 4 | H26: =C26*D26 -> 7017750 | I26: 0 | J26: 0 | K26: คาดจ่าย ก.ย. 69
B27: (Mat No. 1050050000) | H27: (ยกเลิก)
A28: 4 | B28: Capacitor แรงสูง 1 บุชชิ่ง 33 GRDY/19 kV.100 kVAR | C28: ='[1]010-1'!E12 -> 225 | D28: ='[1]010-1'!D12 -> 7886 | G28: ราคากลางปี 2567 ครั้งที่ 4 | H28: =C28*D28 -> 1774350 | I28: 0 | J28: 0 | K28: คาดจ่าย ก.ย. 69
B29: (Mat No. 1050050100) | H29: (ยกเลิก)
A30: 5 | B30: Three phase automatic circuit recloser,solid | C30: ='[1]010-1'!E13 -> 203 | D30: ='[1]010-1'!D13 -> 238400 | G30: ราคากลางปี 2567 ครั้งที่ 4 | H30: =C30*D30 -> 48395200 | J30: =H30 -> 48395200 | K30: คาดจ่าย ธ.ค. 70
B31: dielectric insulation type, Rated voltage : 24 kV
B32: Complete with mounting frame, single-pole type :
B33: 1.ชุดควบคุมอัตโนมัติ สำหรับรีโคลสเซอร์แบบอิเล็คทรอนิคส์
B34: 2.VT.1P.O/D 22,000/230 V.REC.500 VA.
B35: (Mat No. 1040080004, 1040080302, 1040073015)
A36: 6 | B36: Three phase automatic circuit recloser,solid | C36: ='[1]010-1'!E14 -> 34 | D36: ='[1]010-1'!D14 -> 313000 | G36: ราคากลางปี 2567 ครั้งที่ 4 | H36: =C36*D36 -> 10642000 | J36: =H36 -> 10642000 | K36: คาดจ่าย ธ.ค. 70
B37: dielectric insulation type, Rated voltage : 36 kV
B38: Complete with mounting frame, single-pole type :
B39: 1.ชุดควบคุมอัตโนมัติ สำหรับรีโคลสเซอร์แบบอิเล็คทรอนิคส์
B40: 2.VT.1P.O/D 33,000/230 V.REC.500 VA.
B41: (Mat No. 1040080103, 1040080302, 1040073016)
...

Sheet 007 (70)
L1: แบบ งป.007
A2: แบบฟอร์ม
A3: หมวดสิ่งก่อสร้าง
A4: รายละเอียดค่าวัสดุอุปกรณ์ของงานระบบไฟฟ้า
A5: ปีงบประมาณ..........2570...................
A6: กลุ่มโครงสร้าง กลุ่มเครือข่ายและบริการ
A7: ชื่องาน แผนงานจัดหาอุปกรณ์ป้องกัน/ตัดตอน/อุปกรณ์ประกอบและอุปกรณ์สำรองสำหรับสายเคเบิลใต้ดิน/ใต้น้ำ ในระบบจำหน่ายและสายส่งไฟฟ้า (ปี 2569-2571)
A8: หน่วยงาน กองบริหารจัดการระบบไฟฟ้า
A10: ที่ | B10: ประเภท / รายการ | C10: จำนวน | D10: หน่วย | E10: ราคาต่อ | F10: แหล่งที่มาของราคาที่ขอตั้งงบประมาณ | I10: วงเงินรวม (บาท) | J10: ประมาณจ่าย | L10: คำชี้แจง
E11: หน่วย | F11: ครั้งสุดท้ายเมื่อ..... | G11: ท้องตลาด เฉลี่ย 3 บริษัท | H11: อื่นๆ | J11: ปี 2570 | K11: ปี 2571 | M11: 25812 | N11: 25903 | O11: 26085 | P11: 26268
A12: 1 | B12: สวิตช์เปิดได้เมื่อมีโหลดสามารถใช้การ | C12: ='010-1 (2)'!G9 -> 362 | D12: ชุด | E12: ='010-1 (2)'!D9 -> 260000 | H12: สืบราคาจากบริษัท | I12: =C12*E12 -> 94120000 | J12: 0 | K12: =I12 -> 94120000 | L12: คาดจ่าย มิ.ย 71 | M12: =J26+J28+J52+J54 -> 0 | N12: 0 | O12: =K12+K19+K58+K61+K63+K65+K67+K69+K71+K73+K75+K26+K28+K52 -> 166841452 | P12: =K30+K36+K56+K42+K45+K48+K50 -> 89971790 | Q12: =SUM(M12:P12) -> 256813242
B13: ควบคุมระยะไกล 3 เฟส 22 เควี 600 แอมป์
B14: ประกอบด้วย
B15: - ชุดควบคุมสวิตช์ชนิด ภายนอกอาคาร CT, VT,
B16: ชุดจ่ายไฟชุดควบคุม LOCAL และชุดควบคุม
B17: INTERFACE และ CONTROL CABINET
B18: (Mat No. 1040070009, 1040070305, 1040073011, 1000120005)
A19: 2 | B19: สวิตช์เปิดได้เมื่อมีโหลดสามารถใช้การ | C19: ='010-1 (2)'!G10 -> 89 | D19: ชุด | E19: ='010-1 (2)'!D10 -> 260000 | H19: สืบราคาจากบริษัท | I19: =C19*E19 -> 23140000 | J19: 0 | K19: =I19 -> 23140000 | L19: คาดจ่าย มิ.ย 71
B20: ควบคุมระยะไกล 3 เฟส 33 เควี 600 แอมป์
B21: ประกอบด้วย
B22: - ชุดควบคุมสวิตช์ชนิด ภายนอกอาคาร CT, VT,
B23: ชุดจ่ายไฟชุดควบคุม LOCAL และชุดควบคุม
B24: INTERFACE และ CONTROL CABINET
B25: (Mat No. 1040070107, 1040070305,1040073012, 1000120007)
A26: 3 | B26: Capacitor แรงสูง ระบบ 12.7 kV.1 เฟส 100 kVAR. | C26: ='010-1 (2)'!G11 -> 750 | D26: ชิ้น | E26: ='010-1 (2)'!D11 -> 9357 | H26: ราคากลางปี 2567 ครั้งที่ 4 | I26: =C26*E26 -> 7017750 | J26: 0 | K26: =I26 -> 7017750 | L26: คาดจ่าย ก.ย. 70 | M26: คาดจ่าย มิ.ย 71
B27: (Mat No. 1050050000)
A28: 4 | B28: Capacitor แรงสูง 1 บุชชิ่ง 33 GRDY/19 kV.100 kVAR | C28: ='010-1 (2)'!G12 -> 225 | D28: ชิ้น | E28: ='010-1 (2)'!D12 -> 7886 | H28: ราคากลางปี 2567 ครั้งที่ 4 | I28: =C28*E28 -> 1774350 | J28: 0 | K28: =I28 -> 1774350 | L28: คาดจ่าย ก.ย. 70 | M28: คาดจ่าย มิ.ย 71
B29: (Mat No. 1050050100)
A30: 5 | B30: Three phase automatic circuit recloser,solid | C30: ='010-1 (2)'!G13 -> 212 | D30: ชุด | E30: ='010-1 (2)'!D13 -> 238400 | H30: ราคากลางปี 2567 ครั้งที่ 4 | I30: =C30*E30 -> 50540800 | K30: =I30 -> 50540800 | L30: คาดจ่าย ธ.ค. 71
B31: dielectric insulation type, Rated voltage : 24 kV
B32: Complete with mounting frame, single-pole type :
B33: 1.ชุดควบคุมอัตโนมัติ สำหรับรีโคลสเซอร์แบบอิเล็คทรอนิคส์
B34: 2.VT.1P.O/D 22,000/230 V.REC.500 VA.
B35: (Mat No. 1040080004, 1040080302, 1040073015)
A36: 6 | B36: Three phase automatic circuit recloser,solid | C36: ='010-1 (2)'!G14 -> 34 | D36: ชุด | E36: ='010-1 (2)'!D14 -> 313000 | H36: ราคากลางปี 2567 ครั้งที่ 4 | I36: =C36*E36 -> 10642000 | K36: =I36 -> 10642000 | L36: คาดจ่าย ธ.ค. 71
B37: dielectric insulation type, Rated voltage : 36 kV
B38: Complete with mounting frame, single-pole type :
B39: 1.ชุดควบคุมอัตโนมัติ สำหรับรีโคลสเซอร์แบบอิเล็คทรอนิคส์
B40: 2.VT.1P.O/D 33,000/230 V.REC.500 VA.
B41: (Mat No. 1040080103, 1040080302, 1040073016)
...

Sheet 007(71)
L1: แบบ งป.007
A2: แบบฟอร์ม
A3: หมวดสิ่งก่อสร้าง
A4: รายละเอียดค่าวัสดุอุปกรณ์ของงานระบบไฟฟ้า
A5: ปีงบประมาณ..........2571...................
A6: กลุ่มโครงสร้าง กลุ่มเครือข่ายและบริการ
A7: ชื่องาน แผนงานจัดหาอุปกรณ์ป้องกัน/ตัดตอน/อุปกรณ์ประกอบและอุปกรณ์สำรองสำหรับสายเคเบิลใต้ดิน/ใต้น้ำ ในระบบจำหน่ายและสายส่งไฟฟ้า (ปี 2569-2571)
A8: หน่วยงาน กองบริหารจัดการระบบไฟฟ้า
A10: ที่ | B10: ประเภท / รายการ | C10: จำนวน | D10: หน่วย | E10: ราคาต่อ | F10: แหล่งที่มาของราคาที่ขอตั้งงบประมาณ | I10: วงเงินรวม (บาท) | J10: ประมาณจ่าย | L10: คำชี้แจง
E11: หน่วย | F11: ครั้งสุดท้ายเมื่อ..... | G11: ท้องตลาด เฉลี่ย 3 บริษัท | H11: อื่นๆ | J11: ปี 2571 | K11: ปี 2572 | M11: ก.ย.69 | N11: ธ.ค.69 | O11: มิ.ย. 70 | P11: ธ.ค. 70
A12: 1 | B12: สวิตช์เปิดได้เมื่อมีโหลดสามารถใช้การ | C12: ='[2]010-1'!I9 -> 315 | D12: ชุด | E12: ='[2]010-1'!D9 -> 260000 | H12: สืบราคาจากบริษัท | I12: =C12*E12 -> 81900000 | J12: 0 | K12: =I12 -> 81900000 | L12: คาดจ่าย มิ.ย 70 | M12: =J26+J28+J52+J54 -> 15265377 | N12: =I42+I45+I48+I50 -> 5767430 | O12: =K12+K19+K58+K61+K63+K65+K67+K69+K71+K73+K75 -> 149665230 | P12: =K30+K36+K56 -> 49053600 | Q12: =SUM(M12:P12) -> 219751637
B13: ควบคุมระยะไกล 3 เฟส 22 เควี 600 แอมป์
B14: ประกอบด้วย
B15: - ชุดควบคุมสวิตช์ชนิด ภายนอกอาคาร CT, VT,
B16: ชุดจ่ายไฟชุดควบคุม LOCAL และชุดควบคุม
B17: INTERFACE และ CONTROL CABINET
B18: (Mat No. 1040070009, 1040070305, 1040073011, 1000120005)
A19: 2 | B19: สวิตช์เปิดได้เมื่อมีโหลดสามารถใช้การ | C19: ='[2]010-1'!I10 -> 84 | D19: ชุด | E19: ='[2]010-1'!D10 -> 260000 | H19: สืบราคาจากบริษัท | I19: =C19*E19 -> 21840000 | J19: 0 | K19: =I19 -> 21840000 | L19: คาดจ่าย มิ.ย 70
B20: ควบคุมระยะไกล 3 เฟส 33 เควี 600 แอมป์
B21: ประกอบด้วย
B22: - ชุดควบคุมสวิตช์ชนิด ภายนอกอาคาร CT, VT,
B23: ชุดจ่ายไฟชุดควบคุม LOCAL และชุดควบคุม
B24: INTERFACE และ CONTROL CABINET
B25: (Mat No. 1040070107, 1040070305,1040073012, 1000120007)
A26: 3 | B26: Capacitor แรงสูง ระบบ 12.7 kV.1 เฟส 100 kVAR. | C26: ='[2]010-1'!I11 -> 750 | D26: ชิ้น | E26: ='[2]010-1'!D11 -> 9357 | H26: ราคากลางปี 2567 ครั้งที่ 4 | I26: =C26*E26 -> 7017750 | J26: =C26*E26 -> 7017750 | K26: 0 | L26: คาดจ่าย ก.ย. 69
B27: (Mat No. 1050050000)
A28: 4 | B28: Capacitor แรงสูง 1 บุชชิ่ง 33 GRDY/19 kV.100 kVAR | C28: ='[2]010-1'!I12 -> 225 | D28: ชิ้น | E28: ='[2]010-1'!D12 -> 7886 | H28: ราคากลางปี 2567 ครั้งที่ 4 | I28: =C28*E28 -> 1774350 | J28: =I28 -> 1774350 | K28: 0 | L28: คาดจ่าย ก.ย. 69
B29: (Mat No. 1050050100)
A30: 5 | B30: Three phase automatic circuit recloser,solid | C30: ='[2]010-1'!I13 -> 169 | D30: ชุด | E30: ='[2]010-1'!D13 -> 238400 | H30: ราคากลางปี 2567 ครั้งที่ 4 | I30: =C30*E30 -> 40289600 | K30: =I30 -> 40289600 | L30: คาดจ่าย ธ.ค. 70
B31: dielectric insulation type, Rated voltage : 24 kV
B32: Complete with mounting frame, single-pole type :
B33: 1.ชุดควบคุมอัตโนมัติ สำหรับรีโคลสเซอร์แบบอิเล็คทรอนิคส์
B34: 2.VT.1P.O/D 22,000/230 V.REC.500 VA.
B35: (Mat No. 1040080004, 1040080302, 1040073015)
A36: 6 | B36: Three phase automatic circuit recloser,solid | C36: ='[2]010-1'!I14 -> 28 | D36: ชุด | E36: ='[2]010-1'!D14 -> 313000 | H36: ราคากลางปี 2567 ครั้งที่ 4 | I36: =C36*E36 -> 8764000 | K36: =I36 -> 8764000 | L36: คาดจ่าย ธ.ค. 70
B37: dielectric insulation type, Rated voltage : 36 kV
B38: Complete with mounting frame, single-pole type :
B39: 1.ชุดควบคุมอัตโนมัติ สำหรับรีโคลสเซอร์แบบอิเล็คทรอนิคส์
B40: 2.VT.1P.O/D 33,000/230 V.REC.500 VA.
B41: (Mat No. 1040080103, 1040080302, 1040073016)
...

Sheet 009 (69)
A2: รายงานความก้าวหน้าของแผนจัดซื้อ/จัดจ้างตามงบลงทุนเพื่อการดำเนินงานปกติ
A3: ที่ขอตั้งงบประมาณประจำปี 2569
A4: กลุ่มโครงสร้าง กลุ่มเครือข่ายและบริการ
A5: ชื่องาน แผนงานจัดหาอุปกรณ์ป้องกัน/ตัดตอน/อุปกรณ์ประกอบและอุปกรณ์สำรองสำหรับสายเคเบิลใต้ดิน/ใต้น้ำ ในระบบจำหน่ายและสายส่งไฟฟ้า (ปี 2569-2571)
A6: หน่วยงาน กองบริหารจัดการระบบไฟฟ้า
AA7: หน่วย : ล้านบาท(ทศนิยม 3 ตำแหน่ง)
A8: ลำดับ | B8: ขั้นตอนการดำเนินงาน | C8: วงเงิน | D8: กำหนดเวลาดำเนินการใช้เงิน
C9: ดำเนินการ | D9: ปี 2569 | P9: ปี 2570
A10: ที่ | C10: ปี 2569 | D10: ม.ค. | E10: ก.พ. | F10: มี.ค. | G10: เม.ย. | H10: พ.ค. | I10: มิ.ย. | J10: ก.ค. | K10: ส.ค. | L10: ก.ย. | M10: ต.ค. | N10: พ.ย. | O10: ธ.ค. | P10: ม.ค. | Q10: ก.พ. | R10: มี.ค. | S10: เม.ย. | T10: พ.ค. | U10: มิ.ย. | V10: ก.ค. | W10: ส.ค. | X10: ก.ย. | Y10: ต.ค. | Z10: พ.ย. | AA10: ธ.ค.
A11: 1 | B11: อนุมัติหลักการ / อนุมัติสเปค
A12: 2 | B12: การดำเนินการจัดซื้อจัดจ้าง
B13: - จัดทำเอกสารประกวดราคา/สอบราคา
B14: - ประกวดราคา /สอบราคา
B15: - อนุมัติจัดซื้อ / จัดจ้าง
B16: - ทำสัญญา
A17: 3 | B17: ส่งของ / ดำเนินการก่อสร้าง
A18: 4 | B18: ตรวจรับและทดสอบ
A19: 5 | B19: เบิกจ่ายเงิน(ล้านบาท)
B20: (ระบุวงเงินแต่ละเดือนให้ชัดเจน) | L20: ='[1]007 (69)'!L12/1000000 -> 8.998722 | O20: ='[1]007 (69)'!M12/1000000 -> 8.11864 | U20: ='[1]007 (69)'!N12/1000000 -> 136.36813 | AA20: ='[1]007 (69)'!O12/1000000 -> 90.2372
B21: รวมค่าวัสดุอุปกรณ์ | C21: =D21+P21 -> 243.72269 | D21: =SUM(D20:O20) -> 17.117362 | P21: =SUM(P20:AA20) -> 226.60533
A23: หมายเหตุ | B23: 1. ให้แสดง Workflow สถานะการดำเนินงานตามขั้นตอนต่าง ๆ เป็นรายเดือนตั้งแต่ปีที่ตั้งงบประมาณจนสิ้นสุดแผนงาน | AA23: แบบ งป.009
B24: 2. การประมาณเบิกจ่ายรายเดือน แยกรายละเอียด การจัดซื้ออุปกรณ์, ค่าใช้จ่ายหน้างาน, ค่าจ้างเหมาก่อสร้าง สำหรับสำรองค่าปรับราคา ไม่ต้องประมาณจ่าย
B25: 3. สำหรับแผนงานที่ได้รับอนุมัติแล้ว ให้แสดง work flow ตั้งแต่เริ่มแผนจนสิ้นสุดแผนงงาน

Sheet 009 (70)
A2: รายงานความก้าวหน้าของแผนจัดซื้อ/จัดจ้างตามงบลงทุนเพื่อการดำเนินงานปกติ
A3: ที่ขอตั้งงบประมาณประจำปี 2570
A4: กลุ่มโครงสร้าง กลุ่มเครือข่ายและบริการ
A5: ชื่องาน แผนงานจัดหาอุปกรณ์ป้องกัน/ตัดตอน/อุปกรณ์ประกอบและอุปกรณ์สำรองสำหรับสายเคเบิลใต้ดิน/ใต้น้ำ ในระบบจำหน่ายและสายส่งไฟฟ้า (ปี 2569-2571)
A6: หน่วยงาน กองบริหารจัดการระบบไฟฟ้า
AA7: หน่วย : ล้านบาท(ทศนิยม 3 ตำแหน่ง)
A8: ลำดับ | B8: ขั้นตอนการดำเนินงาน | C8: วงเงิน | D8: กำหนดเวลาดำเนินการใช้เงิน
C9: ดำเนินการ | D9: ปี 2570 | P9: ปี 2571
A10: ที่ | C10: ปี 2570 | D10: ม.ค. | E10: ก.พ. | F10: มี.ค. | G10: เม.ย. | H10: พ.ค. | I10: มิ.ย. | J10: ก.ค. | K10: ส.ค. | L10: ก.ย. | M10: ต.ค. | N10: พ.ย. | O10: ธ.ค. | P10: ม.ค. | Q10: ก.พ. | R10: มี.ค. | S10: เม.ย. | T10: พ.ค. | U10: มิ.ย. | V10: ก.ค. | W10: ส.ค. | X10: ก.ย. | Y10: ต.ค. | Z10: พ.ย. | AA10: ธ.ค.
A11: 1 | B11: อนุมัติหลักการ / อนุมัติสเปค
A12: 2 | B12: การดำเนินการจัดซื้อจัดจ้าง
B13: - จัดทำเอกสารประกวดราคา/สอบราคา
B14: - ประกวดราคา /สอบราคา
B15: - อนุมัติจัดซื้อ / จัดจ้าง
B16: - ทำสัญญา
A17: 3 | B17: ส่งของ / ดำเนินการก่อสร้าง
A18: 4 | B18: ตรวจรับและทดสอบ
A19: 5 | B19: เบิกจ่ายเงิน(ล้านบาท)
B20: (ระบุวงเงินแต่ละเดือนให้ชัดเจน) | U20: ='007 (70)'!O12/1000000 -> 166.84145 | AA20: ='007 (70)'!P12/1000000 -> 89.97179
B21: รวมค่าวัสดุอุปกรณ์ | C21: =D21+P21 -> 256.81324 | P21: =SUM(P20:AA20) -> 256.81324
AA23: แบบ งป.009
A24: หมายเหตุ | B24: 1. ให้แสดง Workflow สถานะการดำเนินงานตามขั้นตอนต่าง ๆ เป็นรายเดือนตั้งแต่ปีที่ตั้งงบประมาณจนสิ้นสุดแผนงาน
B25: 2. การประมาณเบิกจ่ายรายเดือน แยกรายละเอียด การจัดซื้ออุปกรณ์, ค่าใช้จ่ายหน้างาน, ค่าจ้างเหมาก่อสร้าง สำหรับสำรองค่าปรับราคา ไม่ต้องประมาณจ่าย
B26: 3. สำหรับแผนงานที่ได้รับอนุมัติแล้ว ให้แสดง work flow ตั้งแต่เริ่มแผนจนสิ้นสุดแผนงงาน

Sheet 009 (71)
A2: รายงานความก้าวหน้าของแผนจัดซื้อ/จัดจ้างตามงบลงทุนเพื่อการดำเนินงานปกติ
A3: ที่ขอตั้งงบประมาณประจำปี 2571
A4: กลุ่มโครงสร้าง กลุ่มเครือข่ายและบริการ
A5: ชื่องาน แผนงานจัดหาอุปกรณ์ป้องกัน/ตัดตอน/อุปกรณ์ประกอบและอุปกรณ์สำรองสำหรับสายเคเบิลใต้ดิน/ใต้น้ำ ในระบบจำหน่ายและสายส่งไฟฟ้า (ปี 2569-2571)
A6: หน่วยงาน กองบริหารจัดการระบบไฟฟ้า
AA7: หน่วย : ล้านบาท(ทศนิยม 3 ตำแหน่ง)
A8: ลำดับ | B8: ขั้นตอนการดำเนินงาน | C8: วงเงิน | D8: กำหนดเวลาดำเนินการใช้เงิน
C9: ดำเนินการ | D9: ปี 2571 | P9: ปี 2572
A10: ที่ | C10: ปี 2569 | D10: ม.ค. | E10: ก.พ. | F10: มี.ค. | G10: เม.ย. | H10: พ.ค. | I10: มิ.ย. | J10: ก.ค. | K10: ส.ค. | L10: ก.ย. | M10: ต.ค. | N10: พ.ย. | O10: ธ.ค. | P10: ม.ค. | Q10: ก.พ. | R10: มี.ค. | S10: เม.ย. | T10: พ.ค. | U10: มิ.ย. | V10: ก.ค. | W10: ส.ค. | X10: ก.ย. | Y10: ต.ค. | Z10: พ.ย. | AA10: ธ.ค.
A11: 1 | B11: อนุมัติหลักการ / อนุมัติสเปค
A12: 2 | B12: การดำเนินการจัดซื้อจัดจ้าง
B13: - จัดทำเอกสารประกวดราคา/สอบราคา
B14: - ประกวดราคา /สอบราคา
B15: - อนุมัติจัดซื้อ / จัดจ้าง
B16: - ทำสัญญา
A17: 3 | B17: ส่งของ / ดำเนินการก่อสร้าง
A18: 4 | B18: ตรวจรับและทดสอบ
A19: 5 | B19: เบิกจ่ายเงิน(ล้านบาท)
B20: (ระบุวงเงินแต่ละเดือนให้ชัดเจน) | L20: ='[2]007(71)'!L12/1000000 -> 15.265377 | O20: ='[2]007(71)'!M12/1000000 -> 5.76743 | U20: ='[2]007(71)'!N12/1000000 -> 149.66523 | AA20: ='[2]007(71)'!O12/1000000 -> 49.0536
B21: รวมค่าวัสดุอุปกรณ์ | C21: =D21+P21 -> 219.75164 | D21: =SUM(D20:O20) -> 21.032807 | P21: =SUM(P20:AA20) -> 198.71883
AA22: แบบ งป.009
A23: หมายเหตุ | B23: 1. ให้แสดง Workflow สถานะการดำเนินงานตามขั้นตอนต่าง ๆ เป็นรายเดือนตั้งแต่ปีที่ตั้งงบประมาณจนสิ้นสุดแผนงาน
B24: 2. การประมาณเบิกจ่ายรายเดือน แยกรายละเอียด การจัดซื้ออุปกรณ์, ค่าใช้จ่ายหน้างาน, ค่าจ้างเหมาก่อสร้าง สำหรับสำรองค่าปรับราคา ไม่ต้องประมาณจ่าย
B25: 3. สำหรับแผนงานที่ได้รับอนุมัติแล้ว ให้แสดง work flow ตั้งแต่เริ่มแผนจนสิ้นสุดแผนงงาน

Sheet 010-1 (2)
A2: แผนการลงทุนรายปี (การลงทุนเพื่อการดำเนินงานปกติ)
A3: กลุ่มโครงสร้าง กลุ่มเครือข่ายและบริการ
A4: ชื่องาน แผนงานจัดหาอุปกรณ์ป้องกัน/ตัดตอน/อุปกรณ์ประกอบและอุปกรณ์สำรองสำหรับสายเคเบิลใต้ดิน/ใต้น้ำ ในระบบจำหน่ายและสายส่งไฟฟ้า (ปี 2569-2571)
A5: หน่วยงาน กองบริหารจัดการระบบไฟฟ้า | L5: หน่วย : บาท
A6: ลำดับ | C6: ประเภท/รายการ | D6: ราคา ต่อหน่วย | E6: วงเงินลงทุน | K6: รวมทั้งสิ้น
B7: รหัสพัสดุ | E7: ปี 2569 | G7: ปี 2570 | I7: ปี 2571
E8: จำนวน | F8: จำนวนเงิน | G8: จำนวน | H8: จำนวนเงิน | I8: จำนวน | J8: จำนวนเงิน | K8: จำนวน | L8: จำนวนเงิน
A9: 1 | B9: 1040070009 or New | C9: Remote control switch (RCS) ระบบ 22 kV (ชุด) | D9: 260000 | E9: 359 | F9: =D9*E9 -> 93340000 | G9: 362 | H9: =D9*G9 -> 94120000 | I9: 315 | J9: =I9*D9 -> 81900000 | K9: =E9+G9+I9 -> 1036 | L9: =D9*K9 -> 269360000 | N9: =(K9+K10)/22530 -> 0.057656458
A10: 2 | B10: 1040070107 or New | C10: Remote control switch (RCS) ระบบ 33 kV (ชุด) | D10: 260000 | E10: 90 | F10: =D10*E10 -> 23400000 | G10: 89 | H10: =D10*G10 -> 23140000 | I10: 84 | J10: =I10*D10 -> 21840000 | K10: =E10+G10+I10 -> 263 | L10: =D10*K10 -> 68380000
A11: 3 | B11: 1050050000 | C11: Capacitor แรงสูง ระบบ 12.7 kV.1 เฟส 100 kVAR. (ชิ้น) | D11: 9357 | E11: 750 | F11: ยกเลิก | G11: 750 | H11: =D11*G11 -> 7017750 | I11: 750 | J11: =I11*D11 -> 7017750 | K11: =E11+G11+I11 -> 2250 | L11: =D11*K11 -> 21053250
A12: 4 | B12: 1050050100 | C12: Capacitor แรงสูง 1 บุชชิ่ง 33 GRDY/19 kV.100 kVAR (ชิ้น) | D12: 7886 | E12: 225 | F12: ยกเลิก | G12: 225 | H12: =D12*G12 -> 1774350 | I12: 225 | J12: =I12*D12 -> 1774350 | K12: =E12+G12+I12 -> 675 | L12: =D12*K12 -> 5323050
A13: 5 | B13: 1040080004 | C13: Automatic circuit recloser (Solid dielectric) ระบบ 22 kV (ชุด) | D13: 238400 | E13: 203 | F13: =D13*E13 -> 48395200 | G13: 212 | H13: =D13*G13 -> 50540800 | I13: 169 | J13: =I13*D13 -> 40289600 | K13: =E13+G13+I13 -> 584 | L13: =D13*K13 -> 139225600 | N13: =(K13+K14)/4743 -> 0.14336918
A14: 6 | B14: 1040080103 | C14: Automatic circuit recloser (Solid dielectric) ระบบ 33 kV (ชุด) | D14: 313000 | E14: 34 | F14: =D14*E14 -> 10642000 | G14: 34 | H14: =D14*G14 -> 10642000 | I14: 28 | J14: =I14*D14 -> 8764000 | K14: =E14+G14+I14 -> 96 | L14: =D14*K14 -> 30048000
A15: 7 | B15: 1040073011 | C15: VT.ขนาด 3 เฟส 22,000/110 V.10 VA.220 V.500 VA. (RCS) (เครื่อง) | D15: 51360 | E15: 65 | F15: =D15*E15 -> 3338400 | G15: 70 | H15: =D15*G15 -> 3595200 | I15: 70 | J15: =I15*D15 -> 3595200 | K15: =E15+G15+I15 -> 205 | L15: =D15*K15 -> 10528800
A16: 8 | B16: 1040073012 | C16: VT.ขนาด 3 เฟส 33,000/110 V.10 VA.220 V.500 VA. (RCS) (เครื่อง) | D16: 61030 | E16: 16 | F16: =D16*E16 -> 976480 | G16: 16 | H16: =D16*G16 -> 976480 | I16: 17 | J16: =I16*D16 -> 1037510 | K16: =E16+G16+I16 -> 49 | L16: =D16*K16 -> 2990470
A17: 9 | B17: 1040073015 | C17: หม้อแปลง 1 เฟส 500 VA 22000/230 V (สำหรับชุด Control unit ของ recloser ) (เครื่อง) | D17: 19090 | E17: 164 | F17: =D17*E17 -> 3130760 | G17: 34 | H17: =D17*G17 -> 649060 | I17: 33 | J17: =I17*D17 -> 629970 | K17: =E17+G17+I17 -> 231 | L17: =D17*K17 -> 4409790
A18: 10 | B18: 1040073016 | C18: หม้อแปลง 1 เฟส 500 VA 33000/230 V (สำหรับชุด Control unit ของ recloser ) (เครื่อง) | D18: 33650 | E18: 20 | F18: =D18*E18 -> 673000 | G18: 5 | H18: =D18*G18 -> 168250 | I18: 15 | J18: =I18*D18 -> 504750 | K18: =E18+G18+I18 -> 40 | L18: =D18*K18 -> 1346000
A19: 11 | B19: 1040050000 | C19: ดิสคอนเนคติ้งสวิตช์ 1 ขา 22 เควี 600 แอมป์ ชนิดติดตั้งในระบบจำหน่าย (ชิ้น) | D19: 5222 | E19: 1296 | F19: =D19*E19 -> 6767712 | G19: 666 | H19: =D19*G19 -> 3477852 | I19: 1026 | J19: =I19*D19 -> 5357772 | K19: =E19+G19+I19 -> 2988 | L19: =D19*K19 -> 15603336
A20: 12 | B20: 1040050100 | C20: ดิสคอนเนคติ้งสวิตช์ 1 ขา 33 เควี 600 แอมป์ ชนิดติดตั้งในระบบจำหน่าย (ชิ้น) | D20: 8263 | E20: 270 | F20: =D20*E20 -> 2231010 | G20: 0 | H20: =D20*G20 -> 0 | I20: 135 | J20: =I20*D20 -> 1115505 | K20: =E20+G20+I20 -> 405 | L20: =D20*K20 -> 3346515
A21: 13 | B21: 1040070202 | C21: 115 kV Pole-mounted Load break switches | D21: 3900000 | E21: 8 | F21: =D21*E21 -> 31200000 | G21: 6 | H21: =D21*G21 -> 23400000 | I21: 0 | J21: =I21*D21 -> 0 | K21: =E21+G21+I21 -> 14 | L21: =D21*K21 -> 54600000 | N21: =20/762 -> 0.026246719
A22: 14 | B22: 1040060207 | C22: 115 kV Air Break Switches (ชุด) | D22: 406900 | E22: 6 | F22: =D22*E22 -> 2441400 | G22: 0 | H22: =D22*G22 -> 0 | I22: 0 | J22: =I22*D22 -> 0 | K22: =E22+G22+I22 -> 6 | L22: =D22*K22 -> 2441400
A23: 15 | B23: 1020040001 | C23: 22kV 50 sq.mm. Underground Cable (เมตร) | D23: 650.46 | E23: 500 | F23: =D23*E23 -> 325230 | G23: 0 | H23: =D23*G23 -> 0 | I23: 500 | J23: =I23*D23 -> 325230 | K23: =E23+G23+I23 -> 1000 | L23: =D23*K23 -> 650460
A24: 16 | B24: 1020040003 | C24: 22kV 95 sq.mm. Underground Cable (เมตร) | D24: 623 | E24: 500 | F24: =D24*E24 -> 311500 | G24: 500 | H24: =D24*G24 -> 311500 | I24: 0 | J24: =I24*D24 -> 0 | K24: =E24+G24+I24 -> 1000 | L24: =D24*K24 -> 623000
A25: 17 | B25: 1020040101 | C25: 33kV 50 sq.mm. Underground Cable (เมตร) | D25: 700 | E25: 500 | F25: =D25*E25 -> 350000 | G25: 0 | H25: =D25*G25 -> 0 | I25: 500 | J25: =I25*D25 -> 350000 | K25: =E25+G25+I25 -> 1000 | L25: =D25*K25 -> 700000
A26: 18 | B26: 1020040103 | C26: 33kV 95 sq.mm.Underground Cable (เมตร) | D26: 800 | E26: 500 | F26: =D26*E26 -> 400000 | G26: 0 | H26: =D26*G26 -> 0 | I26: 500 | J26: =I26*D26 -> 400000 | K26: =E26+G26+I26 -> 1000 | L26: =D26*K26 -> 800000
A27: 19 | B27: 1020050202 | C27: 22kV 3x120 sq.mm. Twist Cable (เมตร) | D27: 1200 | E27: 2000 | F27: =D27*E27 -> 2400000 | G27: 2000 | H27: =D27*G27 -> 2400000 | I27: 2000 | J27: =I27*D27 -> 2400000 | K27: =E27+G27+I27 -> 6000 | L27: =D27*K27 -> 7200000
A28: 20 | B28: 1020050204 | C28: 22kV 3x240 sq.mm. Twist Cable (เมตร) | D28: 1900 | E28: 27000 | F28: ยกเลิก | G28: 16000 | H28: ยกเลิก | I28: 8000 | J28: =I28*D28 -> 15200000 | K28: =E28+G28+I28 -> 51000 | L28: =D28*K28 -> 96900000
A29: 21 | B29: 1020050302 | C29: 33kV 3x120 sq.mm. Twist Cable (เมตร) | D29: 1500 | E29: 6000 | F29: =D29*E29 -> 9000000 | G29: 4000 | H29: =D29*G29 -> 6000000 | I29: 3500 | J29: =I29*D29 -> 5250000 | K29: =E29+G29+I29 -> 13500 | L29: =D29*K29 -> 20250000
A30: 22 | B30: 1020050304 | C30: 33kV 3x240 sq.mm. Twist Cable (เมตร) | D30: 2200 | E30: 2000 | F30: =D30*E30 -> 4400000 | G30: 13000 | H30: =D30*G30 -> 28600000 | I30: 10000 | J30: =I30*D30 -> 22000000 | K30: =E30+G30+I30 -> 25000 | L30: =D30*K30 -> 55000000
A31: รวมค่าอุปกรณ์ | F31: =SUM(F9:F30) -> 243722692 | H31: =SUM(H9:H30) -> 256813242 | J31: =SUM(J9:J30) -> 219751637 | L31: =F31+H31+J31 -> 720287571 | M31: =BAHTTEXT(L31) -> เจ็ดร้อยยี่สิบล้านสองแสนแปดหมื่นเจ็ดพันห้าร้อยเจ็ดสิบเอ็ดบาทถ้วน
A32: สำรองราคา (กรณีแผนระยะยาว) | F32: 0 | H32: 8616398 | J32: 13382875 | L32: =H32+J32+F32 -> 21999273
A33: รวมเป็นเงินทั้งสิ้น | F33: =F31+F32 -> 243722692 | H33: =H31+H32 -> 265429640 | J33: =J31+J32 -> 233134512 | L33: =F33+H33+J33 -> 742286844 | M33: =BAHTTEXT(L33) -> เจ็ดร้อยสี่สิบสองล้านสองแสนแปดหมื่นหกพันแปดร้อยสี่สิบสี่บาทถ้วน
A34: หมายเหตุ* | B34: [1] สำรองค่าปรับราคา เป็นการตั้งวงเงินสำหรับสมทบการจัดซื้อ จัดจ้าง/จ้างเหมา กรณีเป็นแผนงานใหม่ จะเริ่มตั้งสำรองราคาปี 2571 จนสิ้นสุดแผน | L34: แบบ งป.010/1
B35: [2] วงเงินลงทุนรวมต้องเท่ากับวงเงินเต็มแผนงาน

Sheet 010-2 (ori)
A2: แผนการจ่ายเงินตามงบผูกพันปี 2569 (กรณีแผนระยะยาว/งานต่อเนื่อง)
V3: หน่วย : บาท
A4: รายการ | B4: วงเงินเต็ม แผนงาน | C4: อนุมัติถึง ปี 2568 | D4: จ่ายจริงถึง ปี 2568 | E4: ปี 2569 | K4: ปี 2570 | Q4: ปี 2571 | W4: ปี 2572
E5: งบประมาณ | H5: ประมาณจ่าย | K5: งบประมาณ | N5: ประมาณจ่าย | Q5: งบประมาณ | T5: ประมาณจ่าย | W5: งบประมาณ | Z5: ประมาณจ่าย | AE5: 2569 | AF5: 2570 | AG5: 2571 | AH5: 2572
E6: ผูกพัน | F6: ลงทุน | G6: รวม | H6: ผูกพัน | I6: ลงทุน | J6: รวม | K6: ผูกพัน (69) | L6: ลงทุน (70) | M6: รวม | N6: ผูกพัน (69) | O6: ลงทุน (70) | P6: รวม | Q6: ผูกพัน (70) | R6: ลงทุน (71) | S6: รวม | T6: ผูกพัน (70) | U6: ลงทุน (71) | V6: รวม | W6: ผูกพัน (71) | X6: ลงทุน | Y6: รวม | Z6: ผูกพัน (71) | AA6: ลงทุน | AB6: รวม | AE6: ='010-1 (2)'!F31 -> 243722692 | AF6: ='007 (70)'!K77 -> 256813242 | AG6: ='010-1 (2)'!J31 -> 219751637
A7: 1. หมวดที่ดิน | AD7: จ่ายในปี | AE7: ='007 (69)'!I77 -> 17117362 | AF7: ='007 (70)'!J77 -> 0 | AG7: ='[2]007(71)'!L12+'[2]007(71)'!M12 -> 21032807
A8: 2. หมวดสิ่งก่อสร้าง | AD8: ยกยอดไป | AE8: =AE6-AE7 -> 226605330 | AF8: =AF6-AF7 -> 256813242 | AG8: =AG6-AG7 -> 198718830
A9: งานโยธา | AD9: ปี 69 ยกมา | AF9: =AE8 -> 226605330
A10: งานระบบไฟฟ้า | AD10: ปี 70 ยกมา | AG10: =AF8 -> 256813242
A11: - ค่าวัสดุอุปกรณ์ | AD11: ปี 71 ยกมา | AH11: =AG8 -> 198718830
A12: จัดหาอุปกรณ์ไฟฟ้า ทดแทนสำหรับ การจัดการทรัพย์สินระบบจำหน่าย และสายส่งไฟฟ้า รายการที่ 1-22 | AD12: สรุปจ่าย | AE12: =AE7 -> 17117362 | AF12: =AF7+AF9 -> 226605330 | AG12: =AG7+AG10 -> 277846049 | AH12: =AH11 -> 198718830 | AI12: =AE12+AF12+AG12+AH12 -> 720287571
B14: ='010-1 (2)'!L31 -> 720287571 | F14: =AE6 -> 243722692 | G14: =E14+F14 -> 243722692 | I14: =AE7 -> 17117362 | J14: =H14+I14 -> 17117362 | K14: =AE8 -> 226605330 | L14: =AF6 -> 256813242 | M14: =K14+L14 -> 483418572 | N14: =AF9 -> 226605330 | O14: =AF7 -> 0 | P14: =N14+O14 -> 226605330 | Q14: =AF8 -> 256813242 | R14: =AG6 -> 219751637 | S14: =Q14+R14 -> 476564879 | T14: =AG10 -> 256813242 | U14: =AG7 -> 21032807 | V14: =T14+U14 -> 277846049 | W14: =AG8 -> 198718830 | Y14: =W14+X14 -> 198718830 | Z14: =AH11 -> 198718830 | AB14: =Z14+AA14 -> 198718830 | AC14: =AB14+V14+P14+I14 -> 720287571
A17: รวมงานระบบไฟฟ้า | B17: =B14 -> 720287571 | J17: =J14 -> 17117362 | P17: =P14 -> 226605330 | V17: =V14 -> 277846049 | AB17: =AB14 -> 198718830
A18: 3. หมวดเครื่องอุปกรณ์ไฟฟ้า
A19: 4. หมวดยานพาหนะ
A20: 5. หมวดเครื่องมือเครื่องใช้ขนาดเล็ก
A21: 6. หมวดวิจัยและพัฒนา
A22: 7. หมวดอื่น ๆ
A23: รวม | B23: =B17 -> 720287571 | F23: =F14 -> 243722692 | G23: =G14 -> 243722692 | J23: =J14 -> 17117362 | L23: =L14 -> 256813242 | M23: =M14 -> 483418572 | P23: =P17 -> 226605330 | Q23: =Q14 -> 256813242 | R23: =R14 -> 219751637 | S23: =S14 -> 476564879 | V23: =V14 -> 277846049 | AB23: =AB14 -> 198718830
A24: สำรองค่าปรับราคา (อัตราเงินเฟ้อ 3%) | B24: =L24+R24 -> 21999273 | L24: ='[2]010-1'!H32 -> 8616398 | R24: ='[2]010-1'!J32 -> 13382875
A25: รวมทั้งสิ้น | B25: =G25+L25+R25 -> 742286844 | G25: =G23 -> 243722692 | L25: =L23+L24 -> 265429640 | R25: =R23+R24 -> 233134512

Sheet 010-2(Print)
A2: แผนการจ่ายเงินตามงบผูกพันปี 2569 (กรณีแผนระยะยาว/งานต่อเนื่อง)
P3: หน่วย : บาท
A4: รายการ | B4: วงเงินเต็ม แผนงาน | C4: อนุมัติถึง ปี 2568 | D4: จ่ายจริงถึง ปี 2568 | E4: ปี 2569 | K4: ปี 2570
E5: งบประมาณ | H5: ประมาณจ่าย | K5: งบประมาณ | N5: ประมาณจ่าย
E6: ผูกพัน | F6: ลงทุน (68) | G6: รวม | H6: ผูกพัน | I6: ลงทุน | J6: รวม | K6: ผูกพัน | L6: ลงทุน | M6: รวม | N6: ผูกพัน | O6: ลงทุน | P6: รวม
A7: 1. หมวดที่ดิน
A8: 2. หมวดสิ่งก่อสร้าง
A9: งานโยธา
A10: งานระบบไฟฟ้า
A11: - ค่าวัสดุอุปกรณ์
A12: แผนงานจัดหาอุปกรณ์ป้องกัน/ตัดตอน/ อุปกรณ์ประกอบและอุปกรณ์สำรอง สำหรับสายเคเบิลใต้ดิน/ใต้น้ำ ในระบบจำหน่ายและสายส่งไฟฟ้า (ปี 2569-2571)
B14: 720287571 | F14: 243722692 | G14: 243722692 | I14: 17117362 | J14: 17117362 | K14: 226605330 | L14: 256813242 | M14: 483418572 | N14: 226605330 | O14: 0 | P14: 226605330
A17: รวมงานระบบไฟฟ้า | B17: 720287571 | J17: 17117362 | P17: 226605330
A18: 3. หมวดเครื่องอุปกรณ์ไฟฟ้า
A19: 4. หมวดยานพาหนะ
A20: 5. หมวดเครื่องมือเครื่องใช้ขนาดเล็ก
A21: 6. หมวดวิจัยและพัฒนา
A22: 7. หมวดอื่น ๆ
A23: รวม | B23: 720287571 | F23: 243722692 | G23: 243722692 | J23: 17117362 | L23: 256813242 | M23: 483418572 | P23: 226605330
A24: สำรองค่าปรับราคา (อัตราเงินเฟ้อ 3%) | B24: 21999273 | L24: 8616398
A25: รวมทั้งสิ้น | B25: 742286844 | G25: 243722692 | L25: 265429640
P26: หน่วย : บาท
A27: รายการ | B27: วงเงินเต็ม แผนงาน | C27: อนุมัติถึง ปี 2568 | D27: จ่ายจริงถึง ปี 2568 | E27: ปี 2571 | K27: ปี 2572
E28: งบประมาณ | H28: ประมาณจ่าย | K28: งบประมาณ | N28: ประมาณจ่าย
E29: ผูกพัน (70) | F29: ลงทุน (71) | G29: รวม | H29: ผูกพัน (70) | I29: ลงทุน (71) | J29: รวม | K29: ผูกพัน (71) | L29: ลงทุน | M29: รวม | N29: ผูกพัน (71) | O29: ลงทุน | P29: รวม
A30: 1. หมวดที่ดิน
A31: 2. หมวดสิ่งก่อสร้าง
A32: งานโยธา
A33: งานระบบไฟฟ้า
A34: - ค่าวัสดุอุปกรณ์
A35: แผนงานจัดหาอุปกรณ์ป้องกัน/ตัดตอน/ อุปกรณ์ประกอบและอุปกรณ์สำรอง สำหรับสายเคเบิลใต้ดิน/ใต้น้ำ ในระบบจำหน่ายและสายส่งไฟฟ้า (ปี 2569-2571)
B37: 720287571 | E37: 256813242 | F37: 219751637 | G37: 476564879 | H37: 256813242 | I37: 21032807 | J37: 277846049 | K37: 198718830 | M37: 198718830 | N37: 198718830 | P37: 198718830
A40: รวมงานระบบไฟฟ้า | B40: 720287571 | J40: 277846049 | P40: 198718830
A41: 3. หมวดเครื่องอุปกรณ์ไฟฟ้า
A42: 4. หมวดยานพาหนะ
A43: 5. หมวดเครื่องมือเครื่องใช้ขนาดเล็ก
A44: 6. หมวดวิจัยและพัฒนา
A45: 7. หมวดอื่น ๆ
A46: รวม | B46: 720287571 | E46: 256813242 | F46: 219751637 | G46: 476564879 | J46: 277846049 | P46: 198718830
A47: สำรองค่าปรับราคา (อัตราเงินเฟ้อ 3%) | B47: 21999273 | F47: 13382875
...

Sheet 010-3
A2: เป้าหมายการเบิกจ่ายรายเดือน ปี 2570 แยกรายภาคและสำนักงานใหญ่
A3: หน่วยงาน กองบริหารจัดการระบบไฟฟ้า
A4: ชื่องาน แผนงานจัดหาอุปกรณ์ป้องกัน/ตัดตอน/อุปกรณ์ประกอบและอุปกรณ์สำรองสำหรับสายเคเบิลใต้ดิน/ใต้น้ำ ในระบบจำหน่ายและสายส่งไฟฟ้า (ปี 2569-2571)
A5: ชุด (ผูกพัน+ลงทุน) | P5: หน่วย: บาท
A6: ลำดับ ที่ | B6: ศูนย์การไฟฟ้า | D6: ประมาณจ่ายปี 2570
D7: ม.ค. | E7: ก.พ. | F7: มี.ค. | G7: เม.ย. | H7: พ.ค. | I7: มิ.ย. | J7: ก.ค. | K7: ส.ค. | L7: ก.ย. | M7: ต.ค. | N7: พ.ย. | O7: ธ.ค. | P7: รวม
A9: 1 | B9: ศูนย์ EVM ภาคเหนือและภาคตะวันออกเฉียงเหนือ
A10: 2 | B10: ศูนย์ EVM ภาคกลางและภาคใต้
A11: 3 | B11: ศูนย์ EVM สำนักงานใหญ่ | L11: ='009 (70)'!L20 -> 0 | O11: ='009 (70)'!O20 -> 0 | P11: =L11+O11 -> 0
A12: รวมทั้งสิ้น | L12: =L11 -> 0 | O12: =O11 -> 0 | P12: =L12+O12 -> 0
C13: หมายเหตุ - ดำเนินการภายหลังจากได้รับอนุมัติงบประมาณประจำปีจากคณะกรรมการ กฟภ. แล้ว
C14: - ประมาณจ่ายแบ่งตามพื้นที่ดำเนินการ (ภาคเหนือ และภาคตะวันออกเฉียงเหนือ(น,ฉ), ภาคกลาง และภาคใต้ (ก,ต), สำนักงานใหญ่)
P15: แบบ งป. 010/3

Sheet 011
A2: ประมาณการวัสดุอุปกรณ์นำเข้าจากต่างประเทศ (Import Content)
A3: ประจำปี 2570
A4: (งบลงทุนเพื่อการดำเนินงานปกติ)
A5: กลุ่มโครงสร้าง กลุ่มเครือข่ายและบริการ
A6: ชื่องาน แผนงานจัดหาอุปกรณ์ป้องกัน/ตัดตอน/อุปกรณ์ประกอบและอุปกรณ์สำรองสำหรับสายเคเบิลใต้ดิน/ใต้น้ำ ในระบบจำหน่ายและสายส่งไฟฟ้า (ปี 2569-2571)
A7: หน่วยงาน กองบริหารจัดการระบบไฟฟ้า
R8: หน่วย : บาท
A9: ที่ | B9: รายการ | C9: ปีเริ่มต้น - ปี 2569 | D9: ปี 2570 | Q9: ปี 2571 | R9: ปี 2572 - ปีสิ้นสุด
D10: ประมาณการเบิกจ่ายรายเดือน | P10: รวม
D11: ม.ค. | E11: ก.พ. | F11: มี.ค. | G11: เม.ย. | H11: พ.ค. | I11: มิ.ย. | J11: ก.ค. | K11: ส.ค. | L11: ก.ย. | M11: ต.ค. | N11: พ.ย. | O11: ธ.ค.
B12: ทางตรง
B18: ทางอ้อม
B19: หมายถึง การจัดซื้อจัดหาผ่านตัวแทนจำหน่าย | O19: =('007 (70)'!K30+'007 (70)'!K36)/1000000 -> 61.1828 | P19: =O19 -> 61.1828
B20: หรือผ่านผู้รับเหมา
A27: หมายเหตุ | B27: วัสดุอุปกรณ์นำเข้าจากต่างประเทศ (Import Content) หมายถึง การใช้หรือการนำเข้าพัสดุที่ผลิตสำเร็จรูปแล้วจากต่างประเทศ
B28: ไม่ว่าจะนำเข้าโดยคู่สัญญาหรือบุคคลอื่นใด | R28: แบบ งป.011

Sheet Sheet1
